Workbook

Sheet 预算规则
B2: 预算项目 | C2: 科研公司 | E2: 公共项目 | F2: 科目分配规则 | G2: 项目分配规则
B3: 责任中心 | C3: 部门 | E3: 房屋租赁 | F3: 使用面积 | G3: 人员工时
B4: 收入预算 | E4: 固定资产折旧 | F4: 使用部门 | G4: 设备工时
B5: 成本 | C5: 实际生产成本 | E5: 人员人工 | F5: 部门 | G5: 人员工时
B6: 人力成本 | C6: 人均产值 | E6: 无形资产摊销 | F6: 使用部门 | G6: 人员工时
B7: 变动费用 | E7: 装修摊销 | F7: 使用面积 | G7: 人员工时
B8: 市交 | E8: 动力费（电费） | F8: 使用面积 | G8: 人员工时
B9: 差旅 | C9: 按实际情况编制预算
B10: 办公 | C10: 500元/人.年（日常办公用品）；新增人员1000元/人（显示器）
B11: 福利费 | C11: 餐费（含茶点）100元/人.月； | E11: 预算编制记要： 1、收入按第三方，关联方分列； 2、高清的关联结算费用正常做预算； 3、其他收益（政府补贴）以净额法填列 4、按法人公司归集人员费（深圳包含人力资源和财务人员）@所有人 5、关联方借款利息单独填列 6、目前无息借款25年按3.1%利率计算关联利息 7、研发预计立项费用单独一个表格，不包含在利润表，现流表内
B12: 通讯费
B13: 市场推广费
B14: 业务招待费
B15: 其他 | C15: 根据实际业务需要预算
B16: 固定费用
B17: 折旧与摊销 | C17: 财务部
B18: 公共费用 | C18: 按实际情况编制预算
B19: 内部会议费 | C19: 2000元/人.年

Sheet 利润表
A1: 利润预算表
H2: 单位：万元
A3: 项目 | B3: FY2025 （截至2025.11） | C3: Q1 | D3: Q2 | E3: Q3 | F3: Q4 | G3: FY2026 | H3: 26/25
A4: 营业收入 | B4: 185.14723 | C4: =C5+C6 -> 0 | D4: =D5+D6 -> 0 | E4: =E5+E6 -> 0 | F4: =F5+F6 -> 0 | G4: =SUM(C4:F4) -> 0 | H4: =IFERROR(G4/B4-1,"") -> -1
A5: 其中: 关联方销售 | B5: 0 | G5: =SUM(C5:F5) -> 0 | H5: =IFERROR(G5/B5-1,"")
A6: 第三方销售 | B6: 185.14723 | C6: =收入及成本!B10 -> 0 | D6: =收入及成本!C10 -> 0 | E6: =收入及成本!D10 -> 0 | F6: =收入及成本!E10 -> 0 | G6: =SUM(C6:F6) -> 0 | H6: =IFERROR(G6/B6-1,"") -> -1
A7: 营业成本 | B7: 82.407357 | C7: =C8+C9 -> 0 | D7: =D8+D9 -> 0 | E7: =E8+E9 -> 0 | F7: =F8+F9 -> 0 | G7: =SUM(C7:F7) -> 0 | H7: =IFERROR(G7/B7-1,"") -> -1
A8: 其中: 关联方销售 | B8: 2.352436 | G8: =SUM(C8:F8) -> 0 | H8: =IFERROR(G8/B8-1,"") -> -1
A9: 第三方销售 | B9: 80.054921 | C9: =收入及成本!I10 -> 0 | D9: =收入及成本!J10 -> 0 | E9: =收入及成本!K10 -> 0 | F9: =收入及成本!L10 -> 0 | G9: =SUM(C9:F9) -> 0 | H9: =IFERROR(G9/B9-1,"") -> -1
A10: 毛利润 | B10: =B4-B7 -> 102.73987 | C10: =C4-C7 -> 0 | D10: =D4-D7 -> 0 | E10: =E4-E7 -> 0 | F10: =F4-F7 -> 0 | G10: =SUM(C10:F10) -> 0 | H10: =IFERROR(G10/B10-1,"") -> -1
A11: 税金及附加 | B11: 0.157954 | G11: =SUM(C11:F11) -> 0
A12: 销售费用 | B12: 681.56902 | C12: ='附件1.2费用预算（销售）'!C6 -> 100.87 | D12: ='附件1.2费用预算（销售）'!D6 -> 100.87 | E12: ='附件1.2费用预算（销售）'!E6 -> 100.87 | F12: ='附件1.2费用预算（销售）'!F6 -> 100.87 | G12: =SUM(C12:F12) -> 403.48 | H12: =IFERROR(G12/B12-1,"") -> -0.408013
A13: 其中: 技术人员成本 | B13: 0 | G13: =SUM(C13:F13) -> 0 | H13: =IFERROR(G13/B13-1,"")
A14: 运杂费 | B14: 6.125726 | C14: ='附件1.2费用预算（销售）'!C20 -> 0.6 | D14: ='附件1.2费用预算（销售）'!D20 -> 0.6 | E14: ='附件1.2费用预算（销售）'!E20 -> 0.6 | F14: ='附件1.2费用预算（销售）'!F20 -> 0.6 | G14: =SUM(C14:F14) -> 2.4
A15: 管理费用 | B15: 202.73526 | C15: ='附件1.1费用预算（管理）'!C6 -> 0 | D15: ='附件1.1费用预算（管理）'!D6 -> 0 | E15: ='附件1.1费用预算（管理）'!E6 -> 0 | F15: ='附件1.1费用预算（管理）'!F6 -> 0 | G15: =SUM(C15:F15) -> 0 | H15: =IFERROR(G15/B15-1,"") -> -1
A16: 研发费用 | B16: 457.98354 | C16: =研发预算!D4 -> 0 | D16: =研发预算!E4 -> 0 | E16: =研发预算!F4 -> 0 | F16: =研发预算!G4 -> 0 | G16: =SUM(C16:F16) -> 0 | H16: =IFERROR(G16/B16-1,"") -> -1
A17: 财务费用 | B17: 57.358329 | C17: ='附件4（财务费用明细）'!D8 -> 0 | D17: ='附件4（财务费用明细）'!E8 -> 0 | E17: ='附件4（财务费用明细）'!F8 -> 0 | F17: ='附件4（财务费用明细）'!G8 -> 0 | G17: =SUM(C17:F17) -> 0 | H17: =IFERROR(G17/B17-1,"") -> -1
A18: 其中: 利息费用 | B18: 53.411664 | C18: ='附件4（财务费用明细）'!D4 -> 0 | D18: ='附件4（财务费用明细）'!E4 -> 0 | E18: ='附件4（财务费用明细）'!F4 -> 0 | F18: ='附件4（财务费用明细）'!G4 -> 0 | G18: =SUM(C18:F18) -> 0 | H18: =IFERROR(G18/B18-1,"") -> -1
A19: 手续费 | B19: 0.302732 | C19: ='附件4（财务费用明细）'!D5 -> 0 | D19: ='附件4（财务费用明细）'!E5 -> 0 | E19: ='附件4（财务费用明细）'!F5 -> 0 | F19: ='附件4（财务费用明细）'!G5 -> 0 | G19: =SUM(C19:F19) -> 0 | H19: =IFERROR(G19/B19-1,"") -> -1
A20: 利息收入 | B20: -0.487181 | C20: ='附件4（财务费用明细）'!D6 -> 0 | D20: ='附件4（财务费用明细）'!E6 -> 0 | E20: ='附件4（财务费用明细）'!F6 -> 0 | F20: ='附件4（财务费用明细）'!G6 -> 0 | G20: =SUM(C20:F20) -> 0 | H20: =IFERROR(G20/B20-1,"") -> -1
A21: 汇兑损益 | B21: 0.384749 | C21: ='附件4（财务费用明细）'!D7 -> 0 | D21: ='附件4（财务费用明细）'!E7 -> 0 | E21: ='附件4（财务费用明细）'!F7 -> 0 | F21: ='附件4（财务费用明细）'!G7 -> 0 | G21: =SUM(C21:F21) -> 0 | H21: =IFERROR(G21/B21-1,"") -> -1
A22: 租赁利息调整 | B22: 3.746365
A23: 加：其他收益 | B23: 6.780108 | C23: =其他收入及支出!B8 -> 0 | D23: =其他收入及支出!C8 -> 0 | E23: =其他收入及支出!D8 -> 0 | F23: =其他收入及支出!E8 -> 0 | G23: =SUM(C23:F23) -> 0 | H23: =IFERROR(G23/B23-1,"") -> -1
A24: 信用减值损失 | B24: 4.663351 | C24: =其他收入及支出!B4 -> 0 | D24: =其他收入及支出!C4 -> 0 | E24: =其他收入及支出!D4 -> 0 | F24: =其他收入及支出!E4 -> 0 | G24: =SUM(C24:F24) -> 0 | H24: =IFERROR(G24/B24-1,"") -> -1
A25: 资产减值损失 | B25: 0 | C25: =其他收入及支出!B5 -> 0 | D25: =其他收入及支出!C5 -> 0 | E25: =其他收入及支出!D5 -> 0 | F25: =其他收入及支出!E5 -> 0 | G25: =SUM(C25:F25) -> 0 | H25: =IFERROR(G25/B25-1,"")
A26: 营业利润（亏损以“-”号填列） | B26: =B10-B11-B12-B15-B16-B17+B23-B24-B25 -> -1294.9475 | C26: =C10-C11-C12-C15-C16-C17+C23-C24-C25 -> -100.87 | D26: =D10-D11-D12-D15-D16-D17+D23-D24-D25 -> -100.87 | E26: =E10-E11-E12-E15-E16-E17+E23-E24-E25 -> -100.87 | F26: =F10-F11-F12-F15-F16-F17+F23-F24-F25 -> -100.87 | G26: =SUM(C26:F26) -> -403.48 | H26: =IFERROR(G26/B26-1,"") -> -0.6884198
A27: 减：所得税费用 | G27: =SUM(C27:F27) -> 0 | H27: =IFERROR(G27/B27-1,"")
A28: 净利润（净亏损以“-”号填列） | B28: =B26-B27 -> -1294.9475 | C28: =C26-C27 -> -100.87 | D28: =D26-D27 -> -100.87 | E28: =E26-E27 -> -100.87 | F28: =F26-F27 -> -100.87 | G28: =SUM(C28:F28) -> -403.48 | H28: =IFERROR(G28/B28-1,"") -> -0.6884198
A30: 主要比率
A31: 毛利率 | B31: =B10/B4 -> 0.55490904 | C31: =C10/C4 -> #DIV/0! | D31: =D10/D4 -> #DIV/0! | E31: =E10/E4 -> #DIV/0! | F31: =F10/F4 -> #DIV/0! | G31: =G10/G4 -> #DIV/0!
A32: 净利润率 | B32: =B28/B4 -> -6.99415 | C32: =C28/C4 -> #DIV/0! | D32: =D28/D4 -> #DIV/0! | E32: =E28/E4 -> #DIV/0! | F32: =F28/F4 -> #DIV/0! | G32: =G28/G4 -> #DIV/0!
A33: 销售费用率 | B33: =B12/B4 -> 3.6812273 | C33: =C12/C4 -> #DIV/0! | D33: =D12/D4 -> #DIV/0! | E33: =E12/E4 -> #DIV/0! | F33: =F12/F4 -> #DIV/0! | G33: =G12/G4 -> #DIV/0!
A34: 管理费用率 | B34: =B15/B4 -> 1.0949948 | C34: =C15/C4 -> #DIV/0! | D34: =D15/D4 -> #DIV/0! | E34: =E15/E4 -> #DIV/0! | F34: =F15/F4 -> #DIV/0! | G34: =G15/G4 -> #DIV/0!
A35: 研发费用率 | B35: =B16/B4 -> 2.4736182 | C35: =C16/C4 -> #DIV/0! | D35: =D16/D4 -> #DIV/0! | E35: =E16/E4 -> #DIV/0! | F35: =F16/F4 -> #DIV/0! | G35: =G16/G4 -> #DIV/0!
A36: 所得税率 | B36: =B27/B4 -> 0 | C36: =C27/C4 -> #DIV/0! | D36: =D27/D4 -> #DIV/0! | E36: =E27/E4 -> #DIV/0! | F36: =F27/F4 -> #DIV/0! | G36: =G27/G4 -> #DIV/0!

Sheet 现金流量表
A1: 现金流预算表
H2: 单位：万元
A3: 项 目 | B3: Q1 | C3: Q2 | D3: Q3 | E3: Q4 | F3: FY2026 | G3: FY2025 （截至2025.11） | H3: 26/25
A4: 1.经营活动产生的现金流量
A5: 销售商品、提供劳务收到的现金 | B5: =收入及成本!B10*1.13 -> 0 | C5: =收入及成本!C10*1.13 -> 0 | D5: =收入及成本!D10*1.13 -> 0 | E5: =收入及成本!E10*1.13 -> 0 | F5: =SUM(B5:E5) -> 0 | G5: 241.06542 | H5: =IFERROR((F5/G5-1),"") -> -1
A6: 收到的税费返还 | C6: =其他收入及支出!D29 -> 0 | D6: =其他收入及支出!E29 -> 0 | E6: =其他收入及支出!F29 -> 0 | F6: =SUM(B6:E6) -> 0 | G6: 222.40477 | H6: =IFERROR((F6/G6-1),"") -> -1
A7: 收到其他与经营活动有关的现金 | B7: =其他收入及支出!B8-利润表!C20 -> 0 | C7: =其他收入及支出!C8-利润表!D20 -> 0 | D7: =其他收入及支出!D8-利润表!E20 -> 0 | E7: =其他收入及支出!E8-利润表!F20 -> 0 | F7: =SUM(B7:E7) -> 0 | G7: 7.314914 | H7: =IFERROR((F7/G7-1),"") -> -1
A8: 经营活动现金流入小计 | B8: =SUM(B5:B7) -> 0 | C8: =SUM(C5:C7) -> 0 | D8: =SUM(D5:D7) -> 0 | E8: =SUM(E5:E7) -> 0 | F8: =SUM(F5:F7) -> 0 | G8: =SUM(G5:G7) -> 470.7851 | H8: =IFERROR((F8/G8-1),"") -> -1
A9: 购买商品、接受劳务支付的现金 | B9: =产品成本!M12+研发预算!D28 -> 0 | C9: =产品成本!N12+研发预算!E28 -> 0 | D9: =产品成本!O12+研发预算!F28 -> 0 | E9: =产品成本!P12+研发预算!G28 -> 0 | F9: =SUM(B9:E9) -> 0 | G9: 86.841837 | H9: =IFERROR((F9/G9-1),"") -> -1
A10: 支付给职工以及为职工支付的现金 | B10: =产品成本!M13+费用预算!C54+研发预算!D29 -> 0 | C10: =产品成本!N13+费用预算!D54+研发预算!E29 -> 0 | D10: =产品成本!O13+费用预算!E54+研发预算!F29 -> 0 | E10: =产品成本!P13+费用预算!F54+研发预算!G29 -> 0 | F10: =SUM(B10:E10) -> 0 | G10: 850.0631 | H10: =IFERROR((F10/G10-1),"") -> -1
A11: 支付的各项税费 | B11: ='附件5（其他收益明细）'!D12+'附件5（其他收益明细）'!D13+'附件5（其他收益明细）'!D14 -> 0 | C11: ='附件5（其他收益明细）'!E12+'附件5（其他收益明细）'!E13+'附件5（其他收益明细）'!E14 -> 0 | D11: ='附件5（其他收益明细）'!F12+'附件5（其他收益明细）'!F13+'附件5（其他收益明细）'!F14 -> 0 | E11: ='附件5（其他收益明细）'!G12+'附件5（其他收益明细）'!G13+'附件5（其他收益明细）'!G14 -> 0 | F11: =SUM(B11:E11) -> 0 | G11: 0.209619 | H11: =IFERROR((F11/G11-1),"") -> -1 | K11: 核对
A12: 支付其他与经营活动有关的现金 | B12: =产品成本!M14+其他收入及支出!C31+费用预算!C55+资产预算!K23+研发预算!D30+利润表!C19 -> 100.87 | C12: =产品成本!N14+其他收入及支出!D31+费用预算!D55+资产预算!L23+研发预算!E30+利润表!D19 -> 100.87 | D12: =产品成本!O14+其他收入及支出!E31+费用预算!E55+资产预算!M23+研发预算!F30+利润表!E19 -> 100.87 | E12: =产品成本!P14+其他收入及支出!F31+费用预算!F55+资产预算!N23+研发预算!G30+利润表!F19 -> 100.87 | F12: =SUM(B12:E12) -> 403.48 | G12: 448.36159 | H12: =IFERROR((F12/G12-1),"") -> -0.10010133 | K12: 利润 | L12: =利润表!G26 -> -403.48 | N12: 经营现流 | O12: =F14 -> -403.48
A13: 经营活动现金流出小计 | B13: =SUM(B9:B12) -> 100.87 | C13: =SUM(C9:C12) -> 100.87 | D13: =SUM(D9:D12) -> 100.87 | E13: =SUM(E9:E12) -> 100.87 | F13: =SUM(F9:F12) -> 403.48 | G13: =SUM(G9:G12) -> 1385.4761 | H13: =IFERROR((F13/G13-1),"") -> -0.70877882 | K13: 摊销 | L13: =费用预算!G38+费用预算!G39+费用预算!G40+产品成本!F12+产品成本!F24+研发预算!C16+费用预算!G31 -> 0 | N13: 租赁现流 | O13: =-F37 -> 0
A14: 经营活动产生的现金流量净额 | B14: =B8-B13 -> -100.87 | C14: =C8-C13 -> -100.87 | D14: =D8-D13 -> -100.87 | E14: =E8-E13 -> -100.87 | F14: =F8-F13 -> -403.48 | G14: =G8-G13 -> -914.69105 | H14: =IFERROR((F14/G14-1),"") -> -0.55888931 | K14: 汇兑 | L14: =利润表!G21 -> 0 | N14: 注册 | O14: =资产预算!J17 -> 0
A15: 2.投资活动产生的现金流量 | F15: =SUM(B15:E15) -> 0 | H15: =IFERROR((F15/G15-1),"") | N15: 销项税 | O15: =-F5/1.13*13% -> 0
A16: 收回投资收到的现金 | F16: =SUM(B16:E16) -> 0 | H16: =IFERROR((F16/G16-1),"") | K16: 信用减值 | L16: =利润表!G24 -> 0 | N16: 进项税 | O16: =产品成本!Q12/1.13*13% -> 0
A17: 取得投资收益收到的现金 | F17: =SUM(B17:E17) -> 0 | H17: =IFERROR((F17/G17-1),"") | K17: 租赁差 | L17: =利润表!G17-利润表!G18-利润表!G19-利润表!G20-利润表!G21 -> 0 | N17: 利息费用 | O17: =-F35 -> 0
A18: 处置固定资产、无形资产和其他长期资产收回的现金净额 | F18: =SUM(B18:E18) -> 0 | H18: =IFERROR((F18/G18-1),"") | N18: 租赁税 | O18: =F37/1.05*5% -> 0
A19: 处置子公司及其他营业单位收到的现金净额 | F19: =SUM(B19:E19) -> 0 | H19: =IFERROR((F19/G19-1),"") | K19: 调整后 | L19: =SUM(L12:L18) -> -403.48 | N19: 调整后 | O19: =SUM(O12:O18) -> -403.48
A20: 收到其他与投资活动有关的现金 | F20: =SUM(B20:E20) -> 0 | H20: =IFERROR((F20/G20-1),"") | O20: =L19-O19 -> 0
A21: 投资活动现金流入小计 | B21: =SUM(B16:B20) -> 0 | C21: =SUM(C16:C20) -> 0 | D21: =SUM(D16:D20) -> 0 | E21: =SUM(E16:E20) -> 0 | F21: =SUM(F16:F20) -> 0 | G21: =SUM(G16:G20) -> 0 | H21: =IFERROR((F21/G21-1),"")
A22: 购建固定资产、无形资产和其他长期资产支付的现金 | B22: =资产预算!K24+研发预算!D31 -> 0 | C22: =资产预算!L24+研发预算!E31 -> 0 | D22: =资产预算!M24+研发预算!F31 -> 0 | E22: =资产预算!N24+研发预算!G31 -> 0 | F22: =SUM(B22:E22) -> 0 | G22: 262.43109 | H22: =IFERROR((F22/G22-1),"") -> -1
A23: 投资支付的现金 | F23: =SUM(B23:E23) -> 0 | H23: =IFERROR((F23/G23-1),"")
A24: 取得子公司及其他营业单位支付的现金净额 | F24: =SUM(B24:E24) -> 0 | H24: =IFERROR((F24/G24-1),"")
A25: 支付其他与投资活动有关的现金 | F25: =SUM(B25:E25) -> 0 | H25: =IFERROR((F25/G25-1),"")
A26: 投资活动现金流出小计 | B26: =SUM(B22:B25) -> 0 | C26: =SUM(C22:C25) -> 0 | D26: =SUM(D22:D25) -> 0 | E26: =SUM(E22:E25) -> 0 | F26: =SUM(F22:F25) -> 0 | G26: =SUM(G22:G25) -> 262.43109 | H26: =IFERROR((F26/G26-1),"") -> -1
A27: 投资活动产生的现金流量净额 | B27: =B21-B26 -> 0 | C27: =C21-C26 -> 0 | D27: =D21-D26 -> 0 | E27: =E21-E26 -> 0 | F27: =F21-F26 -> 0 | G27: =G21-G26 -> -262.43109 | H27: =IFERROR((F27/G27-1),"") -> -1
A28: 3.筹资活动产生的现金流量 | F28: =SUM(B28:E28) -> 0 | H28: =IFERROR((F28/G28-1),"")
A29: 吸收投资收到的现金 | F29: =SUM(B29:E29) -> 0 | H29: =IFERROR((F29/G29-1),"")
A30: 其中：子公司吸收少数股东投资收到的现金 | F30: =SUM(B30:E30) -> 0 | H30: =IFERROR((F30/G30-1),"")
A31: 取得借款收到的现金 | F31: =SUM(B31:E31) -> 0 | H31: =IFERROR((F31/G31-1),"")
A32: 收到其他与筹资活动有关的现金 | F32: =SUM(B32:E32) -> 0 | G32: 1080 | H32: =IFERROR((F32/G32-1),"") -> -1
A33: 筹资活动现金流入小计 | B33: =SUM(B29:B32)-B30 -> 0 | C33: =SUM(C29:C32)-C30 -> 0 | D33: =SUM(D29:D32)-D30 -> 0 | E33: =SUM(E29:E32)-E30 -> 0 | F33: =SUM(F29:F32)-F30 -> 0 | G33: =SUM(G29:G32)-G30 -> 1080 | H33: =IFERROR((F33/G33-1),"") -> -1 | M33: 预计现金流缺口 | N33: =F33 -> 0
A34: 偿还债务支付的现金 | F34: =SUM(B34:E34) -> 0 | H34: =IFERROR((F34/G34-1),"") | M34: 银行借款 | N34: 700
A35: 分配股利、利润或偿付利息支付的现金 | B35: ='附件4（财务费用明细）'!D4 -> 0 | C35: ='附件4（财务费用明细）'!E4 -> 0 | D35: ='附件4（财务费用明细）'!F4 -> 0 | E35: ='附件4（财务费用明细）'!G4 -> 0 | F35: =SUM(B35:E35) -> 0 | G35: 41.427498 | H35: =IFERROR((F35/G35-1),"") -> -1 | M35: 剩余借款额度 | N35: 980
A36: 其中：子公司支付给少数股东的股利、利润 | F36: =SUM(B36:E36) -> 0 | H36: =IFERROR((F36/G36-1),"") | M36: 新签协议预计使用资金 | N36: =N33-N34-N35 -> -1680
A37: 支付其他与筹资活动有关的现金 | B37: =(产品成本!M15+费用预算!C56+研发预算!D32)*1.05 -> 0 | C37: =(产品成本!N15+费用预算!D56+研发预算!E32)*1.05 -> 0 | D37: =(产品成本!O15+费用预算!E56+研发预算!F32)*1.05 -> 0 | E37: =(产品成本!P15+费用预算!F56+研发预算!G32)*1.05 -> 0 | F37: =SUM(B37:E37) -> 0 | G37: 58.9348 | H37: =IFERROR((F37/G37-1),"") -> -1
A38: 筹资活动现金流出小计 | B38: =SUM(B34:B37)-B36 -> 0 | C38: =SUM(C34:C37)-C36 -> 0 | D38: =SUM(D34:D37)-D36 -> 0 | E38: =SUM(E34:E37)-E36 -> 0 | F38: =SUM(F34:F37)-F36 -> 0 | G38: =SUM(G34:G37)-G36 -> 100.3623 | H38: =IFERROR((F38/G38-1),"") -> -1
A39: 筹资活动产生的现金流量净额 | B39: =B33-B38 -> 0 | C39: =C33-C38 -> 0 | D39: =D33-D38 -> 0 | E39: =E33-E38 -> 0 | F39: =F33-F38 -> 0 | G39: =G33-G38 -> 979.6377 | H39: =IFERROR((F39/G39-1),"") -> -1
A40: 4.汇率变动对现金及现金等价物的影响 | F40: =SUM(B40:E40) -> 0 | G40: -0.311819
...

Sheet 收入及成本
A1: 收入及成本预算表
P2: 单位：万元
A3: 产品线 | B3: 收入金额 | I3: 成本金额 | P3: FY2026毛利率 | Q3: 分类 | R3: FY2025毛利率
B4: Q1 | C4: Q2 | D4: Q3 | E4: Q4 | F4: FY2026 | G4: FY2025 （截至2025.11） | H4: 26/25 | I4: Q1 | J4: Q2 | K4: Q3 | L4: Q4 | M4: FY2026 | N4: FY2025 （截至2025.11） | O4: 26/25
A5: RGP | B5: =J17 -> 0 | C5: =K17 -> 0 | D5: =L17 -> 0 | E5: =M17 -> 0 | F5: =SUM(B5:E5) -> 0 | G5: 26.423093 | H5: =IFERROR(F5/G5-1,"") -> -1 | I5: =产品成本!K4 -> 0 | J5: =产品成本!P4 -> 0 | K5: =产品成本!U4 -> 0 | L5: =产品成本!Z4 -> 0 | M5: =SUM(I5:L5) -> 0 | O5: =IFERROR(M5/N5-1,"") | P5: =1-M5/F5 -> #DIV/0! | Q5: 第三方 | R5: =1-N5/G5 -> 1
A6: 离焦镜片 | B6: =J18 -> 0 | C6: =K18 -> 0 | D6: =L18 -> 0 | E6: =M18 -> 0 | F6: =SUM(B6:E6) -> 0 | G6: 151.64866 | H6: =IFERROR(F6/G6-1,"") -> -1 | I6: =产品成本!K5 -> 0 | J6: =产品成本!P5 -> 0 | K6: =产品成本!U5 -> 0 | L6: =产品成本!Z5 -> 0 | M6: =SUM(I6:L6) -> 0 | O6: =IFERROR(M6/N6-1,"") | P6: =1-M6/F6 -> #DIV/0! | Q6: 第三方 | R6: =1-N6/G6 -> 1
A7: 其他服务 | F7: =SUM(B7:E7) -> 0 | G7: 7.075471 | H7: =IFERROR(F7/G7-1,"") -> -1 | M7: =SUM(I7:L7) -> 0 | O7: =IFERROR(M7/N7-1,"")
F8: =SUM(B8:E8) -> 0 | H8: =IFERROR(F8/G8-1,"") | M8: =SUM(I8:L8) -> 0 | O8: =IFERROR(M8/N8-1,"")
F9: =SUM(B9:E9) -> 0 | H9: =IFERROR(F9/G9-1,"") | M9: =SUM(I9:L9) -> 0 | O9: =IFERROR(M9/N9-1,"")
A10: 合计 | B10: =SUM(B5:B9) -> 0 | C10: =SUM(C5:C9) -> 0 | D10: =SUM(D5:D9) -> 0 | E10: =SUM(E5:E9) -> 0 | F10: =SUM(B10:E10) -> 0 | G10: =SUM(G5:G9) -> 185.14723 | H10: =IFERROR(F10/G10-1,"") -> -1 | I10: =SUM(I5:I9) -> 0 | J10: =SUM(J5:J9) -> 0 | K10: =SUM(K5:K9) -> 0 | L10: =SUM(L5:L9) -> 0 | M10: =SUM(I10:L10) -> 0 | N10: =SUM(N5:N9) -> 0 | O10: =IFERROR(M10/N10-1,"") | P10: =1-M10/F10 -> #DIV/0!
M14: 单位：万元
A15: 产品名称 | B15: 产品型号 | C15: 销售单价 | D15: 销售数量 | I15: 销售收入金额
D16: 小计 | E16: Q1 | F16: Q2 | G16: Q3 | H16: Q4 | I16: 小计 | J16: Q1 | K16: Q2 | L16: Q3 | M16: Q4
A17: RGP | D17: =SUM(E17:H17) -> 0 | I17: =SUM(J17:M17) -> 0 | J17: =E17*$C17 -> 0 | K17: =F17*$C17 -> 0 | L17: =G17*$C17 -> 0 | M17: =H17*$C17 -> 0
A18: 离焦镜片 | D18: =SUM(E18:H18) -> 0 | I18: =SUM(J18:M18) -> 0 | J18: =E18*$C18 -> 0 | K18: =F18*$C18 -> 0 | L18: =G18*$C18 -> 0 | M18: =H18*$C18 -> 0
D19: =SUM(E19:H19) -> 0 | I19: =SUM(J19:M19) -> 0 | J19: =E19*$C19 -> 0 | K19: =F19*$C19 -> 0 | L19: =G19*$C19 -> 0 | M19: =H19*$C19 -> 0
D20: =SUM(E20:H20) -> 0 | I20: =SUM(J20:M20) -> 0 | J20: =E20*$C20 -> 0 | K20: =F20*$C20 -> 0 | L20: =G20*$C20 -> 0 | M20: =H20*$C20 -> 0
A21: 合计 | D21: =SUM(D17:D20) -> 0 | E21: =SUM(E17:E20) -> 0 | F21: =SUM(F17:F20) -> 0 | G21: =SUM(G17:G20) -> 0 | H21: =SUM(H17:H20) -> 0 | I21: =SUM(I17:I20) -> 0 | J21: =SUM(J17:J20) -> 0 | K21: =SUM(K17:K20) -> 0 | ... M21: =SUM(M17:M20) -> 0

Sheet 产品成本
A1: 产品成本预算表 | X1: 单位：万元
A2: 产品名称 | B2: 产品型号 | C2: 总产量 | D2: 成本总计 | E2: 标准单位成本 | F2: 单位成本预算 | G2: Q1 | L2: Q2 | Q2: Q3 | V2: Q4 | AA2: 单位成本
G3: 产量 | H3: 材料成本 | I3: 人工成本 | J3: 制造费用 | K3: 合计 | L3: 产量 | M3: 材料成本 | N3: 人工成本 | O3: 制造费用 | P3: 合计 | Q3: 产量 | R3: 材料成本 | S3: 人工成本 | T3: 制造费用 | U3: 合计 | V3: 产量 | W3: 材料成本 | X3: 人工成本 | Y3: 制造费用 | Z3: 合计 | AA3: 直接材料 | AB3: 直接人工 | AC3: 制造费用
A4: RGP | C4: =收入及成本!D17 -> 0 | D4: =K4+P4+U4+Z4 -> 0 | F4: =D4/C4 -> #DIV/0! | H4: =G4*AA4 -> 0 | I4: =G4*AB4 -> 0 | J4: =G4*AC4 -> 0 | K4: =SUM(H4:J4) -> 0 | M4: =L4*AA4 -> 0 | N4: =L4*AB4 -> 0 | O4: =L4*AC4 -> 0 | P4: =SUM(M4:O4) -> 0 | R4: =Q4*AA4 -> 0 | S4: =Q4*AB4 -> 0 | T4: =Q4*AC4 -> 0 | U4: =SUM(R4:T4) -> 0 | W4: =V4*AA4 -> 0 | X4: =V4*AB4 -> 0 | Y4: =V4*AC4 -> 0 | Z4: =SUM(W4:Y4) -> 0
A5: 离焦镜片 | C5: =收入及成本!D18 -> 0 | D5: =K5+P5+U5+Z5 -> 0 | F5: =D5/C5 -> #DIV/0! | H5: =G5*AA5 -> 0 | I5: =G5*AB5 -> 0 | J5: =G5*AC5 -> 0 | K5: =SUM(H5:J5) -> 0 | M5: =L5*AA5 -> 0 | N5: =L5*AB5 -> 0 | O5: =L5*AC5 -> 0 | P5: =SUM(M5:O5) -> 0 | R5: =Q5*AA5 -> 0 | S5: =Q5*AB5 -> 0 | T5: =Q5*AC5 -> 0 | U5: =SUM(R5:T5) -> 0 | W5: =V5*AA5 -> 0 | X5: =V5*AB5 -> 0 | Y5: =V5*AC5 -> 0 | Z5: =SUM(W5:Y5) -> 0
A8: 总计 | C8: =SUM(C4:C7) -> 0 | D8: =SUM(D4:D7) -> 0 | G8: =SUM(G4:G7) -> 0 | H8: =SUM(H4:H7) -> 0 | I8: =SUM(I4:I7) -> 0 | J8: =SUM(J4:J7) -> 0 | K8: =SUM(K4:K7) -> 0 | L8: =SUM(L4:L7) -> 0 | M8: =SUM(M4:M7) -> 0 | N8: =SUM(N4:N7) -> 0 | ... Z8: =SUM(Z4:Z7) -> 0
H9: =H8+M8+R8+W8 -> 0 | I9: =I8+N8+S8+X8 -> 0 | J9: =J8+O8+T8+Y8 -> 0 | K9: =K8+P8+U8+Z8 -> 0
A10: 制造费用预算表（生产管理人员，QC) | I10: 单位：万元
A11: 费用分类 | B11: Q1 | C11: Q2 | D11: Q3 | E11: Q4 | F11: FY2026 | G11: FY2025 （截至2025.11） | H11: 26/25 | I11: 备注 | K11: 项 目 | M11: Q1 | N11: Q2 | O11: Q3 | P11: Q4 | Q11: FY2026
A12: 折旧 | B12: ='附件3（公共费用分摊表）'!F21 -> 0 | C12: ='附件3（公共费用分摊表）'!G21 -> 0 | D12: ='附件3（公共费用分摊表）'!H21 -> 0 | E12: ='附件3（公共费用分摊表）'!I21 -> 0 | F12: =SUM(B12:E12) -> 0 | G12: 25.597516 | H12: =IFERROR(F12/G12-1,"") -> -1 | K12: 购买商品、接受劳务支付的现金 | M12: =H8*1.13 -> 0 | N12: =M8*1.13 -> 0 | O12: =R8*1.13 -> 0 | P12: =W8*1.13 -> 0 | Q12: =M12+N12+O12+P12 -> 0
A13: 水电费 | B13: ='附件3（公共费用分摊表）'!F17*3 -> 0 | C13: =B13 -> 0 | D13: =B13 -> 0 | E13: =B13 -> 0 | F13: =SUM(B13:E13) -> 0 | G13: 0.541939 | H13: =IFERROR(F13/G13-1,"") -> -1 | K13: 支付给职工以及为职工支付的现金 | M13: =B16+I8 -> 0 | N13: =C16+N8 -> 0 | O13: =D16+S8 -> 0 | P13: =E16+X8 -> 0 | Q13: =M13+N13+O13+P13 -> 0
A14: 加工费 | F14: =SUM(B14:E14) -> 0 | H14: =IFERROR(F14/G14-1,"") | K14: 支付其他与经营活动有关的现金 | M14: =B29-B12-B16-B24-B25-B27 -> 0 | N14: =C29-C12-C16-C24-C25-C27 -> 0 | O14: =D29-D12-D16-D24-D25-D27 -> 0 | P14: =E29-E12-E16-E24-E25-E27 -> 0 | Q14: =M14+N14+O14+P14 -> 0
A15: 维修检测费 | F15: =SUM(B15:E15) -> 0 | G15: 7.865777 | H15: =IFERROR(F15/G15-1,"") -> -1 | K15: 支付其他与筹资活动有关的现金 | M15: =B27 -> 0 | N15: =C27 -> 0 | O15: =D27 -> 0 | P15: =E27 -> 0 | Q15: =M15+N15+O15+P15 -> 0
A16: 人员人工 | B16: ='附件2（人员预算)'!F12/4 -> 0 | C16: =B16 -> 0 | D16: =B16 -> 0 | E16: =B16 -> 0 | F16: =SUM(B16:E16) -> 0 | H16: =IFERROR(F16/G16-1,"") | Q16: =SUM(Q12:Q15)-H9-I9-J9+F12+F24-Q12/1.13*13% -> 0
A17: 办公费 | F17: =SUM(B17:E17) -> 0 | G17: 0.0522 | H17: =IFERROR(F17/G17-1,"") -> -1
A18: 市内交通费 | F18: =SUM(B18:E18) -> 0 | H18: =IFERROR(F18/G18-1,"")
A19: 差旅费 | F19: =SUM(B19:E19) -> 0 | H19: =IFERROR(F19/G19-1,"")
A20: 福利费 | F20: =SUM(B20:E20) -> 0 | H20: =IFERROR(F20/G20-1,"")
A21: 物料消耗 | F21: =SUM(B21:E21) -> 0 | G21: 4.577437 | H21: =IFERROR(F21/G21-1,"") -> -1
A22: 物业费 | F22: =SUM(B22:E22) -> 0 | H22: =IFERROR(F22/G22-1,"")
A23: 运杂费 | F23: =SUM(B23:E23) -> 0 | H23: =IFERROR(F23/G23-1,"")
A24: 摊销费-无形资产 | F24: =SUM(B24:E24) -> 0 | G24: 0.590329 | H24: =IFERROR(F24/G24-1,"") -> -1
A25: 摊销费-其他摊销 | F25: =SUM(B25:E25) -> 0 | H25: =IFERROR(F25/G25-1,"")
A26: 环保费 | F26: =SUM(B26:E26) -> 0 | G26: 1.6 | H26: =IFERROR(F26/G26-1,"") -> -1
A27: 使用权资产折旧 | B27: ='附件3（公共费用分摊表）'!F12*3 -> 0 | C27: =B27 -> 0 | D27: =B27 -> 0 | E27: =B27 -> 0 | F27: =SUM(B27:E27) -> 0 | G27: 5.216486 | H27: =IFERROR(F27/G27-1,"") -> -1
A28: 通讯费 | F28: =SUM(B28:E28) -> 0 | G28: 0.508079 | H28: =IFERROR(F28/G28-1,"") -> -1
A29: 总计 | B29: =SUM(B12:B28) -> 0 | C29: =SUM(C12:C28) -> 0 | D29: =SUM(D12:D28) -> 0 | E29: =SUM(E12:E28) -> 0 | F29: =SUM(F12:F28) -> 0 | G29: =SUM(G12:G28) -> 46.549763 | H29: =IFERROR(F29/G29-1,"") -> -1

Sheet 其他收入及支出
A1: 其他收入及支出预算表
H2: 单位：万元
A3: 项目 | B3: Q1 | C3: Q2 | D3: Q3 | E3: Q4 | F3: FY2026 | G3: FY2025 | H3: 26/25
A4: 信用减值损失 | B4: ='附件5（其他收益明细）'!D16 -> 0 | C4: ='附件5（其他收益明细）'!E16 -> 0 | D4: ='附件5（其他收益明细）'!F16 -> 0 | E4: ='附件5（其他收益明细）'!G16 -> 0 | F4: =SUM(B4:E4) -> 0 | H4: =IFERROR(F4/G4-1,"")
A5: 资产减值损失 | B5: ='附件5（其他收益明细）'!D15 -> 0 | C5: ='附件5（其他收益明细）'!E15 -> 0 | D5: ='附件5（其他收益明细）'!F15 -> 0 | E5: ='附件5（其他收益明细）'!G15 -> 0 | F5: =SUM(B5:E5) -> 0 | H5: =IFERROR(F5/G5-1,"")
A6: 公允价值变动损益 | F6: =SUM(B6:E6) -> 0 | H6: =IFERROR(F6/G6-1,"")
A7: 资产处置收益 | F7: =SUM(B7:E7) -> 0 | H7: =IFERROR(F7/G7-1,"")
A8: 其他收益 | B8: ='附件5（其他收益明细）'!D8 -> 0 | C8: ='附件5（其他收益明细）'!E8 -> 0 | D8: ='附件5（其他收益明细）'!F8 -> 0 | E8: ='附件5（其他收益明细）'!G8 -> 0 | F8: =SUM(B8:E8) -> 0 | H8: =IFERROR(F8/G8-1,"")
A9: 其中：退税 | F9: =SUM(B9:E9) -> 0 | H9: =IFERROR(F9/G9-1,"")
A10: 政府补贴 | B10: ='附件5（其他收益明细）'!D4+'附件5（其他收益明细）'!D5+'附件5（其他收益明细）'!D6+G17 -> 0 | C10: ='附件5（其他收益明细）'!E4+'附件5（其他收益明细）'!E5+'附件5（其他收益明细）'!E6 -> 0 | D10: ='附件5（其他收益明细）'!F4+'附件5（其他收益明细）'!F5+'附件5（其他收益明细）'!F6 -> 0 | E10: ='附件5（其他收益明细）'!G4+'附件5（其他收益明细）'!G5+'附件5（其他收益明细）'!G6 -> 0 | F10: =SUM(B10:E10) -> 0 | H10: =IFERROR(F10/G10-1,"")
A11: 营业外收入 | F11: =SUM(B11:E11) -> 0 | H11: =IFERROR(F11/G11-1,"")
A12: 营业外支出 | F12: =SUM(B12:E12) -> 0 | H12: =IFERROR(F12/G12-1,"")
A14: 政府补助，按照应取得的分项列示，标注可取得的概率、金额和时间，对于和费用联动的补助，按净额法放此列
A16: 项目 | B16: 明细项目 | C16: 计划取得日期 | D16: 可取得概率 | E16: 收益金额 | F16: 费用金额 | G16: 净额
A17: 其他收益 | G17: =E17-F17 -> 0
G18: =E18-F18 -> 0
G19: =E19-F19 -> 0
G20: =E20-F20 -> 0
G21: =E21-F21 -> 0
G22: =E22-F22 -> 0
G23: =E23-F23 -> 0
E24: =SUM(E17:E23) -> 0 | G24: =E24-F24 -> 0
A28: 项 目 | C28: Q1 | D28: Q2 | E28: Q3 | F28: Q4 | G28: FY2026
A29: 收到的税费返还 | D29: =C9 -> 0 | E29: =D9 -> 0 | F29: =E9 -> 0 | G29: =SUM(C29:F29) -> 0
A30: 收到其他与经营活动有关的现金 | C30: =B8+B11 -> 0 | D30: =C8+C11 -> 0 | E30: =D8+D11 -> 0 | F30: =E8+E11 -> 0 | G30: =SUM(C30:F30) -> 0
A31: 支付其他与经营活动有关的现金 | C31: =B12 -> 0 | D31: =C12 -> 0 | E31: =D12 -> 0 | F31: =E12 -> 0 | G31: =SUM(C31:F31) -> 0

Sheet 费用预算
A1: 费用预算表
I2: 单位：万元
A3: 费用分类 | C3: Q1 | D3: Q2 | E3: Q3 | F3: Q4 | G3: FY2026 | H3: FY2025 （截至2025.11） | I3: 0.0104 | J3: 备注
A5: 人年数
A6: 费用总计 | C6: =SUM(C7:C8) -> 100.87 | D6: =SUM(D7:D8) -> 100.87 | E6: =SUM(E7:E8) -> 100.87 | F6: =SUM(F7:F8) -> 100.87 | G6: =SUM(G7:G8) -> 403.48 | H6: =SUM(H7:H8) -> 405.76524 | I6: =IFERROR(G6/H6-1,"") -> -0.0056319338
A7: 总部费用分摊合计 | I7: =IFERROR(G7/H7-1,"")
A8: 期间费用合计 | C8: =SUM(C9:C12) -> 100.87 | D8: =SUM(D9:D12) -> 100.87 | E8: =SUM(E9:E12) -> 100.87 | F8: =SUM(F9:F12) -> 100.87 | G8: =SUM(G9:G12) -> 403.48 | H8: =SUM(H9:H12) -> 405.76524 | I8: =IFERROR(G8/H8-1,"") -> -0.0056319338
A9: 其中：人员费用合计 | C9: =SUM(C45:C51) -> 0 | D9: =SUM(D45:D51) -> 0 | E9: =SUM(E45:E51) -> 0 | F9: =SUM(F45:F51) -> 0 | G9: =SUM(G45:G51) -> 0 | H9: =SUM(H45:H51) -> 0 | I9: =IFERROR(G9/H9-1,"")
A10: 公共费用合计 | C10: =SUM(C36:C44) -> 0 | D10: =SUM(D36:D44) -> 0 | E10: =SUM(E36:E44) -> 0 | F10: =SUM(F36:F44) -> 0 | G10: =SUM(G36:G44) -> 0 | H10: =SUM(H36:H44) -> 59.238034 | I10: =IFERROR(G10/H10-1,"") -> -1
A11: 日常费用合计 | C11: =SUM(C13:C22) -> 23.3 | D11: =SUM(D13:D22) -> 23.3 | E11: =SUM(E13:E22) -> 23.3 | F11: =SUM(F13:F22) -> 23.3 | G11: =SUM(G13:G22) -> 93.2 | H11: =SUM(H13:H22) -> 96.400884 | I11: =IFERROR(G11/H11-1,"") -> -0.033203886
A12: 专项费用合计 | C12: =SUM(C23:C35) -> 77.57 | D12: =SUM(D23:D35) -> 77.57 | E12: =SUM(E23:E35) -> 77.57 | F12: =SUM(F23:F35) -> 77.57 | G12: =SUM(G23:G35) -> 310.28 | H12: =SUM(H23:H35) -> 250.12633 | I12: =IFERROR(G12/H12-1,"") -> 0.24049318
A13: 日常费用 | B13: 办公费 | C13: ='附件1.1费用预算（管理）'!C13+'附件1.2费用预算（销售）'!C13 -> 0.125 | D13: ='附件1.1费用预算（管理）'!D13+'附件1.2费用预算（销售）'!D13 -> 0.125 | E13: ='附件1.1费用预算（管理）'!E13+'附件1.2费用预算（销售）'!E13 -> 0.125 | F13: ='附件1.1费用预算（管理）'!F13+'附件1.2费用预算（销售）'!F13 -> 0.125 | G13: =SUM(C13:F13) -> 0.5 | H13: ='附件1.1费用预算（管理）'!H13+'附件1.2费用预算（销售）'!H13 -> 1.749161 | I13: =IFERROR(G13/H13-1,"") -> -0.71414867
B14: 通讯费 | C14: ='附件1.1费用预算（管理）'!C14+'附件1.2费用预算（销售）'!C14 -> 1.02 | D14: ='附件1.1费用预算（管理）'!D14+'附件1.2费用预算（销售）'!D14 -> 1.02 | E14: ='附件1.1费用预算（管理）'!E14+'附件1.2费用预算（销售）'!E14 -> 1.02 | F14: ='附件1.1费用预算（管理）'!F14+'附件1.2费用预算（销售）'!F14 -> 1.02 | G14: =SUM(C14:F14) -> 4.08 | H14: ='附件1.1费用预算（管理）'!H14+'附件1.2费用预算（销售）'!H14 -> 2.621484 | I14: =IFERROR(G14/H14-1,"") -> 0.55637036
B15: 市内交通费 | C15: ='附件1.1费用预算（管理）'!C15+'附件1.2费用预算（销售）'!C15 -> 1.605 | D15: ='附件1.1费用预算（管理）'!D15+'附件1.2费用预算（销售）'!D15 -> 1.605 | E15: ='附件1.1费用预算（管理）'!E15+'附件1.2费用预算（销售）'!E15 -> 1.605 | F15: ='附件1.1费用预算（管理）'!F15+'附件1.2费用预算（销售）'!F15 -> 1.605 | G15: =SUM(C15:F15) -> 6.42 | H15: ='附件1.1费用预算（管理）'!H15+'附件1.2费用预算（销售）'!H15 -> 4.220902 | I15: =IFERROR(G15/H15-1,"") -> 0.52100191
B16: 境内差旅费 | C16: ='附件1.1费用预算（管理）'!C16+'附件1.2费用预算（销售）'!C16 -> 19.95 | D16: ='附件1.1费用预算（管理）'!D16+'附件1.2费用预算（销售）'!D16 -> 19.95 | E16: ='附件1.1费用预算（管理）'!E16+'附件1.2费用预算（销售）'!E16 -> 19.95 | F16: ='附件1.1费用预算（管理）'!F16+'附件1.2费用预算（销售）'!F16 -> 19.95 | G16: =SUM(C16:F16) -> 79.8 | H16: ='附件1.1费用预算（管理）'!H16+'附件1.2费用预算（销售）'!H16 -> 75.063253 | I16: =IFERROR(G16/H16-1,"") -> 0.063103407
B17: 福利费（餐费） | C17: ='附件1.1费用预算（管理）'!C17+'附件1.2费用预算（销售）'!C17 -> 0 | D17: ='附件1.1费用预算（管理）'!D17+'附件1.2费用预算（销售）'!D17 -> 0 | E17: ='附件1.1费用预算（管理）'!E17+'附件1.2费用预算（销售）'!E17 -> 0 | F17: ='附件1.1费用预算（管理）'!F17+'附件1.2费用预算（销售）'!F17 -> 0 | G17: =SUM(C17:F17) -> 0 | H17: ='附件1.1费用预算（管理）'!H17+'附件1.2费用预算（销售）'!H17 -> 0 | I17: =IFERROR(G17/H17-1,"")
B18: 境外差旅费 | C18: ='附件1.1费用预算（管理）'!C18+'附件1.2费用预算（销售）'!C18 -> 0 | D18: ='附件1.1费用预算（管理）'!D18+'附件1.2费用预算（销售）'!D18 -> 0 | E18: ='附件1.1费用预算（管理）'!E18+'附件1.2费用预算（销售）'!E18 -> 0 | F18: ='附件1.1费用预算（管理）'!F18+'附件1.2费用预算（销售）'!F18 -> 0 | G18: =SUM(C18:F18) -> 0 | H18: ='附件1.1费用预算（管理）'!H18+'附件1.2费用预算（销售）'!H18 -> 2.742189 | I18: =IFERROR(G18/H18-1,"") -> -1
B19: 会议费 | C19: ='附件1.1费用预算（管理）'!C19+'附件1.2费用预算（销售）'!C19 -> 0 | D19: ='附件1.1费用预算（管理）'!D19+'附件1.2费用预算（销售）'!D19 -> 0 | E19: ='附件1.1费用预算（管理）'!E19+'附件1.2费用预算（销售）'!E19 -> 0 | F19: ='附件1.1费用预算（管理）'!F19+'附件1.2费用预算（销售）'!F19 -> 0 | G19: =SUM(C19:F19) -> 0 | H19: ='附件1.1费用预算（管理）'!H19+'附件1.2费用预算（销售）'!H19 -> 2.818129 | I19: =IFERROR(G19/H19-1,"") -> -1
B20: 运杂费 | C20: ='附件1.1费用预算（管理）'!C20+'附件1.2费用预算（销售）'!C20 -> 0.6 | D20: ='附件1.1费用预算（管理）'!D20+'附件1.2费用预算（销售）'!D20 -> 0.6 | E20: ='附件1.1费用预算（管理）'!E20+'附件1.2费用预算（销售）'!E20 -> 0.6 | F20: ='附件1.1费用预算（管理）'!F20+'附件1.2费用预算（销售）'!F20 -> 0.6 | G20: =SUM(C20:F20) -> 2.4 | H20: ='附件1.1费用预算（管理）'!H20+'附件1.2费用预算（销售）'!H20 -> 7.185766 | I20: =IFERROR(G20/H20-1,"") -> -0.66600638
B21: 中标服务费 | C21: ='附件1.1费用预算（管理）'!C21+'附件1.2费用预算（销售）'!C21 -> 0 | D21: ='附件1.1费用预算（管理）'!D21+'附件1.2费用预算（销售）'!D21 -> 0 | E21: ='附件1.1费用预算（管理）'!E21+'附件1.2费用预算（销售）'!E21 -> 0 | F21: ='附件1.1费用预算（管理）'!F21+'附件1.2费用预算（销售）'!F21 -> 0 | G21: =SUM(C21:F21) -> 0 | H21: ='附件1.1费用预算（管理）'!H21+'附件1.2费用预算（销售）'!H21 -> 0 | I21: =IFERROR(G21/H21-1,"")
B22: 样机费 | C22: ='附件1.1费用预算（管理）'!C22+'附件1.2费用预算（销售）'!C22 -> 0 | D22: ='附件1.1费用预算（管理）'!D22+'附件1.2费用预算（销售）'!D22 -> 0 | E22: ='附件1.1费用预算（管理）'!E22+'附件1.2费用预算（销售）'!E22 -> 0 | F22: ='附件1.1费用预算（管理）'!F22+'附件1.2费用预算（销售）'!F22 -> 0 | G22: =SUM(C22:F22) -> 0 | H22: ='附件1.1费用预算（管理）'!H22+'附件1.2费用预算（销售）'!H22 -> 0 | I22: =IFERROR(G22/H22-1,"")
A23: 管理专项费用 | B23: 培训费 | C23: ='附件1.1费用预算（管理）'!C23+'附件1.2费用预算（销售）'!C23 -> 0 | D23: ='附件1.1费用预算（管理）'!D23+'附件1.2费用预算（销售）'!D23 -> 0 | E23: ='附件1.1费用预算（管理）'!E23+'附件1.2费用预算（销售）'!E23 -> 0 | F23: ='附件1.1费用预算（管理）'!F23+'附件1.2费用预算（销售）'!F23 -> 0 | G23: =SUM(C23:F23) -> 0 | H23: ='附件1.1费用预算（管理）'!H23+'附件1.2费用预算（销售）'!H23 -> 0 | I23: =IFERROR(G23/H23-1,"")
B24: 咨询服务费 | C24: ='附件1.1费用预算（管理）'!C24+'附件1.2费用预算（销售）'!C24 -> 0 | D24: ='附件1.1费用预算（管理）'!D24+'附件1.2费用预算（销售）'!D24 -> 0 | E24: ='附件1.1费用预算（管理）'!E24+'附件1.2费用预算（销售）'!E24 -> 0 | F24: ='附件1.1费用预算（管理）'!F24+'附件1.2费用预算（销售）'!F24 -> 0 | G24: =SUM(C24:F24) -> 0 | H24: ='附件1.1费用预算（管理）'!H24+'附件1.2费用预算（销售）'!H24 -> 38.517036 | I24: =IFERROR(G24/H24-1,"") -> -1
B25: 劳务费（管理） | C25: ='附件1.1费用预算（管理）'!C25+'附件1.2费用预算（销售）'!C25 -> 0 | D25: ='附件1.1费用预算（管理）'!D25+'附件1.2费用预算（销售）'!D25 -> 0 | E25: ='附件1.1费用预算（管理）'!E25+'附件1.2费用预算（销售）'!E25 -> 0 | F25: ='附件1.1费用预算（管理）'!F25+'附件1.2费用预算（销售）'!F25 -> 0 | G25: =SUM(C25:F25) -> 0 | H25: ='附件1.1费用预算（管理）'!H25+'附件1.2费用预算（销售）'!H25 -> 0.825 | I25: =IFERROR(G25/H25-1,"") -> -1
A26: 市场专项费用 | B26: 业务招待费 | C26: ='附件1.1费用预算（管理）'!C26+'附件1.2费用预算（销售）'!C26 -> 5.82 | D26: ='附件1.1费用预算（管理）'!D26+'附件1.2费用预算（销售）'!D26 -> 5.82 | E26: ='附件1.1费用预算（管理）'!E26+'附件1.2费用预算（销售）'!E26 -> 5.82 | F26: ='附件1.1费用预算（管理）'!F26+'附件1.2费用预算（销售）'!F26 -> 5.82 | G26: =SUM(C26:F26) -> 23.28 | H26: ='附件1.1费用预算（管理）'!H26+'附件1.2费用预算（销售）'!H26 -> 20.760336 | I26: =IFERROR(G26/H26-1,"") -> 0.12136913
B27: 市场推广费 | C27: ='附件1.1费用预算（管理）'!C27+'附件1.2费用预算（销售）'!C27 -> 65.25 | D27: ='附件1.1费用预算（管理）'!D27+'附件1.2费用预算（销售）'!D27 -> 65.25 | E27: ='附件1.1费用预算（管理）'!E27+'附件1.2费用预算（销售）'!E27 -> 65.25 | F27: ='附件1.1费用预算（管理）'!F27+'附件1.2费用预算（销售）'!F27 -> 65.25 | G27: =SUM(C27:F27) -> 261 | H27: ='附件1.1费用预算（管理）'!H27+'附件1.2费用预算（销售）'!H27 -> 181.17432 | I27: =IFERROR(G27/H27-1,"") -> 0.44060149
B28: 广告费 | C28: ='附件1.1费用预算（管理）'!C28+'附件1.2费用预算（销售）'!C28 -> 0 | D28: ='附件1.1费用预算（管理）'!D28+'附件1.2费用预算（销售）'!D28 -> 0 | E28: ='附件1.1费用预算（管理）'!E28+'附件1.2费用预算（销售）'!E28 -> 0 | F28: ='附件1.1费用预算（管理）'!F28+'附件1.2费用预算（销售）'!F28 -> 0 | G28: =SUM(C28:F28) -> 0 | H28: ='附件1.1费用预算（管理）'!H28+'附件1.2费用预算（销售）'!H28 -> 0 | I28: =IFERROR(G28/H28-1,"")
B29: 劳务费（市场） | C29: ='附件1.1费用预算（管理）'!C29+'附件1.2费用预算（销售）'!C29 -> 6.5 | D29: ='附件1.1费用预算（管理）'!D29+'附件1.2费用预算（销售）'!D29 -> 6.5 | E29: ='附件1.1费用预算（管理）'!E29+'附件1.2费用预算（销售）'!E29 -> 6.5 | F29: ='附件1.1费用预算（管理）'!F29+'附件1.2费用预算（销售）'!F29 -> 6.5 | G29: =SUM(C29:F29) -> 26 | H29: ='附件1.1费用预算（管理）'!H29+'附件1.2费用预算（销售）'!H29 -> 5.820356 | I29: =IFERROR(G29/H29-1,"") -> 3.4670807
B30: 客户培训费 | C30: ='附件1.1费用预算（管理）'!C30+'附件1.2费用预算（销售）'!C30 -> 0 | D30: ='附件1.1费用预算（管理）'!D30+'附件1.2费用预算（销售）'!D30 -> 0 | E30: ='附件1.1费用预算（管理）'!E30+'附件1.2费用预算（销售）'!E30 -> 0 | F30: ='附件1.1费用预算（管理）'!F30+'附件1.2费用预算（销售）'!F30 -> 0 | G30: =SUM(C30:F30) -> 0 | H30: ='附件1.1费用预算（管理）'!H30+'附件1.2费用预算（销售）'!H30 -> 0 | I30: =IFERROR(G30/H30-1,"")
B31: 注册费 | C31: ='附件1.1费用预算（管理）'!C31+'附件1.2费用预算（销售）'!C31 -> 0 | D31: ='附件1.1费用预算（管理）'!D31+'附件1.2费用预算（销售）'!D31 -> 0 | E31: ='附件1.1费用预算（管理）'!E31+'附件1.2费用预算（销售）'!E31 -> 0 | F31: ='附件1.1费用预算（管理）'!F31+'附件1.2费用预算（销售）'!F31 -> 0 | G31: =SUM(C31:F31) -> 0 | H31: ='附件1.1费用预算（管理）'!H31+'附件1.2费用预算（销售）'!H31 -> 2.816
B32: 研究费用 | C32: ='附件1.1费用预算（管理）'!C32+'附件1.2费用预算（销售）'!C32 -> 0 | D32: ='附件1.1费用预算（管理）'!D32+'附件1.2费用预算（销售）'!D32 -> 0 | E32: ='附件1.1费用预算（管理）'!E32+'附件1.2费用预算（销售）'!E32 -> 0 | F32: ='附件1.1费用预算（管理）'!F32+'附件1.2费用预算（销售）'!F32 -> 0 | G32: =SUM(C32:F32) -> 0 | H32: ='附件1.1费用预算（管理）'!H32+'附件1.2费用预算（销售）'!H32 -> 0 | I32: =IFERROR(G32/H32-1,"")
A33: 其他专项 | B33: 存货损失 | C33: ='附件1.1费用预算（管理）'!C33+'附件1.2费用预算（销售）'!C33 -> 0 | D33: ='附件1.1费用预算（管理）'!D33+'附件1.2费用预算（销售）'!D33 -> 0 | E33: ='附件1.1费用预算（管理）'!E33+'附件1.2费用预算（销售）'!E33 -> 0 | F33: ='附件1.1费用预算（管理）'!F33+'附件1.2费用预算（销售）'!F33 -> 0 | G33: =SUM(C33:F33) -> 0 | H33: ='附件1.1费用预算（管理）'!H33+'附件1.2费用预算（销售）'!H33 -> 0 | I33: =IFERROR(G33/H33-1,"")
B34: 税费 | C34: ='附件1.1费用预算（管理）'!C34+'附件1.2费用预算（销售）'!C34 -> 0 | D34: ='附件1.1费用预算（管理）'!D34+'附件1.2费用预算（销售）'!D34 -> 0 | E34: ='附件1.1费用预算（管理）'!E34+'附件1.2费用预算（销售）'!E34 -> 0 | F34: ='附件1.1费用预算（管理）'!F34+'附件1.2费用预算（销售）'!F34 -> 0 | G34: =SUM(C34:F34) -> 0 | H34: ='附件1.1费用预算（管理）'!H34+'附件1.2费用预算（销售）'!H34 -> 0 | I34: =IFERROR(G34/H34-1,"")
B35: 售后维修费 | C35: ='附件1.1费用预算（管理）'!C35+'附件1.2费用预算（销售）'!C35 -> 0 | D35: ='附件1.1费用预算（管理）'!D35+'附件1.2费用预算（销售）'!D35 -> 0 | E35: ='附件1.1费用预算（管理）'!E35+'附件1.2费用预算（销售）'!E35 -> 0 | F35: ='附件1.1费用预算（管理）'!F35+'附件1.2费用预算（销售）'!F35 -> 0 | G35: =SUM(C35:F35) -> 0 | H35: ='附件1.1费用预算（管理）'!H35+'附件1.2费用预算（销售）'!H35 -> 0.213274 | I35: =IFERROR(G35/H35-1,"") -> -1
A36: 公共费用 | B36: 租赁费 | C36: ='附件1.1费用预算（管理）'!C36+'附件1.2费用预算（销售）'!C36 -> 0 | D36: ='附件1.1费用预算（管理）'!D36+'附件1.2费用预算（销售）'!D36 -> 0 | E36: ='附件1.1费用预算（管理）'!E36+'附件1.2费用预算（销售）'!E36 -> 0 | F36: ='附件1.1费用预算（管理）'!F36+'附件1.2费用预算（销售）'!F36 -> 0 | G36: =SUM(C36:F36) -> 0 | H36: ='附件1.1费用预算（管理）'!H36+'附件1.2费用预算（销售）'!H36 -> 18.007176 | I36: =IFERROR(G36/H36-1,"") -> -1
B37: 水电物业费 | C37: ='附件1.1费用预算（管理）'!C37+'附件1.2费用预算（销售）'!C37 -> 0 | D37: ='附件1.1费用预算（管理）'!D37+'附件1.2费用预算（销售）'!D37 -> 0 | E37: ='附件1.1费用预算（管理）'!E37+'附件1.2费用预算（销售）'!E37 -> 0 | F37: ='附件1.1费用预算（管理）'!F37+'附件1.2费用预算（销售）'!F37 -> 0 | G37: =SUM(C37:F37) -> 0 | H37: ='附件1.1费用预算（管理）'!H37+'附件1.2费用预算（销售）'!H37 -> 10.4 | I37: =IFERROR(G37/H37-1,"") -> -1
B38: 折旧费 | C38: ='附件1.1费用预算（管理）'!C38+'附件1.2费用预算（销售）'!C38 -> 0 | D38: ='附件1.1费用预算（管理）'!D38+'附件1.2费用预算（销售）'!D38 -> 0 | E38: ='附件1.1费用预算（管理）'!E38+'附件1.2费用预算（销售）'!E38 -> 0 | F38: ='附件1.1费用预算（管理）'!F38+'附件1.2费用预算（销售）'!F38 -> 0 | G38: =SUM(C38:F38) -> 0 | H38: ='附件1.1费用预算（管理）'!H38+'附件1.2费用预算（销售）'!H38 -> 2.030609 | I38: =IFERROR(G38/H38-1,"") -> -1
B39: 无形资产摊销 | C39: ='附件1.1费用预算（管理）'!C39+'附件1.2费用预算（销售）'!C39 -> 0 | D39: ='附件1.1费用预算（管理）'!D39+'附件1.2费用预算（销售）'!D39 -> 0 | E39: ='附件1.1费用预算（管理）'!E39+'附件1.2费用预算（销售）'!E39 -> 0 | F39: ='附件1.1费用预算（管理）'!F39+'附件1.2费用预算（销售）'!F39 -> 0 | G39: =SUM(C39:F39) -> 0 | H39: ='附件1.1费用预算（管理）'!H39+'附件1.2费用预算（销售）'!H39 -> 0.014399
B40: 装修费摊销 | C40: ='附件1.1费用预算（管理）'!C40+'附件1.2费用预算（销售）'!C40 -> 0 | D40: ='附件1.1费用预算（管理）'!D40+'附件1.2费用预算（销售）'!D40 -> 0 | E40: ='附件1.1费用预算（管理）'!E40+'附件1.2费用预算（销售）'!E40 -> 0 | F40: ='附件1.1费用预算（管理）'!F40+'附件1.2费用预算（销售）'!F40 -> 0 | G40: =SUM(C40:F40) -> 0 | H40: ='附件1.1费用预算（管理）'!H40+'附件1.2费用预算（销售）'!H40 -> 0 | I40: =IFERROR(G40/H40-1,"")
B41: 车辆费 | C41: ='附件1.1费用预算（管理）'!C41+'附件1.2费用预算（销售）'!C41 -> 0 | D41: ='附件1.1费用预算（管理）'!D41+'附件1.2费用预算（销售）'!D41 -> 0 | E41: ='附件1.1费用预算（管理）'!E41+'附件1.2费用预算（销售）'!E41 -> 0 | F41: ='附件1.1费用预算（管理）'!F41+'附件1.2费用预算（销售）'!F41 -> 0 | G41: =SUM(C41:F41) -> 0 | H41: ='附件1.1费用预算（管理）'!H41+'附件1.2费用预算（销售）'!H41 -> 0.05 | I41: =IFERROR(G41/H41-1,"") -> -1
...

Sheet 资产预算
A1: 固定&无形资产预算表 | M1: 单位：万元
A2: 序号 | B2: 资产名称 | C2: 项目名称 | D2: 使用部门 | E2: 资产用途 | F2: 计划采购日期 | G2: 计划到货日期 | H2: 数量 | I2: 单价 | J2: 预算金额 | K2: Q1 | L2: Q2 | M2: Q3 | N2: Q4
B3: 总计 | J3: =SUM(J4:J13) -> 0 | K3: =SUM(K4:K13) -> 0 | L3: =SUM(L4:L13) -> 0 | M3: =SUM(M4:M13) -> 0 | N3: =SUM(N4:N13) -> 0
A4: =ROW()-3 -> 1 | J4: =H4*I4 -> 0 | O4: =J4-SUM(K4:N4) -> 0 | Q4: 办公类 | R4: 部门
A5: =ROW()-3 -> 2 | J5: =H5*I5 -> 0 | O5: =J5-SUM(K5:N5) -> 0 | Q5: 生产设备 | R5: 苏州高清-研发部
A6: =ROW()-3 -> 3 | J6: =H6*I6 -> 0 | O6: =J6-SUM(K6:N6) -> 0 | Q6: RD1202 | R6: 苏州高清-采购部
A7: =ROW()-3 -> 4 | J7: =H7*I7 -> 0 | O7: =J7-SUM(K7:N7) -> 0 | Q7: RD1204 | R7: 苏州高清-生产部
A8: =ROW()-3 -> 5 | O8: =J8-SUM(K8:N8) -> 0 | Q8: RD1205 | R8: 苏州高清-市场部
A9: =ROW()-3 -> 6 | J9: =H9*I9 -> 0 | O9: =J9-SUM(K9:N9) -> 0 | Q9: RD1206 | R9: 苏州高清-销售部
A10: =ROW()-3 -> 7 | J10: =H10*I10 -> 0 | O10: =J10-SUM(K10:N10) -> 0 | Q10: 无形资产 | R10: 苏州高清-质量管理部
A11: =ROW()-3 -> 8 | J11: =H11*I11 -> 0 | O11: =J11-SUM(K11:N11) -> 0 | R11: 苏州高清-注册部
A12: =ROW()-3 -> 9 | J12: =H12*I12 -> 0 | O12: =J12-SUM(K12:N12) -> 0 | R12: 苏州高清-总经办
A13: =ROW()-3 -> 10 | J13: =H13*I13 -> 0 | O13: =J13-SUM(K13:N13) -> 0
A15: 其他长期资产预算表
A16: 序号 | B16: 项目编码 | C16: 项目名称 | D16: 使用部门 | E16: 资产用途 | F16: 计划采购日期 | G16: 计划到货日期 | H16: 数量 | I16: 单价 | J16: 预算金额 | K16: Q1 | L16: Q2 | M16: Q3 | N16: Q4
A17: 1
A18: 2
A19: 3
J20: =SUM(J17:J19) -> 0 | K20: =SUM(K17:K19) -> 0 | L20: =SUM(L17:L19) -> 0 | M20: =SUM(M17:M19) -> 0 | N20: =SUM(N17:N19) -> 0
F22: 项目 | J22: FY2026 | K22: Q1 | L22: Q2 | M22: Q3 | N22: Q4
F23: 支付其他与经营活动有关的现金 | J23: =J20 -> 0 | K23: =K20 -> 0 | L23: =L20 -> 0 | M23: =M20 -> 0 | N23: =N20 -> 0
F24: 购建固定资产、无形资产和其他长期资产支付的现金 | J24: =J3 -> 0 | K24: =K3 -> 0 | L24: =L3 -> 0 | M24: =M3 -> 0 | N24: =N3 -> 0

Sheet 研发预算
A1: 研发项目预算表 | H1: 单位：万元 | I1: =A35 -> RD1202 | N1: =A36 -> RD1204 | S1: =A37 -> RD1205 | X1: =A38 -> RD1206 | AC1: =A39 -> RD1207
A2: 分类 | B2: FY2025 | C2: FY2026 | D2: Q1 | E2: Q2 | F2: Q3 | G2: Q4 | H2: 备注 | I2: FY2025 | J2: Q1 | K2: Q2 | L2: Q3 | M2: Q4 | N2: FY2025 | O2: Q1 | P2: Q2 | Q2: Q3 | R2: Q4 | S2: FY2025 | T2: Q1 | U2: Q2 | V2: Q3 | W2: Q4 | X2: FY2026 | Y2: Q1 | Z2: Q2 | AA2: Q3 | AB2: Q4 | AC2: FY2026 | AD2: Q1 | AE2: Q2 | AF2: Q3 | AG2: Q4 | AH2: FY2026 | AI2: Q1 | AJ2: Q2 | AK2: Q3 | AL2: Q4 | AM2: FY2026 | AN2: Q1 | AO2: Q2 | AP2: Q3 | AQ2: Q4
A3: 资金支出总计 | B3: =SUM(B6:B27)-B16-B19-B21 -> 429.83682 | C3: =SUM(D3:G3) -> 0 | D3: =SUM(D6:D27)-D16-D19-D21 -> 0 | E3: =SUM(E6:E27)-E16-E19-E21 -> 0 | F3: =SUM(F6:F27)-F16-F19-F21 -> 0 | G3: =SUM(G6:G27)-G16-G19-G21 -> 0 | I3: =SUM(I6:I27)-I16-I19-I21 -> #DIV/0! | J3: =SUM(J6:J27)-J16-J19-J21 -> #DIV/0! | K3: =SUM(K6:K27)-K16-K19-K21 -> #DIV/0! | L3: =SUM(L6:L27)-L16-L19-L21 -> #DIV/0! | M3: =SUM(M6:M27)-M16-M19-M21 -> #DIV/0! | N3: =SUM(N6:N27)-N16-N19-N21 -> #DIV/0! | O3: =SUM(O6:O27)-O16-O19-O21 -> #DIV/0! | P3: =SUM(P6:P27)-P16-P19-P21 -> #DIV/0! | ... AM3: =SUM(AM6:AM27)-AM16-AM19-AM21 -> 0 | AN3: =SUM(AN6:AN24)-AN17-AN22 -> 0 | AO3: =SUM(AO6:AO24)-AO17-AO22 -> 0 | AP3: =SUM(AP6:AP24)-AP17-AP22 -> 0 | AQ3: =SUM(AQ6:AQ24)-AQ17-AQ22 -> 0 | AR3: =SUM(I3:AQ3)/2-C3 -> #DIV/0!
A4: 费用化总计 | B4: =SUM(B6:B23)-B15-B18-B20 -> 457.98354 | C4: =SUM(D4:G4) -> 0 | D4: =SUM(D6:D23)-D15-D18-D20 -> 0 | E4: =SUM(E6:E23)-E15-E18-E20 -> 0 | F4: =SUM(F6:F23)-F15-F18-F20 -> 0 | G4: =SUM(G6:G23)-G15-G18-G20 -> 0 | I4: =SUM(I6:I23)-I15-I18-I20 -> #DIV/0! | J4: =SUM(J6:J23)-J15-J18-J20 -> #DIV/0! | K4: =SUM(K6:K23)-K15-K18-K20 -> #DIV/0! | L4: =SUM(L6:L23)-L15-L18-L20 -> #DIV/0! | M4: =SUM(M6:M23)-M15-M18-M20 -> #DIV/0! | N4: =SUM(N6:N23)-N15-N18-N20 -> #DIV/0! | O4: =SUM(O6:O23)-O15-O18-O20 -> #DIV/0! | P4: =SUM(P6:P23)-P15-P18-P20 -> #DIV/0! | ... AM4: =SUM(AM6:AM23)-AM15-AM18-AM20 -> 0 | AN4: =SUM(AN6:AN24)-AN8-AN16-AN19-AN21 -> 0 | AO4: =SUM(AO6:AO24)-AO8-AO16-AO19-AO21 -> 0 | AP4: =SUM(AP6:AP24)-AP8-AP16-AP19-AP21 -> 0 | AQ4: =SUM(AQ6:AQ24)-AQ8-AQ16-AQ19-AQ21 -> 0 | AR4: =SUM(I4:AQ4)/2-C4 -> #DIV/0!
A5: 资本化总计 | B5: =SUM(B24:B27) -> 34.675891 | C5: =SUM(D5:G5) -> 0 | D5: =SUM(D24:D27) -> 0 | E5: =SUM(E24:E27) -> 0 | F5: =SUM(F24:F27) -> 0 | G5: =SUM(G24:G27) -> 0 | I5: =SUM(I24:I27) -> 0 | J5: =SUM(J24:J27) -> 0 | K5: =SUM(K24:K27) -> 0 | L5: =SUM(L24:L27) -> 0 | M5: =SUM(M24:M27) -> 0 | N5: =SUM(N24:N27) -> 0 | O5: =SUM(O24:O27) -> 0 | P5: =SUM(P24:P27) -> 0 | ... AM5: =SUM(AM24:AM27) -> 0 | AN5: =AN8 -> 0 | AO5: =AO8 -> 0 | AP5: =AP8 -> 0 | AQ5: =AQ8 -> 0 | AR5: =SUM(I5:AQ5)/2-C5 -> 0
A6: 材料 | B6: 23.493631 | C6: =SUM(D6:G6) -> 0 | D6: =J6+O6+T6+Y6+AD6 -> 0 | E6: =K6+P6+U6+Z6+AE6 -> 0 | F6: =L6+Q6+V6+AA6+AF6 -> 0 | G6: =M6+R6+W6+AB6+AG6 -> 0 | H6: 子项目 | I6: =SUM(J6:M6) -> 0 | N6: =SUM(O6:R6) -> 0 | S6: =SUM(T6:W6) -> 0 | X6: =SUM(Y6:AB6) -> 0 | AC6: =SUM(AD6:AG6) -> 0 | AH6: =SUM(AI6:AL6) -> 0 | AM6: =SUM(AN6:AQ6) -> 0 | AR6: =SUM(I6:AQ6)/2-C6 -> 0
A7: 动力费 | B7: 2.630694 | C7: =SUM(D7:G7) -> 0 | D7: ='附件3（公共费用分摊表）'!G17*3 -> 0 | E7: =D7 -> 0 | F7: =D7 -> 0 | G7: =D7 -> 0 | H7: 子项目 | I7: =SUM(J7:M7) -> #DIV/0! | J7: =D7*D35 -> #DIV/0! | K7: =E7*E35 -> #DIV/0! | L7: =F7*F35 -> #DIV/0! | M7: =G7*G35 -> #DIV/0! | N7: =SUM(O7:R7) -> #DIV/0! | O7: =D7*D36 -> #DIV/0! | P7: =E7*E36 -> #DIV/0! | Q7: =F7*F36 -> #DIV/0! | R7: =G7*G36 -> #DIV/0! | S7: =SUM(T7:W7) -> #DIV/0! | T7: =D37*D7 -> #DIV/0! | U7: =E37*E7 -> #DIV/0! | V7: =F37*F7 -> #DIV/0! | W7: =G37*G7 -> #DIV/0! | X7: =SUM(Y7:AB7) -> #DIV/0! | Y7: =D7*D38 -> #DIV/0! | Z7: =E7*E38 -> #DIV/0! | AA7: =F7*F38 -> #DIV/0! | AB7: =G7*G38 -> #DIV/0! | AC7: =SUM(AD7:AG7) -> #DIV/0! | AD7: =D7*D39 -> #DIV/0! | AE7: =E7*E39 -> #DIV/0! | AF7: =F7*F39 -> #DIV/0! | AG7: =G7*G39 -> #DIV/0! | AH7: =SUM(AI7:AL7) -> 0 | AM7: =SUM(AN7:AQ7) -> 0 | AR7: =SUM(I7:AQ7)/2-C7 -> #DIV/0!
A8: 试验费 | B8: 16.119022 | C8: =SUM(D8:G8) -> 0 | D8: =J8+O8+T8+Y8+AC8 -> 0 | E8: =K8+P8+U8+Z8+AD8 -> 0 | F8: =L8+Q8+V8+AA8+AE8 -> 0 | G8: =M8+R8+W8+AB8+AF8 -> 0 | H8: 子项目 | I8: =SUM(J8:M8) -> 0 | N8: =SUM(O8:R8) -> 0 | S8: =SUM(T8:W8) -> 0 | X8: =SUM(Y8:AB8) -> 0 | AC8: =SUM(AD8:AG8) -> 0 | AH8: =SUM(AI8:AL8) -> 0 | AM8: =SUM(AN8:AQ8) -> 0 | AR8: =SUM(I8:AQ8)/2-C8 -> 0
A9: 测试购置费 | C9: =SUM(D9:G9) -> 0 | D9: =J9+O9+T9+Y9+AC9 -> 0 | E9: =K9+P9+U9+Z9+AD9 -> 0 | F9: =L9+Q9+V9+AA9+AE9 -> 0 | G9: =M9+R9+W9+AB9+AF9 -> 0 | H9: 子项目 | I9: =SUM(J9:M9) -> 0 | N9: =SUM(O9:R9) -> 0 | S9: =SUM(T9:W9) -> 0 | X9: =SUM(Y9:AB9) -> 0 | AC9: =SUM(AD9:AG9) -> 0 | AH9: =SUM(AI9:AL9) -> 0 | AM9: =SUM(AN9:AQ9) -> 0 | AR9: =SUM(I9:AQ9)/2-C9 -> 0
A10: 检验费 | B10: 2.178963 | C10: =SUM(D10:G10) -> 0 | D10: =J10+O10+T10+Y10+AC10 -> 0 | E10: =K10+P10+U10+Z10+AD10 -> 0 | F10: =L10+Q10+V10+AA10+AE10 -> 0 | G10: =M10+R10+W10+AB10+AF10 -> 0 | H10: 子项目 | I10: =SUM(J10:M10) -> 0 | N10: =SUM(O10:R10) -> 0 | S10: =SUM(T10:W10) -> 0 | X10: =SUM(Y10:AB10) -> 0 | AC10: =SUM(AD10:AG10) -> 0 | AH10: =SUM(AI10:AL10) -> 0 | AM10: =SUM(AN10:AQ10) -> 0 | AR10: =SUM(I10:AQ10)/2-C10 -> 0
A11: 设备租赁费 | C11: =SUM(D11:G11) -> 0 | D11: =J11+O11+T11+Y11 -> 0 | E11: =K11+P11+U11+Z11 -> 0 | F11: =L11+Q11+V11+AA11 -> 0 | G11: =M11+R11+W11+AB11 -> 0 | H11: 子项目 | I11: =SUM(J11:M11) -> 0 | N11: =SUM(O11:R11) -> 0 | S11: =SUM(T11:W11) -> 0 | X11: =SUM(Y11:AB11) -> 0 | AC11: =SUM(AD11:AG11) -> 0 | AH11: =SUM(AI11:AL11) -> 0 | AM11: =SUM(AN11:AQ11) -> 0 | AR11: =SUM(I11:AQ11)/2-C11 -> 0
A12: 使用权资产折旧 | B12: 25.322055 | C12: =SUM(D12:G12) -> 0 | D12: ='附件3（公共费用分摊表）'!G12*3 -> 0 | E12: =D12 -> 0 | F12: =D12 -> 0 | G12: =D12 -> 0 | H12: 汇总 | I12: =SUM(J12:M12) -> #DIV/0! | J12: =D12*D35 -> #DIV/0! | K12: =E12*E35 -> #DIV/0! | L12: =F12*F35 -> #DIV/0! | M12: =G12*G35 -> #DIV/0! | N12: =SUM(O12:R12) -> #DIV/0! | O12: =D12*D36 -> #DIV/0! | P12: =E12*E36 -> #DIV/0! | Q12: =F12*F36 -> #DIV/0! | R12: =G12*G36 -> #DIV/0! | S12: =SUM(T12:W12) -> #DIV/0! | T12: =D12*D37 -> #DIV/0! | U12: =E12*E37 -> #DIV/0! | V12: =F12*F37 -> #DIV/0! | W12: =G12*G37 -> #DIV/0! | X12: =SUM(Y12:AB12) -> #DIV/0! | Y12: =D12*D38 -> #DIV/0! | Z12: =E12*E38 -> #DIV/0! | AA12: =F12*F38 -> #DIV/0! | AB12: =G12*G38 -> #DIV/0! | AC12: =SUM(AD12:AG12) -> #DIV/0! | AD12: =D12*D39 -> #DIV/0! | AE12: =E12*E39 -> #DIV/0! | AF12: =F12*F39 -> #DIV/0! | AG12: =G12*G39 -> #DIV/0! | AH12: =SUM(AI12:AL12) -> 0 | AM12: =SUM(AN12:AQ12) -> 0 | AR12: =SUM(I12:AQ12)/2-C12 -> #DIV/0!
A13: 设备运维费 | C13: =SUM(D13:G13) -> 0 | D13: =J13+O13+T13+Y13 -> 0 | E13: =K13+P13+U13+Z13 -> 0 | F13: =L13+Q13+V13+AA13 -> 0 | G13: =M13+R13+W13+AB13 -> 0 | H13: 子项目 | I13: =SUM(J13:M13) -> 0 | N13: =SUM(O13:R13) -> 0 | S13: =SUM(T13:W13) -> 0 | X13: =SUM(Y13:AB13) -> 0 | AC13: =SUM(AD13:AG13) -> 0 | AH13: =SUM(AI13:AL13) -> 0 | AM13: =SUM(AN13:AQ13) -> 0 | AR13: =SUM(I13:AQ13)/2-C13 -> 0
A14: 人员人工 | B14: 318.36379 | C14: ='附件2（人员预算)'!H12 -> 0 | D14: =C14/4 -> 0 | E14: =D14 -> 0 | F14: =D14 -> 0 | G14: =D14 -> 0 | H14: 汇总 | I14: =SUM(J14:M14) -> 0 | J14: ='附件2（人员预算)'!C21/10000/4 -> 0 | K14: =J14 -> 0 | L14: =J14 -> 0 | M14: =J14 -> 0 | N14: =SUM(O14:R14) -> 0 | O14: ='附件2（人员预算)'!D21/10000/4 -> 0 | P14: =O14 -> 0 | Q14: =O14 -> 0 | R14: =O14 -> 0 | S14: =SUM(T14:W14) -> 0 | T14: ='附件2（人员预算)'!E21/10000/4 -> 0 | U14: =T14 -> 0 | V14: =T14 -> 0 | W14: =T14 -> 0 | X14: =SUM(Y14:AB14) -> 0 | Y14: ='附件2（人员预算)'!F21/10000/4 -> 0 | Z14: =Y14 -> 0 | AA14: =Y14 -> 0 | AB14: =Y14 -> 0 | AC14: =SUM(AD14:AG14) -> 0 | AD14: ='附件2（人员预算)'!G21/10000/4 -> 0 | AE14: =AD14 -> 0 | AF14: =AD14 -> 0 | AG14: =AD14 -> 0 | AH14: =SUM(AI14:AL14) -> 0 | AM14: =SUM(AN14:AQ14) -> 0 | AR14: =SUM(I14:AQ14)/2-C14 -> 0
A15: 固定资产 | C15: =SUM(D15:G15) -> 0 | H15: 子项目 | I15: =SUM(J15:M15) -> 0 | N15: =SUM(O15:R15) -> 0 | S15: =SUM(T15:W15) -> 0 | X15: =SUM(Y15:AB15) -> 0 | AC15: =SUM(AD15:AG15) -> 0 | AH15: =SUM(AI15:AL15) -> 0 | AM15: =SUM(AN15:AQ15) -> 0 | AR15: =SUM(I15:AQ15)/2-C15 -> 0
A16: 折旧费用 | B16: 61.198287 | C16: =SUM(D16:G16) -> 0 | D16: ='附件3（公共费用分摊表）'!F22 -> 0 | E16: ='附件3（公共费用分摊表）'!G22 -> 0 | F16: ='附件3（公共费用分摊表）'!H22 -> 0 | G16: ='附件3（公共费用分摊表）'!I22 -> 0 | H16: 汇总 | I16: =SUM(J16:M16) -> #DIV/0! | J16: =D16*D44 -> #DIV/0! | K16: =E16*E44 -> #DIV/0! | L16: =F16*F44 -> #DIV/0! | M16: =G16*G44 -> #DIV/0! | N16: =SUM(O16:R16) -> #DIV/0! | O16: =D16*D45 -> #DIV/0! | P16: =E16*E45 -> #DIV/0! | Q16: =F16*F45 -> #DIV/0! | R16: =G16*G45 -> #DIV/0! | S16: =SUM(T16:W16) -> #DIV/0! | T16: =D16*D37 -> #DIV/0! | U16: =E16*E37 -> #DIV/0! | V16: =F16*F37 -> #DIV/0! | W16: =G16*G37 -> #DIV/0! | X16: =SUM(Y16:AB16) -> #DIV/0! | Y16: =D47*D16 -> #DIV/0! | Z16: =E47*E16 -> #DIV/0! | AA16: =F47*F16 -> #DIV/0! | AB16: =G47*G16 -> #DIV/0! | AC16: =SUM(AD16:AG16) -> #DIV/0! | AD16: =D16*D48 -> #DIV/0! | AE16: =E16*E48 -> #DIV/0! | AF16: =F16*F48 -> #DIV/0! | AG16: =G16*G48 -> #DIV/0! | AH16: =SUM(AI16:AL16) -> 0 | AM16: =SUM(AN16:AQ16) -> 0 | AR16: =SUM(I16:AQ16)/2-C16 -> #DIV/0!
A17: 设计费 | C17: =SUM(D17:G17) -> 0 | D17: =J17+O17+T17+Y17 -> 0 | E17: =K17+P17+U17+Z17 -> 0 | F17: =L17+Q17+V17+AA17 -> 0 | G17: =M17+R17+W17+AB17 -> 0 | H17: 子项目 | I17: =SUM(J17:M17) -> 0 | N17: =SUM(O17:R17) -> 0 | S17: =SUM(T17:W17) -> 0 | X17: =SUM(Y17:AB17) -> 0 | AC17: =SUM(AD17:AG17) -> 0 | AH17: =SUM(AI17:AL17) -> 0 | AM17: =SUM(AN17:AQ17) -> 0 | AR17: =SUM(I17:AQ17)/2-C17 -> 0
A18: 无形资产 | C18: =SUM(D18:G18) -> 0 | D18: =J18+O18+T18+Y18 -> 0 | E18: =K18+P18+U18+Z18 -> 0 | F18: =L18+Q18+V18+AA18 -> 0 | G18: =M18+R18+W18+AB18 -> 0 | H18: 子项目 | I18: =SUM(J18:M18) -> 0 | N18: =SUM(O18:R18) -> 0 | S18: =SUM(T18:W18) -> 0 | X18: =SUM(Y18:AB18) -> 0 | AC18: =SUM(AD18:AG18) -> 0 | AH18: =SUM(AI18:AL18) -> 0 | AM18: =SUM(AN18:AQ18) -> 0 | AR18: =SUM(I18:AQ18)/2-C18 -> 0
A19: 无形资产摊销 | B19: 1.624323 | C19: =SUM(D19:G19) -> 0 | D19: =J19+O19+T19+Y19 -> 0 | E19: =K19+P19+U19+Z19 -> 0 | F19: =L19+Q19+V19+AA19 -> 0 | G19: =M19+R19+W19+AB19 -> 0 | H19: 汇总 | I19: =SUM(J19:M19) -> 0 | N19: =SUM(O19:R19) -> 0 | S19: =SUM(T19:W19) -> 0 | X19: =SUM(Y19:AB19) -> 0 | AC19: =SUM(AD19:AG19) -> 0 | AH19: =SUM(AI19:AL19) -> 0 | AM19: =SUM(AN19:AQ19) -> 0 | AR19: =SUM(I19:AQ19)/2-C19 -> 0
A20: 厂房建设 | C20: =SUM(D20:G20) -> 0 | D20: =J20+O20+T20+Y20 -> 0 | E20: =K20+P20+U20+Z20 -> 0 | F20: =L20+Q20+V20+AA20 -> 0 | G20: =M20+R20+W20+AB20 -> 0 | H20: 汇总 | I20: =SUM(J20:M20) -> 0 | N20: =SUM(O20:R20) -> 0 | S20: =SUM(T20:W20) -> 0 | X20: =SUM(Y20:AB20) -> 0 | AC20: =SUM(AD20:AG20) -> 0 | AH20: =SUM(AI20:AL20) -> 0 | AM20: =SUM(AN20:AQ20) -> 0 | AR20: =SUM(I20:AQ20)/2-C20 -> 0
A21: 其他摊销 | C21: =SUM(D21:G21) -> 0 | D21: =J21+O21+T21+Y21 -> 0 | E21: =K21+P21+U21+Z21 -> 0 | F21: =L21+Q21+V21+AA21 -> 0 | G21: =M21+R21+W21+AB21 -> 0 | H21: 汇总 | I21: =SUM(J21:M21) -> 0 | N21: =SUM(O21:R21) -> 0 | S21: =SUM(T21:W21) -> 0 | X21: =SUM(Y21:AB21) -> 0 | AC21: =SUM(AD21:AG21) -> 0 | AH21: =SUM(AI21:AL21) -> 0 | AM21: =SUM(AN21:AQ21) -> 0 | AR21: =SUM(I21:AQ21)/2-C21 -> 0
A22: 其他费用 | B22: 7.052783 | C22: =SUM(D22:G22) -> 0 | D22: =J22+O22+T22+Y22 -> 0 | E22: =K22+P22+U22+Z22 -> 0 | F22: =L22+Q22+V22+AA22 -> 0 | G22: =M22+R22+W22+AB22 -> 0 | H22: 子项目 | I22: =SUM(J22:M22) -> 0 | N22: =SUM(O22:R22) -> 0 | S22: =SUM(T22:W22) -> 0 | X22: =SUM(Y22:AB22) -> 0 | AC22: =SUM(AD22:AG22) -> 0 | AH22: =SUM(AI22:AL22) -> 0 | AM22: =SUM(AN22:AQ22) -> 0 | AR22: =SUM(I22:AQ22)/2-C22 -> 0
A23: 委托研发 | C23: =SUM(D23:G23) -> 0 | D23: =J23+O23+T23+Y23 -> 0 | E23: =K23+P23+U23+Z23 -> 0 | F23: =L23+Q23+V23+AA23 -> 0 | G23: =M23+R23+W23+AB23 -> 0 | H23: 子项目 | I23: =SUM(J23:M23) -> 0 | N23: =SUM(O23:R23) -> 0 | S23: =SUM(T23:W23) -> 0 | X23: =SUM(Y23:AB23) -> 0 | AC23: =SUM(AD23:AG23) -> 0 | AH23: =SUM(AI23:AL23) -> 0 | AM23: =SUM(AN23:AQ23) -> 0 | AR23: =SUM(I23:AQ23)/2-C23 -> 0
A24: 注册费 | C24: =SUM(D24:G24) -> 0 | D24: =J24+O24+T24+Y24 -> 0 | E24: =K24+P24+U24+Z24 -> 0 | F24: =L24+Q24+V24+AA24 -> 0 | G24: =M24+R24+W24+AB24 -> 0 | H24: 子项目 | I24: =SUM(J24:M24) -> 0 | N24: =SUM(O24:R24) -> 0 | S24: =SUM(T24:W24) -> 0 | X24: =SUM(Y24:AB24) -> 0 | AC24: =SUM(AD24:AG24) -> 0 | AH24: =SUM(AI24:AL24) -> 0 | AM24: =SUM(AN24:AQ24) -> 0 | AR24: =SUM(I24:AQ24)/2-C24 -> 0
A25: 临床试验费 | B25: 34.675891 | C25: =SUM(D25:G25) -> 0 | D25: =J25+O25+T25+Y25 -> 0 | E25: =K25+P25+U25+Z25 -> 0 | F25: =L25+Q25+V25+AA25 -> 0 | G25: =M25+R25+W25+AB25 -> 0 | H25: 子项目 | I25: =SUM(J25:M25) -> 0 | N25: =SUM(O25:R25) -> 0 | S25: =SUM(T25:W25) -> 0 | X25: =SUM(Y25:AB25) -> 0 | AC25: =SUM(AD25:AG25) -> 0 | AH25: =SUM(AI25:AL25) -> 0 | AM25: =SUM(AN25:AQ25) -> 0 | AR25: =SUM(I25:AQ25)/2-C25 -> 0
A26: 临床人员人工 | C26: =SUM(D26:G26) -> 0 | D26: =J26+O26+T26+Y26 -> 0 | E26: =K26+P26+U26+Z26 -> 0 | F26: =L26+Q26+V26+AA26 -> 0 | G26: =M26+R26+W26+AB26 -> 0 | H26: 子项目 | I26: =SUM(J26:M26) -> 0 | N26: =SUM(O26:R26) -> 0 | S26: =SUM(T26:W26) -> 0 | X26: =SUM(Y26:AB26) -> 0 | AC26: =SUM(AD26:AG26) -> 0 | AH26: =SUM(AI26:AL26) -> 0 | AM26: =SUM(AN26:AQ26) -> 0 | AR26: =SUM(I26:AQ26)/2-C26 -> 0
A27: 临床材料费 | C27: =SUM(D27:G27) -> 0 | D27: =J27+O27+T27+Y27 -> 0 | E27: =K27+P27+U27+Z27 -> 0 | F27: =L27+Q27+V27+AA27 -> 0 | G27: =M27+R27+W27+AB27 -> 0 | H27: 子项目 | I27: =SUM(J27:M27) -> 0 | N27: =SUM(O27:R27) -> 0 | S27: =SUM(T27:W27) -> 0 | X27: =SUM(Y27:AB27) -> 0 | AC27: =SUM(AD27:AG27) -> 0 | AH27: =SUM(AI27:AL27) -> 0 | AM27: =SUM(AN27:AQ27) -> 0 | AR27: =SUM(I27:AQ27)/2-C27 -> 0
A28: 购买商品、接受劳务支付的现金 | C28: =C6 -> 0 | D28: =D6 -> 0 | E28: =E6 -> 0 | F28: =F6 -> 0 | G28: =G6 -> 0
A29: 支付给职工以及为职工支付的现金 | C29: =C14 -> 0 | D29: =D14 -> 0 | E29: =E14 -> 0 | F29: =F14 -> 0 | G29: =G14 -> 0
A30: 支付其他与经营活动有关的现金 | C30: =C7+C8+C9+C10+C11+C13+C17+C22+C23+C24 -> 0 | D30: =D7+D8+D9+D10+D11+D13+D17+D22+D23+D24 -> 0 | E30: =E7+E8+E9+E10+E11+E13+E17+E22+E23+E24 -> 0 | F30: =F7+F8+F9+F10+F11+F13+F17+F22+F23+F24 -> 0 | G30: =G7+G8+G9+G10+G11+G13+G17+G22+G23+G24 -> 0
A31: 购建固定资产、无形资产和其他长期资产支付的现金 | C31: =C15+C25+C26+C27 -> 0 | D31: =D15+D25+D26+D27 -> 0 | E31: =E15+E25+E26+E27 -> 0 | F31: =F15+F25+F26+F27 -> 0 | G31: =G15+G25+G26+G27 -> 0
A32: 支付其他与筹资活动有关的现金 | C32: =C12 -> 0 | D32: =D12 -> 0 | E32: =E12 -> 0 | F32: =F12 -> 0 | G32: =G12 -> 0
A33: 项目工时分配表 | B33: =SUM(C28:C32)-C4-C25+C16 -> 0
A34: 项目编码 | B34: 项目简称 | C34: FY2026 | D34: Q1 | E34: Q2 | F34: Q3 | G34: Q4
A35: RD1202 | B35: 角膜塑形镜OK7 | D35: ='附件2（人员预算)'!C22 -> #DIV/0! | E35: =D35 -> #DIV/0! | F35: =D35 -> #DIV/0! | G35: =D35 -> #DIV/0!
A36: RD1204 | B36: 离焦镜片 | D36: ='附件2（人员预算)'!D22 -> #DIV/0! | E36: =D36 -> #DIV/0! | F36: =D36 -> #DIV/0! | G36: =D36 -> #DIV/0!
A37: RD1205 | B37: 多焦软镜（国内自研） | D37: ='附件2（人员预算)'!E22 -> #DIV/0! | E37: =D37 -> #DIV/0! | F37: =D37 -> #DIV/0! | G37: =D37 -> #DIV/0!
A38: RD1206 | B38: 高透氧RGP | D38: ='附件2（人员预算)'!F22 -> #DIV/0! | E38: =D38 -> #DIV/0! | F38: =D38 -> #DIV/0! | G38: =D38 -> #DIV/0!
A39: RD1207 | B39: 渐近项目 | D39: ='附件2（人员预算)'!G22 -> #DIV/0! | E39: =D39 -> #DIV/0! | F39: =D39 -> #DIV/0! | G39: =D39 -> #DIV/0!
B40: 合计 | D40: =SUM(D35:D39) -> #DIV/0! | E40: =SUM(E35:E39) -> #DIV/0! | F40: =SUM(F35:F39) -> #DIV/0! | G40: =SUM(G35:G39) -> #DIV/0!
...

Sheet 附件1.1费用预算（管理）
A1: 管理费用预算表
I2: 单位：万元
A3: 费用分类 | C3: Q1 | D3: Q2 | E3: Q3 | F3: Q4 | G3: FY2026 | H3: FY2025 （截至2025.11） | I3: 26/25 | J3: 备注 | L3: 总经办 | N3: 注册部 | P3: 财务&人力 | R3: 质量管理部 | T3: 采购部
L4: FY2025 （截至2025.11） | M4: FY2026 | N4: FY2025 | O4: FY2026 | P4: FY2025 | Q4: FY2026 | R4: FY2025 | S4: FY2026 | T4: FY2025 | U4: FY2026
A5: 人年数 | L5: 1 | N5: 1 | T5: 1
A6: 费用总计 | C6: =SUM(C7:C8) -> 0 | D6: =SUM(D7:D8) -> 0 | E6: =SUM(E7:E8) -> 0 | F6: =SUM(F7:F8) -> 0 | G6: =SUM(G7:G8) -> 0 | H6: =SUM(H7:H8) -> 129.65299 | I6: =IFERROR(G6/H6-1,"") -> -1
A7: 总部费用分摊合计 | I7: =IFERROR(G7/H7-1,"")
A8: 期间费用合计 | C8: =SUM(C9:C12) -> 0 | D8: =SUM(D9:D12) -> 0 | E8: =SUM(E9:E12) -> 0 | F8: =SUM(F9:F12) -> 0 | G8: =SUM(G9:G12) -> 0 | H8: =SUM(H9:H12) -> 129.65299 | I8: =IFERROR(G8/H8-1,"") -> -1 | L8: =SUM(L9:L12) -> 109.89299 | M8: =SUM(M9:M12) -> 0 | N8: =SUM(N9:N12) -> 0.6 | O8: =SUM(O9:O12) -> 0 | P8: =SUM(P9:P12) -> 2.62 | Q8: =SUM(Q9:Q12) -> 0 | R8: =SUM(R9:R12) -> 16.43 | S8: =SUM(S9:S12) -> 0 | ... U8: =SUM(U9:U12) -> 0
A9: 其中：人员费用合计 | C9: =SUM(C45:C51) -> 0 | D9: =SUM(D45:D51) -> 0 | E9: =SUM(E45:E51) -> 0 | F9: =SUM(F45:F51) -> 0 | G9: =SUM(G45:G51) -> 0 | H9: =SUM(H45:H51) -> 0 | I9: =IFERROR(G9/H9-1,"") | L9: =SUM(L45:L51) -> 0 | M9: =SUM(M45:M51) -> 0 | N9: =SUM(N45:N51) -> 0 | O9: =SUM(O45:O51) -> 0 | P9: =SUM(P45:P51) -> 0 | Q9: =SUM(Q45:Q51) -> 0 | R9: =SUM(R45:R51) -> 0 | S9: =SUM(S45:S51) -> 0 | ... U9: =SUM(U45:U51) -> 0
A10: 公共费用合计 | C10: =SUM(C36:C44) -> 0 | D10: =SUM(D36:D44) -> 0 | E10: =SUM(E36:E44) -> 0 | F10: =SUM(F36:F44) -> 0 | G10: =SUM(G36:G44) -> 0 | H10: =SUM(H36:H44) -> 59.142271 | I10: =IFERROR(G10/H10-1,"") -> -1 | L10: =SUM(L36:L44) -> 58.002271 | M10: =SUM(M36:M44) -> 0 | N10: =SUM(N36:N44) -> 0.06 | O10: =SUM(O36:O44) -> 0 | P10: =SUM(P36:P44) -> 0 | Q10: =SUM(Q36:Q44) -> 0 | R10: =SUM(R36:R44) -> 1.06 | S10: =SUM(S36:S44) -> 0 | ... U10: =SUM(U36:U44) -> 0
A11: 日常费用合计 | C11: =SUM(C13:C22) -> 0 | D11: =SUM(D13:D22) -> 0 | E11: =SUM(E13:E22) -> 0 | F11: =SUM(F13:F22) -> 0 | G11: =SUM(G13:G22) -> 0 | H11: =SUM(H13:H22) -> 26.146912 | I11: =IFERROR(G11/H11-1,"") -> -1 | L11: =SUM(L13:L22) -> 24.196912 | M11: =SUM(M13:M22) -> 0 | N11: =SUM(N13:N22) -> 0.29 | O11: =SUM(O13:O22) -> 0 | P11: =SUM(P13:P22) -> 0 | Q11: =SUM(Q13:Q22) -> 0 | R11: =SUM(R13:R22) -> 1.57 | S11: =SUM(S13:S22) -> 0 | ... U11: =SUM(U13:U22) -> 0
A12: 专项费用合计 | C12: =SUM(C23:C35) -> 0 | D12: =SUM(D23:D35) -> 0 | E12: =SUM(E23:E35) -> 0 | F12: =SUM(F23:F35) -> 0 | G12: =SUM(G23:G35) -> 0 | H12: =SUM(H23:H35) -> 44.363806 | I12: =IFERROR(G12/H12-1,"") -> -1 | L12: =SUM(L23:L35) -> 27.693806 | M12: =SUM(M23:M35) -> 0 | N12: =SUM(N23:N35) -> 0.25 | O12: =SUM(O23:O35) -> 0 | P12: =SUM(P23:P35) -> 2.62 | Q12: =SUM(Q23:Q35) -> 0 | R12: =SUM(R23:R35) -> 13.8 | S12: =SUM(S23:S35) -> 0 | ... U12: =SUM(U23:U35) -> 0
A13: 日常费用 | B13: 办公费 | C13: =(M13+O13+Q13)/4 -> 0 | D13: =C13 -> 0 | E13: =D13 -> 0 | F13: =E13 -> 0 | G13: =SUM(C13:F13) -> 0 | H13: =L13+N13+P13+R13+T13 -> 1.489777 | I13: =IFERROR(G13/H13-1,"") -> -1 | L13: 1.429777 | R13: 0.06
B14: 通讯费 | C14: =(M14+O14+Q14)/4 -> 0 | D14: =C14 -> 0 | E14: =D14 -> 0 | F14: =E14 -> 0 | G14: =SUM(C14:F14) -> 0 | H14: =L14+N14+P14+R14+T14 -> 1.15886 | I14: =IFERROR(G14/H14-1,"") -> -1 | L14: 0.59886 | N14: 0.07 | R14: 0.42 | T14: 0.07
B15: 市内交通费 | C15: =(M15+O15+Q15)/4 -> 0 | D15: =C15 -> 0 | E15: =D15 -> 0 | F15: =E15 -> 0 | G15: =SUM(C15:F15) -> 0 | H15: =L15+N15+P15+R15+T15 -> 0.169472 | I15: =IFERROR(G15/H15-1,"") -> -1 | L15: 0.159472 | R15: 0.01
B16: 境内差旅费 | C16: =(M16+O16+Q16)/4 -> 0 | D16: =C16 -> 0 | E16: =D16 -> 0 | F16: =E16 -> 0 | G16: =SUM(C16:F16) -> 0 | H16: =L16+N16+P16+R16+T16 -> 16.708445 | I16: =IFERROR(G16/H16-1,"") -> -1 | J16: 需附明细 | L16: 15.408445 | N16: 0.22 | R16: 1.08
B17: 福利费（餐费） | C17: =(M17+O17+Q17)/4 -> 0 | D17: =C17 -> 0 | E17: =D17 -> 0 | F17: =E17 -> 0 | G17: =SUM(C17:F17) -> 0 | H17: =L17+N17+P17+R17+T17 -> 0 | I17: =IFERROR(G17/H17-1,"")
B18: 境外差旅费 | C18: =(M18+O18+Q18)/4 -> 0 | D18: =C18 -> 0 | E18: =D18 -> 0 | F18: =E18 -> 0 | G18: =SUM(C18:F18) -> 0 | H18: =L18+N18+P18+R18+T18 -> 2.742189 | I18: =IFERROR(G18/H18-1,"") -> -1 | J18: 需附明细 | L18: 2.742189
B19: 会议费 | C19: =(M19+O19+Q19)/4 -> 0 | D19: =C19 -> 0 | E19: =D19 -> 0 | F19: =E19 -> 0 | G19: =SUM(C19:F19) -> 0 | H19: =L19+N19+P19+R19+T19 -> 2.818129 | I19: =IFERROR(G19/H19-1,"") -> -1 | J19: 需附明细 | L19: 2.818129
B20: 运杂费 | C20: =(M20+O20+Q20)/4 -> 0 | D20: =C20 -> 0 | E20: =D20 -> 0 | F20: =E20 -> 0 | G20: =SUM(C20:F20) -> 0 | H20: =L20+N20+P20+R20+T20 -> 1.06004 | I20: =IFERROR(G20/H20-1,"") -> -1 | L20: 1.04004 | T20: 0.02
B21: 中标服务费 | C21: =(M21+O21+Q21)/4 -> 0 | D21: =C21 -> 0 | E21: =D21 -> 0 | F21: =E21 -> 0 | G21: =SUM(C21:F21) -> 0 | H21: =L21+N21+P21+R21+T21 -> 0 | I21: =IFERROR(G21/H21-1,"")
B22: 样机费 | C22: =(M22+O22+Q22)/4 -> 0 | D22: =C22 -> 0 | E22: =D22 -> 0 | F22: =E22 -> 0 | G22: =SUM(C22:F22) -> 0 | H22: =L22+N22+P22+R22+T22 -> 0 | I22: =IFERROR(G22/H22-1,"")
A23: 管理专项费用 | B23: 培训费 | C23: =(M23+O23+Q23)/4 -> 0 | D23: =C23 -> 0 | E23: =D23 -> 0 | F23: =E23 -> 0 | G23: =SUM(C23:F23) -> 0 | H23: =L23+N23+P23+R23+T23 -> 0 | I23: =IFERROR(G23/H23-1,"") | J23: 需附明细
B24: 咨询服务费 | C24: =(M24+O24+Q24)/4 -> 0 | D24: =C24 -> 0 | E24: =D24 -> 0 | F24: =E24 -> 0 | G24: =SUM(C24:F24) -> 0 | H24: =L24+N24+P24+R24+T24 -> 38.517036 | I24: =IFERROR(G24/H24-1,"") -> -1 | J24: 需附明细 | L24: 25.407036 | P24: =0.5+2.12 -> 2.62 | R24: 10.49
B25: 劳务费（管理） | C25: =(M25+O25+Q25)/4 -> 0 | D25: =C25 -> 0 | E25: =D25 -> 0 | F25: =E25 -> 0 | G25: =SUM(C25:F25) -> 0 | H25: =L25+N25+P25+R25+T25 -> 0.825 | I25: =IFERROR(G25/H25-1,"") -> -1 | L25: 0.825
A26: 市场专项费用 | B26: 业务招待费 | C26: =(M26+O26+Q26)/4 -> 0 | D26: =C26 -> 0 | E26: =D26 -> 0 | F26: =E26 -> 0 | G26: =SUM(C26:F26) -> 0 | H26: =L26+N26+P26+R26+T26 -> 5.02177 | I26: =IFERROR(G26/H26-1,"") -> -1 | J26: 需附明细 | L26: 1.46177 | N26: =0.11+0.14 -> 0.25 | R26: 3.31
B27: 市场推广费 | C27: =(M27+O27+Q27)/4 -> 0 | D27: =C27 -> 0 | E27: =D27 -> 0 | F27: =E27 -> 0 | G27: =SUM(C27:F27) -> 0 | H27: =L27+N27+P27+R27+T27 -> 0 | I27: =IFERROR(G27/H27-1,"") | J27: 需附明细
B28: 广告费 | C28: =(M28+O28+Q28)/4 -> 0 | D28: =C28 -> 0 | E28: =D28 -> 0 | F28: =E28 -> 0 | G28: =SUM(C28:F28) -> 0 | H28: =L28+N28+P28+R28+T28 -> 0 | I28: =IFERROR(G28/H28-1,"")
B29: 劳务费（市场） | C29: =(M29+O29+Q29)/4 -> 0 | D29: =C29 -> 0 | E29: =D29 -> 0 | F29: =E29 -> 0 | G29: =SUM(C29:F29) -> 0 | H29: =L29+N29+P29+R29+T29 -> 0 | I29: =IFERROR(G29/H29-1,"")
B30: 客户培训费 | C30: =(M30+O30+Q30)/4 -> 0 | D30: =C30 -> 0 | E30: =D30 -> 0 | F30: =E30 -> 0 | G30: =SUM(C30:F30) -> 0 | H30: =L30+N30+P30+R30+T30 -> 0 | I30: =IFERROR(G30/H30-1,"")
B31: 注册费 | C31: =(M31+O31+Q31)/4 -> 0 | D31: =C31 -> 0 | E31: =D31 -> 0 | F31: =E31 -> 0 | G31: =SUM(C31:F31) -> 0 | H31: =L31+N31+P31+R31+T31 -> 0 | J31: 财务填写
B32: 研究费用 | C32: =(M32+O32+Q32)/4 -> 0 | D32: =C32 -> 0 | E32: =D32 -> 0 | F32: =E32 -> 0 | G32: =SUM(C32:F32) -> 0 | H32: =L32+N32+P32+R32+T32 -> 0 | I32: =IFERROR(G32/H32-1,"")
A33: 其他专项 | B33: 存货损失 | C33: =(M33+O33+Q33)/4 -> 0 | D33: =C33 -> 0 | E33: =D33 -> 0 | F33: =E33 -> 0 | G33: =SUM(C33:F33) -> 0 | H33: =L33+N33+P33+R33+T33 -> 0 | I33: =IFERROR(G33/H33-1,"")
B34: 税费 | C34: =(M34+O34+Q34)/4 -> 0 | D34: =C34 -> 0 | E34: =D34 -> 0 | F34: =E34 -> 0 | G34: =SUM(C34:F34) -> 0 | H34: =L34+N34+P34+R34+T34 -> 0 | I34: =IFERROR(G34/H34-1,"")
B35: 售后维修费 | C35: =(M35+O35+Q35)/4 -> 0 | D35: =C35 -> 0 | E35: =D35 -> 0 | F35: =E35 -> 0 | G35: =SUM(C35:F35) -> 0 | H35: =L35+N35+P35+R35+T35 -> 0 | I35: =IFERROR(G35/H35-1,"")
A36: 公共费用 | B36: 租赁费 | C36: =(M36+O36+Q36)/4 -> 0 | D36: =C36 -> 0 | E36: =D36 -> 0 | F36: =E36 -> 0 | G36: =SUM(C36:F36) -> 0 | H36: =L36+N36+P36+R36+T36 -> 18.007176 | I36: =IFERROR(G36/H36-1,"") -> -1 | L36: 18.007176
B37: 水电物业费 | C37: =(M37+O37+Q37)/4 -> 0 | D37: =C37 -> 0 | E37: =D37 -> 0 | F37: =E37 -> 0 | G37: =SUM(C37:F37) -> 0 | H37: =L37+N37+P37+R37+T37 -> 10.4 | I37: =IFERROR(G37/H37-1,"") -> -1 | L37: 10.4
B38: 折旧费 | C38: =(M38+O38+Q38)/4 -> 0 | D38: =C38 -> 0 | E38: =D38 -> 0 | F38: =E38 -> 0 | G38: =SUM(C38:F38) -> 0 | H38: =L38+N38+P38+R38+T38 -> 1.934846 | I38: =IFERROR(G38/H38-1,"") -> -1 | J38: 财务填写 | L38: 0.794846 | N38: 0.06 | R38: 1.06 | T38: 0.02
B39: 无形资产摊销 | C39: =(M39+O39+Q39)/4 -> 0 | D39: =C39 -> 0 | E39: =D39 -> 0 | F39: =E39 -> 0 | G39: =SUM(C39:F39) -> 0 | H39: =L39+N39+P39+R39+T39 -> 0.014399 | I39: =IFERROR(G39/H39-1,"") -> -1 | L39: 0.014399
B40: 装修费摊销 | C40: =(M40+O40+Q40)/4 -> 0 | D40: =C40 -> 0 | E40: =D40 -> 0 | F40: =E40 -> 0 | G40: =SUM(C40:F40) -> 0 | H40: =L40+N40+P40+R40+T40 -> 0 | I40: =IFERROR(G40/H40-1,"")
...

Sheet 附件1.2费用预算（销售）
A1: 销售费用预算表
J2: 单位：万元
A3: 费用分类 | C3: Q1 | D3: Q2 | E3: Q3 | F3: Q4 | G3: FY2026 | H3: FY2025 （截至2025.11） | I3: 26/25 | J3: 备注 | L3: 销售部 | N3: 市场部（含新媒体运营）
L4: FY2025 | M4: FY2026 | N4: FY2025 | O4: FY2026
A5: 人年数 | N5: 4
A6: 费用总计 | C6: =SUM(C7:C8) -> 100.87 | D6: =SUM(D7:D8) -> 100.87 | E6: =SUM(E7:E8) -> 100.87 | F6: =SUM(F7:F8) -> 100.87 | G6: =SUM(G7:G8) -> 403.48 | H6: =SUM(H7:H8) -> 276.11225 | I6: =IFERROR(G6/H6-1,"") -> 0.46128973
A7: 总部费用分摊合计 | I7: =IFERROR(G7/H7-1,"")
A8: 期间费用合计 | C8: =SUM(C9:C12) -> 100.87 | D8: =SUM(D9:D12) -> 100.87 | E8: =SUM(E9:E12) -> 100.87 | F8: =SUM(F9:F12) -> 100.87 | G8: =SUM(G9:G12) -> 403.48 | H8: =SUM(H9:H12) -> 276.11225 | I8: =IFERROR(G8/H8-1,"") -> 0.46128973 | L8: =SUM(L9:L12) -> 92.306486 | M8: =SUM(M9:M12) -> 87.3 | N8: =SUM(N9:N12) -> 183.80577 | O8: =SUM(O9:O12) -> 316.18
A9: 其中：人员费用合计 | C9: =SUM(C45:C51) -> 0 | D9: =SUM(D45:D51) -> 0 | E9: =SUM(E45:E51) -> 0 | F9: =SUM(F45:F51) -> 0 | G9: =SUM(G45:G51) -> 0 | H9: =SUM(H45:H51) -> 0 | I9: =IFERROR(G9/H9-1,"") | L9: =SUM(L45:L51) -> 0 | M9: =SUM(M45:M51) -> 0 | N9: =SUM(N45:N51) -> 0 | O9: =SUM(O45:O51) -> 0
