Workbook

Sheet TIPS
K3: 年度 | L3: 2026
B4: 虚拟数据可以模拟放进来，下一版我再设置公式 | K4: 合作伙伴名称 | L4: xxx
B5: 以下需要确认 | K5: 业绩目标（万元）
B6: 1、产品型号是否有数量和金额双考核指标设置? | C6: 月度跟进表是数量，季度和年度已金额为主，需要分解到产品 | K6: 按季度分解 | L6: Q1 | M6: Q2 | N6: Q3 | O6: Q4
B7: 2、产品型号向下还是否继续分组？如有可能一并设置进来，尽可能全 | C7: ultra，时空之眼，小旋风，RGP，OK镜
B8: 3、返利的逻辑昨天没有太明白，再沟通下，我结合看是否统一设置表格公式 | C8: 返利你先不用做
B9: 4、医院授权代理商会变化，这个时间节点基本是月度或者季度节点吧？ | C9: 季度 | K9: 产品线分解（年度）
B10: 5、代理商类似提前备货/吃货这种方式，是否也一并放进来 | C10: 放进去
K11: 产品型号 | L11: 数量 | M11: 单价 | N11: 总金额
C12: 季度指标是否按照一定比例拆分，如是可以设置比例加入公式 | K12: Ultra
K13: 时空之眼
K14: 小旋风
B15: 表格说明：暂时用了一些虚拟数据模拟 | K15: OK7
B16: 1、可视化图形合集--可根据销售和管理策略，设计不同图形化表达，自动 | L16: 0.8 | M16: 0.2
B17: 2、ALL总表-各代理商总达成：填写指标，其他从后面子表取数 | K17: 返利计算
B18: 3、代理商-产品进销存：代理商分产品指标、进销存数据，蓝色部分已设置公式从子表取数 | K18: 80%是金额返利，20%是市场返利
B19: 4、代理商-进货明细表，实时统计代理商进货数据（分型号）
B20: 5、代理商-授权医院清单：需要期初填报，现用模拟数据
B21: 6、终端销售统计表：蓝色部分已设置公式，其他需销售动态填报 | K21: 市场支持
B23: 有以下两个提示点： | K23: 专家讲课
B24: 1、季度指标是否按照一定比例拆分，如是可以设置比例加入公式 | K24: 市场物料
B25: 2、代理商和终端客户是否设置代理商编号和客户编码，考虑未来长远也行启用系统可设置 | K25: 区域会议
K26: 参会或游学
K27: 新媒体
K28: 其他（一事一议）

Sheet 可视化动态图形合集
A2: ALL | B2: 全部代理商数据
B3: 总指标 | C3: 总达成 | D3: 达成率
B5: 可增加仪表盘，饼图等表达完成进度的图形
C12: 设置下拉选择，选择某个代理商时，下面达成相应对标，下方可设置某个代理商年度达成进度，分月折线图；产品型号相关数据图形等；根据业务管理需求调整
A13: 代理商 | B13: 公司1
J14: 分月数据
B15: 年度指标(万元) | C15: 年度指标(数量) | D15: Q1 | E15: Q2 | F15: Q3 | G15: Q4 | H15: 年度达成 | I15: 年度达成率 | J15: 1月 | K15: 2月 | L15: 3月 | M15: 4月 | N15: 5月 | O15: 6月 | P15: 7月 | Q15: 8月 | R15: 9月 | S15: 10月 | T15: 11月 | U15: 12月
B16: =VLOOKUP($B$13,'ALL总表-各代理商总达成'!$C:$N,COLUMN(),) -> 2000 | C16: =VLOOKUP($B$13,'ALL总表-各代理商总达成'!$C:$N,COLUMN(),) -> 0 | D16: =VLOOKUP($B$13,'ALL总表-各代理商总达成'!$C:$N,COLUMN(),) -> 100 | E16: =VLOOKUP($B$13,'ALL总表-各代理商总达成'!$C:$N,COLUMN(),) -> 100 | F16: =VLOOKUP($B$13,'ALL总表-各代理商总达成'!$C:$N,COLUMN(),) -> 100 | G16: =VLOOKUP($B$13,'ALL总表-各代理商总达成'!$C:$N,COLUMN(),) -> 100 | H16: =VLOOKUP($B$13,'ALL总表-各代理商总达成'!$C:$N,COLUMN(),) -> 400 | I16: =VLOOKUP($B$13,'ALL总表-各代理商总达成'!$C:$N,COLUMN(),) -> 0.2 | J16: =SUMIFS(终端客户销售统计表!$K:$K,终端客户销售统计表!$L:$L,可视化动态图形合集!$B$13,终端客户销售统计表!$G:$G,可视化动态图形合集!J$15)/10000 -> 0 | K16: =SUMIFS(终端客户销售统计表!$K:$K,终端客户销售统计表!$L:$L,可视化动态图形合集!$B$13,终端客户销售统计表!$G:$G,可视化动态图形合集!K$15)/10000 -> 0 | L16: =SUMIFS(终端客户销售统计表!$K:$K,终端客户销售统计表!$L:$L,可视化动态图形合集!$B$13,终端客户销售统计表!$G:$G,可视化动态图形合集!L$15)/10000 -> 100 | M16: =SUMIFS(终端客户销售统计表!$K:$K,终端客户销售统计表!$L:$L,可视化动态图形合集!$B$13,终端客户销售统计表!$G:$G,可视化动态图形合集!M$15)/10000 -> 0 | N16: =SUMIFS(终端客户销售统计表!$K:$K,终端客户销售统计表!$L:$L,可视化动态图形合集!$B$13,终端客户销售统计表!$G:$G,可视化动态图形合集!N$15)/10000 -> 0 | O16: =SUMIFS(终端客户销售统计表!$K:$K,终端客户销售统计表!$L:$L,可视化动态图形合集!$B$13,终端客户销售统计表!$G:$G,可视化动态图形合集!O$15)/10000 -> 100 | P16: =SUMIFS(终端客户销售统计表!$K:$K,终端客户销售统计表!$L:$L,可视化动态图形合集!$B$13,终端客户销售统计表!$G:$G,可视化动态图形合集!P$15)/10000 -> 0 | Q16: =SUMIFS(终端客户销售统计表!$K:$K,终端客户销售统计表!$L:$L,可视化动态图形合集!$B$13,终端客户销售统计表!$G:$G,可视化动态图形合集!Q$15)/10000 -> 0 | ... U16: =SUMIFS(终端客户销售统计表!$K:$K,终端客户销售统计表!$L:$L,可视化动态图形合集!$B$13,终端客户销售统计表!$G:$G,可视化动态图形合集!U$15)/10000 -> 0

Sheet 省市
B1: 省市
B2: 北京市
B3: 天津市
B4: 河北省
B5: 内蒙古自治区
B6: 山西省
B7: 陕西省
B8: 甘肃省
B9: 青海省
B10: 宁夏回族自治区
B11: 新疆维吾尔自治区
B12: 黑龙江省
... B32: 西藏自治区

Sheet ALL总表-各代理商总达成
A1: 年度 | B1: 代理商编号 | C1: 代理商名称 | D1: 年度指标(万元) | E1: 年度指标(数量) | F1: Q1 | G1: Q2 | H1: Q3 | I1: Q4 | J1: 年度达成 | K1: 年度达成率 | L1: 授权医院数量 | M1: 返利 | N1: 市场支持-分类
A2: 2026年 | B2: A00001 | C2: 公司1 | D2: 2000 | F2: =SUMIF('代理商-产品进销存'!$B:$B,'ALL总表-各代理商总达成'!$C2,'代理商-产品进销存'!L:L) -> 100 | G2: =SUMIF('代理商-产品进销存'!$B:$B,'ALL总表-各代理商总达成'!$C2,'代理商-产品进销存'!M:M) -> 100 | H2: =SUMIF('代理商-产品进销存'!$B:$B,'ALL总表-各代理商总达成'!$C2,'代理商-产品进销存'!N:N) -> 100 | I2: =SUMIF('代理商-产品进销存'!$B:$B,'ALL总表-各代理商总达成'!$C2,'代理商-产品进销存'!O:O) -> 100 | J2: =SUM(F2:I2) -> 400 | K2: =J2/D2 -> 0.2
A3: 2026年 | B3: A00002 | C3: 公司2 | D3: 2000 | F3: =SUMIF('代理商-产品进销存'!$B:$B,'ALL总表-各代理商总达成'!$C3,'代理商-产品进销存'!L:L) -> 100 | G3: =SUMIF('代理商-产品进销存'!$B:$B,'ALL总表-各代理商总达成'!$C3,'代理商-产品进销存'!M:M) -> 100 | H3: =SUMIF('代理商-产品进销存'!$B:$B,'ALL总表-各代理商总达成'!$C3,'代理商-产品进销存'!N:N) -> 100 | I3: =SUMIF('代理商-产品进销存'!$B:$B,'ALL总表-各代理商总达成'!$C3,'代理商-产品进销存'!O:O) -> 100 | J3: =SUM(F3:I3) -> 400 | K3: =J3/D3 -> 0.2
A4: 2026年 | B4: A00003 | C4: 公司3 | D4: 2000 | F4: =SUMIF('代理商-产品进销存'!$B:$B,'ALL总表-各代理商总达成'!$C4,'代理商-产品进销存'!L:L) -> 100 | G4: =SUMIF('代理商-产品进销存'!$B:$B,'ALL总表-各代理商总达成'!$C4,'代理商-产品进销存'!M:M) -> 100 | H4: =SUMIF('代理商-产品进销存'!$B:$B,'ALL总表-各代理商总达成'!$C4,'代理商-产品进销存'!N:N) -> 100 | I4: =SUMIF('代理商-产品进销存'!$B:$B,'ALL总表-各代理商总达成'!$C4,'代理商-产品进销存'!O:O) -> 100 | J4: =SUM(F4:I4) -> 400 | K4: =J4/D4 -> 0.2
A5: 2026年 | B5: A00004 | C5: 公司4 | D5: 2000 | F5: =SUMIF('代理商-产品进销存'!$B:$B,'ALL总表-各代理商总达成'!$C5,'代理商-产品进销存'!L:L) -> 100 | G5: =SUMIF('代理商-产品进销存'!$B:$B,'ALL总表-各代理商总达成'!$C5,'代理商-产品进销存'!M:M) -> 100 | H5: =SUMIF('代理商-产品进销存'!$B:$B,'ALL总表-各代理商总达成'!$C5,'代理商-产品进销存'!N:N) -> 100 | I5: =SUMIF('代理商-产品进销存'!$B:$B,'ALL总表-各代理商总达成'!$C5,'代理商-产品进销存'!O:O) -> 100 | J5: =SUM(F5:I5) -> 400 | K5: =J5/D5 -> 0.2
A6: 2026年 | B6: A00005 | C6: 公司5 | D6: 2000 | F6: =SUMIF('代理商-产品进销存'!$B:$B,'ALL总表-各代理商总达成'!$C6,'代理商-产品进销存'!L:L) -> 100 | G6: =SUMIF('代理商-产品进销存'!$B:$B,'ALL总表-各代理商总达成'!$C6,'代理商-产品进销存'!M:M) -> 100 | H6: =SUMIF('代理商-产品进销存'!$B:$B,'ALL总表-各代理商总达成'!$C6,'代理商-产品进销存'!N:N) -> 0 | I6: =SUMIF('代理商-产品进销存'!$B:$B,'ALL总表-各代理商总达成'!$C6,'代理商-产品进销存'!O:O) -> 0 | J6: =SUM(F6:I6) -> 200 | K6: =J6/D6 -> 0.1
A7: 2026年 | B7: A00006 | C7: 公司6 | D7: 2000 | F7: =SUMIF('代理商-产品进销存'!$B:$B,'ALL总表-各代理商总达成'!$C7,'代理商-产品进销存'!L:L) -> 0 | G7: =SUMIF('代理商-产品进销存'!$B:$B,'ALL总表-各代理商总达成'!$C7,'代理商-产品进销存'!M:M) -> 0 | H7: =SUMIF('代理商-产品进销存'!$B:$B,'ALL总表-各代理商总达成'!$C7,'代理商-产品进销存'!N:N) -> 100 | I7: =SUMIF('代理商-产品进销存'!$B:$B,'ALL总表-各代理商总达成'!$C7,'代理商-产品进销存'!O:O) -> 100 | J7: =SUM(F7:I7) -> 200 | K7: =J7/D7 -> 0.1
A8: 2026年 | B8: A00007 | C8: 公司7 | D8: 2000 | F8: =SUMIF('代理商-产品进销存'!$B:$B,'ALL总表-各代理商总达成'!$C8,'代理商-产品进销存'!L:L) -> 0 | G8: =SUMIF('代理商-产品进销存'!$B:$B,'ALL总表-各代理商总达成'!$C8,'代理商-产品进销存'!M:M) -> 0 | H8: =SUMIF('代理商-产品进销存'!$B:$B,'ALL总表-各代理商总达成'!$C8,'代理商-产品进销存'!N:N) -> 0 | I8: =SUMIF('代理商-产品进销存'!$B:$B,'ALL总表-各代理商总达成'!$C8,'代理商-产品进销存'!O:O) -> 0 | J8: =SUM(F8:I8) -> 0 | K8: =J8/D8 -> 0
A9: 2026年 | B9: A00008 | C9: 公司8 | D9: 2000 | F9: =SUMIF('代理商-产品进销存'!$B:$B,'ALL总表-各代理商总达成'!$C9,'代理商-产品进销存'!L:L) -> 0 | G9: =SUMIF('代理商-产品进销存'!$B:$B,'ALL总表-各代理商总达成'!$C9,'代理商-产品进销存'!M:M) -> 0 | H9: =SUMIF('代理商-产品进销存'!$B:$B,'ALL总表-各代理商总达成'!$C9,'代理商-产品进销存'!N:N) -> 0 | I9: =SUMIF('代理商-产品进销存'!$B:$B,'ALL总表-各代理商总达成'!$C9,'代理商-产品进销存'!O:O) -> 0 | J9: =SUM(F9:I9) -> 0 | K9: =J9/D9 -> 0
A10: 2026年 | B10: A00009 | C10: 公司9 | D10: 2000 | F10: =SUMIF('代理商-产品进销存'!$B:$B,'ALL总表-各代理商总达成'!$C10,'代理商-产品进销存'!L:L) -> 0 | G10: =SUMIF('代理商-产品进销存'!$B:$B,'ALL总表-各代理商总达成'!$C10,'代理商-产品进销存'!M:M) -> 0 | H10: =SUMIF('代理商-产品进销存'!$B:$B,'ALL总表-各代理商总达成'!$C10,'代理商-产品进销存'!N:N) -> 0 | I10: =SUMIF('代理商-产品进销存'!$B:$B,'ALL总表-各代理商总达成'!$C10,'代理商-产品进销存'!O:O) -> 0 | J10: =SUM(F10:I10) -> 0 | K10: =J10/D10 -> 0
A11: 2026年 | B11: A00010 | C11: 公司10 | D11: 2000 | F11: =SUMIF('代理商-产品进销存'!$B:$B,'ALL总表-各代理商总达成'!$C11,'代理商-产品进销存'!L:L) -> 0 | G11: =SUMIF('代理商-产品进销存'!$B:$B,'ALL总表-各代理商总达成'!$C11,'代理商-产品进销存'!M:M) -> 0 | H11: =SUMIF('代理商-产品进销存'!$B:$B,'ALL总表-各代理商总达成'!$C11,'代理商-产品进销存'!N:N) -> 0 | I11: =SUMIF('代理商-产品进销存'!$B:$B,'ALL总表-各代理商总达成'!$C11,'代理商-产品进销存'!O:O) -> 0 | J11: =SUM(F11:I11) -> 0 | K11: =J11/D11 -> 0
A12: 2026年 | B12: A00011 | C12: 公司11 | D12: 2000 | F12: =SUMIF('代理商-产品进销存'!$B:$B,'ALL总表-各代理商总达成'!$C12,'代理商-产品进销存'!L:L) -> 0 | G12: =SUMIF('代理商-产品进销存'!$B:$B,'ALL总表-各代理商总达成'!$C12,'代理商-产品进销存'!M:M) -> 0 | H12: =SUMIF('代理商-产品进销存'!$B:$B,'ALL总表-各代理商总达成'!$C12,'代理商-产品进销存'!N:N) -> 0 | I12: =SUMIF('代理商-产品进销存'!$B:$B,'ALL总表-各代理商总达成'!$C12,'代理商-产品进销存'!O:O) -> 0 | J12: =SUM(F12:I12) -> 0 | K12: =J12/D12 -> 0
A13: 2026年 | B13: A00012 | C13: 公司12 | D13: 2000 | F13: =SUMIF('代理商-产品进销存'!$B:$B,'ALL总表-各代理商总达成'!$C13,'代理商-产品进销存'!L:L) -> 0 | G13: =SUMIF('代理商-产品进销存'!$B:$B,'ALL总表-各代理商总达成'!$C13,'代理商-产品进销存'!M:M) -> 0 | H13: =SUMIF('代理商-产品进销存'!$B:$B,'ALL总表-各代理商总达成'!$C13,'代理商-产品进销存'!N:N) -> 0 | I13: =SUMIF('代理商-产品进销存'!$B:$B,'ALL总表-各代理商总达成'!$C13,'代理商-产品进销存'!O:O) -> 0 | J13: =SUM(F13:I13) -> 0 | K13: =J13/D13 -> 0
... A40: 2026年 | B40: A00039 | C40: 公司39 | D40: 2000 | F40: =SUMIF('代理商-产品进销存'!$B:$B,'ALL总表-各代理商总达成'!$C40,'代理商-产品进销存'!L:L) -> 0 | G40: =SUMIF('代理商-产品进销存'!$B:$B,'ALL总表-各代理商总达成'!$C40,'代理商-产品进销存'!M:M) -> 0 | H40: =SUMIF('代理商-产品进销存'!$B:$B,'ALL总表-各代理商总达成'!$C40,'代理商-产品进销存'!N:N) -> 0 | I40: =SUMIF('代理商-产品进销存'!$B:$B,'ALL总表-各代理商总达成'!$C40,'代理商-产品进销存'!O:O) -> 0 | J40: =SUM(F40:I40) -> 0 | K40: =J40/D40 -> 0

Sheet 代理商-产品进销存
E1: 指标相关数据 | L1: 终端销售数据 | R1: 代理商进货数据 | W1: 代理商库存数据
A2: 代理商编号 | B2: 代理商名称 | C2: 年度 | D2: 产品型号 | E2: 年度指标(数量) | F2: 销售单价 | G2: 年度指标(万元) | H2: Q1 | I2: Q2 | J2: Q3 | K2: Q4 | L2: Q1 | M2: Q2 | N2: Q3 | O2: Q4 | P2: 年度达成 | Q2: 年度达成率 | R2: Q1 | S2: Q2 | T2: Q3 | U2: Q4 | V2: 年度总计 | W2: Q1 | X2: Q2 | Y2: Q3 | Z2: Q4 | AA2: 年度总计 | AB2: 返利 | AC2: 市场支持-分类
A3: A00001 | B3: 公司1 | D3: Ultra | E3: 500 | F3: 10000 | G3: =E3*F3/10000 -> 500 | H3: =$G3*15% -> 75 | I3: =$G3*25% -> 125 | J3: =$G3*35% -> 175 | K3: =$G3*25% -> 125 | L3: =(SUMIFS(终端客户销售统计表!$K:$K,终端客户销售统计表!$L:$L,$B3,终端客户销售统计表!$H:$H,$D3,终端客户销售统计表!$G:$G,"1月")+SUMIFS(终端客户销售统计表!$K:$K,终端客户销售统计表!$L:$L,$B3,终端客户销售统计表!$H:$H,$D3,终端客户销售统计表!$G:$G,"2月")+SUMIFS(终端客户销售统计表!$K:$K,终端客户销售统计表!$L:$L,$B3,终端客户销售统计表!$H:$H,$D3,终端客户销售统计表!$G:$G,"3月"))/10000 -> 100 | M3: =(SUMIFS(终端客户销售统计表!$K:$K,终端客户销售统计表!$L:$L,$B3,终端客户销售统计表!$H:$H,$D3,终端客户销售统计表!$G:$G,"4月")+SUMIFS(终端客户销售统计表!$K:$K,终端客户销售统计表!$L:$L,$B3,终端客户销售统计表!$H:$H,$D3,终端客户销售统计表!$G:$G,"5月")+SUMIFS(终端客户销售统计表!$K:$K,终端客户销售统计表!$L:$L,$B3,终端客户销售统计表!$H:$H,$D3,终端客户销售统计表!$G:$G,"6月"))/10000 -> 0 | N3: =(SUMIFS(终端客户销售统计表!$K:$K,终端客户销售统计表!$L:$L,$B3,终端客户销售统计表!$H:$H,$D3,终端客户销售统计表!$G:$G,"7月")+SUMIFS(终端客户销售统计表!$K:$K,终端客户销售统计表!$L:$L,$B3,终端客户销售统计表!$H:$H,$D3,终端客户销售统计表!$G:$G,"8月")+SUMIFS(终端客户销售统计表!$K:$K,终端客户销售统计表!$L:$L,$B3,终端客户销售统计表!$H:$H,$D3,终端客户销售统计表!$G:$G,"9月"))/10000 -> 0 | O3: =(SUMIFS(终端客户销售统计表!$K:$K,终端客户销售统计表!$L:$L,$B3,终端客户销售统计表!$H:$H,$D3,终端客户销售统计表!$G:$G,"10月")+SUMIFS(终端客户销售统计表!$K:$K,终端客户销售统计表!$L:$L,$B3,终端客户销售统计表!$H:$H,$D3,终端客户销售统计表!$G:$G,"11月")+SUMIFS(终端客户销售统计表!$K:$K,终端客户销售统计表!$L:$L,$B3,终端客户销售统计表!$H:$H,$D3,终端客户销售统计表!$G:$G,"12月"))/10000 -> 0 | P3: =SUM(L3:O3) -> 100 | Q3: =IFERROR(P3/G3,"") -> 0.2 | R3: =(SUMIFS('代理商-进货明细表'!$I:$I,'代理商-进货明细表'!$B:$B,'代理商-产品进销存'!$B3,'代理商-进货明细表'!$F:$F,'代理商-产品进销存'!$D3,'代理商-进货明细表'!$E:$E,"1月")+SUMIFS('代理商-进货明细表'!$I:$I,'代理商-进货明细表'!$B:$B,'代理商-产品进销存'!$B3,'代理商-进货明细表'!$F:$F,'代理商-产品进销存'!$D3,'代理商-进货明细表'!$E:$E,"2月")+SUMIFS('代理商-进货明细表'!$I:$I,'代理商-进货明细表'!$B:$B,'代理商-产品进销存'!$B3,'代理商-进货明细表'!$F:$F,'代理商-产品进销存'!$D3,'代理商-进货明细表'!$E:$E,"3月"))/10000 -> 0 | S3: =(SUMIFS('代理商-进货明细表'!$I:$I,'代理商-进货明细表'!$B:$B,'代理商-产品进销存'!$B3,'代理商-进货明细表'!$F:$F,'代理商-产品进销存'!$D3,'代理商-进货明细表'!$E:$E,"4月")+SUMIFS('代理商-进货明细表'!$I:$I,'代理商-进货明细表'!$B:$B,'代理商-产品进销存'!$B3,'代理商-进货明细表'!$F:$F,'代理商-产品进销存'!$D3,'代理商-进货明细表'!$E:$E,"5月")+SUMIFS('代理商-进货明细表'!$I:$I,'代理商-进货明细表'!$B:$B,'代理商-产品进销存'!$B3,'代理商-进货明细表'!$F:$F,'代理商-产品进销存'!$D3,'代理商-进货明细表'!$E:$E,"6月"))/10000 -> 400 | T3: =(SUMIFS('代理商-进货明细表'!$I:$I,'代理商-进货明细表'!$B:$B,'代理商-产品进销存'!$B3,'代理商-进货明细表'!$F:$F,'代理商-产品进销存'!$D3,'代理商-进货明细表'!$E:$E,"7月")+SUMIFS('代理商-进货明细表'!$I:$I,'代理商-进货明细表'!$B:$B,'代理商-产品进销存'!$B3,'代理商-进货明细表'!$F:$F,'代理商-产品进销存'!$D3,'代理商-进货明细表'!$E:$E,"8月")+SUMIFS('代理商-进货明细表'!$I:$I,'代理商-进货明细表'!$B:$B,'代理商-产品进销存'!$B3,'代理商-进货明细表'!$F:$F,'代理商-产品进销存'!$D3,'代理商-进货明细表'!$E:$E,"9月"))/10000 -> 0 | U3: =(SUMIFS('代理商-进货明细表'!$I:$I,'代理商-进货明细表'!$B:$B,'代理商-产品进销存'!$B3,'代理商-进货明细表'!$F:$F,'代理商-产品进销存'!$D3,'代理商-进货明细表'!$E:$E,"10月")+SUMIFS('代理商-进货明细表'!$I:$I,'代理商-进货明细表'!$B:$B,'代理商-产品进销存'!$B3,'代理商-进货明细表'!$F:$F,'代理商-产品进销存'!$D3,'代理商-进货明细表'!$E:$E,"11月")+SUMIFS('代理商-进货明细表'!$I:$I,'代理商-进货明细表'!$B:$B,'代理商-产品进销存'!$B3,'代理商-进货明细表'!$F:$F,'代理商-产品进销存'!$D3,'代理商-进货明细表'!$E:$E,"12月"))/10000 -> 0 | V3: =SUM(R3:U3) -> 400 | W3: =R3-L3 -> -100 | X3: =S3-M3 -> 400 | Y3: =T3-N3 -> 0 | Z3: =U3-O3 -> 0 | AA3: =SUM(W3:Z3) -> 300
A4: A00001 | B4: 公司1 | D4: 时空之眼 | E4: 500 | F4: 10000 | G4: =E4*F4/10000 -> 500 | H4: =$G4*15% -> 75 | I4: =$G4*25% -> 125 | J4: =$G4*35% -> 175 | K4: =$G4*25% -> 125 | L4: =(SUMIFS(终端客户销售统计表!$K:$K,终端客户销售统计表!$L:$L,$B4,终端客户销售统计表!$H:$H,$D4,终端客户销售统计表!$G:$G,"1月")+SUMIFS(终端客户销售统计表!$K:$K,终端客户销售统计表!$L:$L,$B4,终端客户销售统计表!$H:$H,$D4,终端客户销售统计表!$G:$G,"2月")+SUMIFS(终端客户销售统计表!$K:$K,终端客户销售统计表!$L:$L,$B4,终端客户销售统计表!$H:$H,$D4,终端客户销售统计表!$G:$G,"3月"))/10000 -> 0 | M4: =(SUMIFS(终端客户销售统计表!$K:$K,终端客户销售统计表!$L:$L,$B4,终端客户销售统计表!$H:$H,$D4,终端客户销售统计表!$G:$G,"4月")+SUMIFS(终端客户销售统计表!$K:$K,终端客户销售统计表!$L:$L,$B4,终端客户销售统计表!$H:$H,$D4,终端客户销售统计表!$G:$G,"5月")+SUMIFS(终端客户销售统计表!$K:$K,终端客户销售统计表!$L:$L,$B4,终端客户销售统计表!$H:$H,$D4,终端客户销售统计表!$G:$G,"6月"))/10000 -> 100 | N4: =(SUMIFS(终端客户销售统计表!$K:$K,终端客户销售统计表!$L:$L,$B4,终端客户销售统计表!$H:$H,$D4,终端客户销售统计表!$G:$G,"7月")+SUMIFS(终端客户销售统计表!$K:$K,终端客户销售统计表!$L:$L,$B4,终端客户销售统计表!$H:$H,$D4,终端客户销售统计表!$G:$G,"8月")+SUMIFS(终端客户销售统计表!$K:$K,终端客户销售统计表!$L:$L,$B4,终端客户销售统计表!$H:$H,$D4,终端客户销售统计表!$G:$G,"9月"))/10000 -> 0 | O4: =(SUMIFS(终端客户销售统计表!$K:$K,终端客户销售统计表!$L:$L,$B4,终端客户销售统计表!$H:$H,$D4,终端客户销售统计表!$G:$G,"10月")+SUMIFS(终端客户销售统计表!$K:$K,终端客户销售统计表!$L:$L,$B4,终端客户销售统计表!$H:$H,$D4,终端客户销售统计表!$G:$G,"11月")+SUMIFS(终端客户销售统计表!$K:$K,终端客户销售统计表!$L:$L,$B4,终端客户销售统计表!$H:$H,$D4,终端客户销售统计表!$G:$G,"12月"))/10000 -> 0 | P4: =SUM(L4:O4) -> 100 | Q4: =IFERROR(P4/G4,"") -> 0.2 | R4: =(SUMIFS('代理商-进货明细表'!$I:$I,'代理商-进货明细表'!$B:$B,'代理商-产品进销存'!$B4,'代理商-进货明细表'!$F:$F,'代理商-产品进销存'!$D4,'代理商-进货明细表'!$E:$E,"1月")+SUMIFS('代理商-进货明细表'!$I:$I,'代理商-进货明细表'!$B:$B,'代理商-产品进销存'!$B4,'代理商-进货明细表'!$F:$F,'代理商-产品进销存'!$D4,'代理商-进货明细表'!$E:$E,"2月")+SUMIFS('代理商-进货明细表'!$I:$I,'代理商-进货明细表'!$B:$B,'代理商-产品进销存'!$B4,'代理商-进货明细表'!$F:$F,'代理商-产品进销存'!$D4,'代理商-进货明细表'!$E:$E,"3月"))/10000 -> 400 | S4: =(SUMIFS('代理商-进货明细表'!$I:$I,'代理商-进货明细表'!$B:$B,'代理商-产品进销存'!$B4,'代理商-进货明细表'!$F:$F,'代理商-产品进销存'!$D4,'代理商-进货明细表'!$E:$E,"4月")+SUMIFS('代理商-进货明细表'!$I:$I,'代理商-进货明细表'!$B:$B,'代理商-产品进销存'!$B4,'代理商-进货明细表'!$F:$F,'代理商-产品进销存'!$D4,'代理商-进货明细表'!$E:$E,"5月")+SUMIFS('代理商-进货明细表'!$I:$I,'代理商-进货明细表'!$B:$B,'代理商-产品进销存'!$B4,'代理商-进货明细表'!$F:$F,'代理商-产品进销存'!$D4,'代理商-进货明细表'!$E:$E,"6月"))/10000 -> 0 | T4: =(SUMIFS('代理商-进货明细表'!$I:$I,'代理商-进货明细表'!$B:$B,'代理商-产品进销存'!$B4,'代理商-进货明细表'!$F:$F,'代理商-产品进销存'!$D4,'代理商-进货明细表'!$E:$E,"7月")+SUMIFS('代理商-进货明细表'!$I:$I,'代理商-进货明细表'!$B:$B,'代理商-产品进销存'!$B4,'代理商-进货明细表'!$F:$F,'代理商-产品进销存'!$D4,'代理商-进货明细表'!$E:$E,"8月")+SUMIFS('代理商-进货明细表'!$I:$I,'代理商-进货明细表'!$B:$B,'代理商-产品进销存'!$B4,'代理商-进货明细表'!$F:$F,'代理商-产品进销存'!$D4,'代理商-进货明细表'!$E:$E,"9月"))/10000 -> 0 | U4: =(SUMIFS('代理商-进货明细表'!$I:$I,'代理商-进货明细表'!$B:$B,'代理商-产品进销存'!$B4,'代理商-进货明细表'!$F:$F,'代理商-产品进销存'!$D4,'代理商-进货明细表'!$E:$E,"10月")+SUMIFS('代理商-进货明细表'!$I:$I,'代理商-进货明细表'!$B:$B,'代理商-产品进销存'!$B4,'代理商-进货明细表'!$F:$F,'代理商-产品进销存'!$D4,'代理商-进货明细表'!$E:$E,"11月")+SUMIFS('代理商-进货明细表'!$I:$I,'代理商-进货明细表'!$B:$B,'代理商-产品进销存'!$B4,'代理商-进货明细表'!$F:$F,'代理商-产品进销存'!$D4,'代理商-进货明细表'!$E:$E,"12月"))/10000 -> 0 | V4: =SUM(R4:U4) -> 400 | W4: =R4-L4 -> 400 | X4: =S4-M4 -> -100 | Y4: =T4-N4 -> 0 | Z4: =U4-O4 -> 0 | AA4: =SUM(W4:Z4) -> 300
A5: A00001 | B5: 公司1 | D5: 小旋风 | E5: 500 | F5: 10000 | G5: =E5*F5/10000 -> 500 | H5: =$G5*15% -> 75 | I5: =$G5*25% -> 125 | J5: =$G5*35% -> 175 | K5: =$G5*25% -> 125 | L5: =(SUMIFS(终端客户销售统计表!$K:$K,终端客户销售统计表!$L:$L,$B5,终端客户销售统计表!$H:$H,$D5,终端客户销售统计表!$G:$G,"1月")+SUMIFS(终端客户销售统计表!$K:$K,终端客户销售统计表!$L:$L,$B5,终端客户销售统计表!$H:$H,$D5,终端客户销售统计表!$G:$G,"2月")+SUMIFS(终端客户销售统计表!$K:$K,终端客户销售统计表!$L:$L,$B5,终端客户销售统计表!$H:$H,$D5,终端客户销售统计表!$G:$G,"3月"))/10000 -> 0 | M5: =(SUMIFS(终端客户销售统计表!$K:$K,终端客户销售统计表!$L:$L,$B5,终端客户销售统计表!$H:$H,$D5,终端客户销售统计表!$G:$G,"4月")+SUMIFS(终端客户销售统计表!$K:$K,终端客户销售统计表!$L:$L,$B5,终端客户销售统计表!$H:$H,$D5,终端客户销售统计表!$G:$G,"5月")+SUMIFS(终端客户销售统计表!$K:$K,终端客户销售统计表!$L:$L,$B5,终端客户销售统计表!$H:$H,$D5,终端客户销售统计表!$G:$G,"6月"))/10000 -> 0 | N5: =(SUMIFS(终端客户销售统计表!$K:$K,终端客户销售统计表!$L:$L,$B5,终端客户销售统计表!$H:$H,$D5,终端客户销售统计表!$G:$G,"7月")+SUMIFS(终端客户销售统计表!$K:$K,终端客户销售统计表!$L:$L,$B5,终端客户销售统计表!$H:$H,$D5,终端客户销售统计表!$G:$G,"8月")+SUMIFS(终端客户销售统计表!$K:$K,终端客户销售统计表!$L:$L,$B5,终端客户销售统计表!$H:$H,$D5,终端客户销售统计表!$G:$G,"9月"))/10000 -> 100 | O5: =(SUMIFS(终端客户销售统计表!$K:$K,终端客户销售统计表!$L:$L,$B5,终端客户销售统计表!$H:$H,$D5,终端客户销售统计表!$G:$G,"10月")+SUMIFS(终端客户销售统计表!$K:$K,终端客户销售统计表!$L:$L,$B5,终端客户销售统计表!$H:$H,$D5,终端客户销售统计表!$G:$G,"11月")+SUMIFS(终端客户销售统计表!$K:$K,终端客户销售统计表!$L:$L,$B5,终端客户销售统计表!$H:$H,$D5,终端客户销售统计表!$G:$G,"12月"))/10000 -> 0 | P5: =SUM(L5:O5) -> 100 | Q5: =IFERROR(P5/G5,"") -> 0.2 | R5: =(SUMIFS('代理商-进货明细表'!$I:$I,'代理商-进货明细表'!$B:$B,'代理商-产品进销存'!$B5,'代理商-进货明细表'!$F:$F,'代理商-产品进销存'!$D5,'代理商-进货明细表'!$E:$E,"1月")+SUMIFS('代理商-进货明细表'!$I:$I,'代理商-进货明细表'!$B:$B,'代理商-产品进销存'!$B5,'代理商-进货明细表'!$F:$F,'代理商-产品进销存'!$D5,'代理商-进货明细表'!$E:$E,"2月")+SUMIFS('代理商-进货明细表'!$I:$I,'代理商-进货明细表'!$B:$B,'代理商-产品进销存'!$B5,'代理商-进货明细表'!$F:$F,'代理商-产品进销存'!$D5,'代理商-进货明细表'!$E:$E,"3月"))/10000 -> 0 | S5: =(SUMIFS('代理商-进货明细表'!$I:$I,'代理商-进货明细表'!$B:$B,'代理商-产品进销存'!$B5,'代理商-进货明细表'!$F:$F,'代理商-产品进销存'!$D5,'代理商-进货明细表'!$E:$E,"4月")+SUMIFS('代理商-进货明细表'!$I:$I,'代理商-进货明细表'!$B:$B,'代理商-产品进销存'!$B5,'代理商-进货明细表'!$F:$F,'代理商-产品进销存'!$D5,'代理商-进货明细表'!$E:$E,"5月")+SUMIFS('代理商-进货明细表'!$I:$I,'代理商-进货明细表'!$B:$B,'代理商-产品进销存'!$B5,'代理商-进货明细表'!$F:$F,'代理商-产品进销存'!$D5,'代理商-进货明细表'!$E:$E,"6月"))/10000 -> 0 | T5: =(SUMIFS('代理商-进货明细表'!$I:$I,'代理商-进货明细表'!$B:$B,'代理商-产品进销存'!$B5,'代理商-进货明细表'!$F:$F,'代理商-产品进销存'!$D5,'代理商-进货明细表'!$E:$E,"7月")+SUMIFS('代理商-进货明细表'!$I:$I,'代理商-进货明细表'!$B:$B,'代理商-产品进销存'!$B5,'代理商-进货明细表'!$F:$F,'代理商-产品进销存'!$D5,'代理商-进货明细表'!$E:$E,"8月")+SUMIFS('代理商-进货明细表'!$I:$I,'代理商-进货明细表'!$B:$B,'代理商-产品进销存'!$B5,'代理商-进货明细表'!$F:$F,'代理商-产品进销存'!$D5,'代理商-进货明细表'!$E:$E,"9月"))/10000 -> 400 | U5: =(SUMIFS('代理商-进货明细表'!$I:$I,'代理商-进货明细表'!$B:$B,'代理商-产品进销存'!$B5,'代理商-进货明细表'!$F:$F,'代理商-产品进销存'!$D5,'代理商-进货明细表'!$E:$E,"10月")+SUMIFS('代理商-进货明细表'!$I:$I,'代理商-进货明细表'!$B:$B,'代理商-产品进销存'!$B5,'代理商-进货明细表'!$F:$F,'代理商-产品进销存'!$D5,'代理商-进货明细表'!$E:$E,"11月")+SUMIFS('代理商-进货明细表'!$I:$I,'代理商-进货明细表'!$B:$B,'代理商-产品进销存'!$B5,'代理商-进货明细表'!$F:$F,'代理商-产品进销存'!$D5,'代理商-进货明细表'!$E:$E,"12月"))/10000 -> 0 | V5: =SUM(R5:U5) -> 400 | W5: =R5-L5 -> 0 | X5: =S5-M5 -> 0 | Y5: =T5-N5 -> 300 | Z5: =U5-O5 -> 0 | AA5: =SUM(W5:Z5) -> 300
A6: A00001 | B6: 公司1 | D6: OK7 | E6: 500 | F6: 10000 | G6: =E6*F6/10000 -> 500 | H6: =$G6*15% -> 75 | I6: =$G6*25% -> 125 | J6: =$G6*35% -> 175 | K6: =$G6*25% -> 125 | L6: =(SUMIFS(终端客户销售统计表!$K:$K,终端客户销售统计表!$L:$L,$B6,终端客户销售统计表!$H:$H,$D6,终端客户销售统计表!$G:$G,"1月")+SUMIFS(终端客户销售统计表!$K:$K,终端客户销售统计表!$L:$L,$B6,终端客户销售统计表!$H:$H,$D6,终端客户销售统计表!$G:$G,"2月")+SUMIFS(终端客户销售统计表!$K:$K,终端客户销售统计表!$L:$L,$B6,终端客户销售统计表!$H:$H,$D6,终端客户销售统计表!$G:$G,"3月"))/10000 -> 0 | M6: =(SUMIFS(终端客户销售统计表!$K:$K,终端客户销售统计表!$L:$L,$B6,终端客户销售统计表!$H:$H,$D6,终端客户销售统计表!$G:$G,"4月")+SUMIFS(终端客户销售统计表!$K:$K,终端客户销售统计表!$L:$L,$B6,终端客户销售统计表!$H:$H,$D6,终端客户销售统计表!$G:$G,"5月")+SUMIFS(终端客户销售统计表!$K:$K,终端客户销售统计表!$L:$L,$B6,终端客户销售统计表!$H:$H,$D6,终端客户销售统计表!$G:$G,"6月"))/10000 -> 0 | N6: =(SUMIFS(终端客户销售统计表!$K:$K,终端客户销售统计表!$L:$L,$B6,终端客户销售统计表!$H:$H,$D6,终端客户销售统计表!$G:$G,"7月")+SUMIFS(终端客户销售统计表!$K:$K,终端客户销售统计表!$L:$L,$B6,终端客户销售统计表!$H:$H,$D6,终端客户销售统计表!$G:$G,"8月")+SUMIFS(终端客户销售统计表!$K:$K,终端客户销售统计表!$L:$L,$B6,终端客户销售统计表!$H:$H,$D6,终端客户销售统计表!$G:$G,"9月"))/10000 -> 0 | O6: =(SUMIFS(终端客户销售统计表!$K:$K,终端客户销售统计表!$L:$L,$B6,终端客户销售统计表!$H:$H,$D6,终端客户销售统计表!$G:$G,"10月")+SUMIFS(终端客户销售统计表!$K:$K,终端客户销售统计表!$L:$L,$B6,终端客户销售统计表!$H:$H,$D6,终端客户销售统计表!$G:$G,"11月")+SUMIFS(终端客户销售统计表!$K:$K,终端客户销售统计表!$L:$L,$B6,终端客户销售统计表!$H:$H,$D6,终端客户销售统计表!$G:$G,"12月"))/10000 -> 100 | P6: =SUM(L6:O6) -> 100 | Q6: =IFERROR(P6/G6,"") -> 0.2 | R6: =(SUMIFS('代理商-进货明细表'!$I:$I,'代理商-进货明细表'!$B:$B,'代理商-产品进销存'!$B6,'代理商-进货明细表'!$F:$F,'代理商-产品进销存'!$D6,'代理商-进货明细表'!$E:$E,"1月")+SUMIFS('代理商-进货明细表'!$I:$I,'代理商-进货明细表'!$B:$B,'代理商-产品进销存'!$B6,'代理商-进货明细表'!$F:$F,'代理商-产品进销存'!$D6,'代理商-进货明细表'!$E:$E,"2月")+SUMIFS('代理商-进货明细表'!$I:$I,'代理商-进货明细表'!$B:$B,'代理商-产品进销存'!$B6,'代理商-进货明细表'!$F:$F,'代理商-产品进销存'!$D6,'代理商-进货明细表'!$E:$E,"3月"))/10000 -> 0 | S6: =(SUMIFS('代理商-进货明细表'!$I:$I,'代理商-进货明细表'!$B:$B,'代理商-产品进销存'!$B6,'代理商-进货明细表'!$F:$F,'代理商-产品进销存'!$D6,'代理商-进货明细表'!$E:$E,"4月")+SUMIFS('代理商-进货明细表'!$I:$I,'代理商-进货明细表'!$B:$B,'代理商-产品进销存'!$B6,'代理商-进货明细表'!$F:$F,'代理商-产品进销存'!$D6,'代理商-进货明细表'!$E:$E,"5月")+SUMIFS('代理商-进货明细表'!$I:$I,'代理商-进货明细表'!$B:$B,'代理商-产品进销存'!$B6,'代理商-进货明细表'!$F:$F,'代理商-产品进销存'!$D6,'代理商-进货明细表'!$E:$E,"6月"))/10000 -> 0 | T6: =(SUMIFS('代理商-进货明细表'!$I:$I,'代理商-进货明细表'!$B:$B,'代理商-产品进销存'!$B6,'代理商-进货明细表'!$F:$F,'代理商-产品进销存'!$D6,'代理商-进货明细表'!$E:$E,"7月")+SUMIFS('代理商-进货明细表'!$I:$I,'代理商-进货明细表'!$B:$B,'代理商-产品进销存'!$B6,'代理商-进货明细表'!$F:$F,'代理商-产品进销存'!$D6,'代理商-进货明细表'!$E:$E,"8月")+SUMIFS('代理商-进货明细表'!$I:$I,'代理商-进货明细表'!$B:$B,'代理商-产品进销存'!$B6,'代理商-进货明细表'!$F:$F,'代理商-产品进销存'!$D6,'代理商-进货明细表'!$E:$E,"9月"))/10000 -> 0 | U6: =(SUMIFS('代理商-进货明细表'!$I:$I,'代理商-进货明细表'!$B:$B,'代理商-产品进销存'!$B6,'代理商-进货明细表'!$F:$F,'代理商-产品进销存'!$D6,'代理商-进货明细表'!$E:$E,"10月")+SUMIFS('代理商-进货明细表'!$I:$I,'代理商-进货明细表'!$B:$B,'代理商-产品进销存'!$B6,'代理商-进货明细表'!$F:$F,'代理商-产品进销存'!$D6,'代理商-进货明细表'!$E:$E,"11月")+SUMIFS('代理商-进货明细表'!$I:$I,'代理商-进货明细表'!$B:$B,'代理商-产品进销存'!$B6,'代理商-进货明细表'!$F:$F,'代理商-产品进销存'!$D6,'代理商-进货明细表'!$E:$E,"12月"))/10000 -> 400 | V6: =SUM(R6:U6) -> 400 | W6: =R6-L6 -> 0 | X6: =S6-M6 -> 0 | Y6: =T6-N6 -> 0 | Z6: =U6-O6 -> 300 | AA6: =SUM(W6:Z6) -> 300
A7: A00002 | B7: 公司2 | D7: Ultra | E7: 500 | F7: 10000 | G7: =E7*F7/10000 -> 500 | H7: =$G7*15% -> 75 | I7: =$G7*25% -> 125 | J7: =$G7*35% -> 175 | K7: =$G7*25% -> 125 | L7: =(SUMIFS(终端客户销售统计表!$K:$K,终端客户销售统计表!$L:$L,$B7,终端客户销售统计表!$H:$H,$D7,终端客户销售统计表!$G:$G,"1月")+SUMIFS(终端客户销售统计表!$K:$K,终端客户销售统计表!$L:$L,$B7,终端客户销售统计表!$H:$H,$D7,终端客户销售统计表!$G:$G,"2月")+SUMIFS(终端客户销售统计表!$K:$K,终端客户销售统计表!$L:$L,$B7,终端客户销售统计表!$H:$H,$D7,终端客户销售统计表!$G:$G,"3月"))/10000 -> 100 | M7: =(SUMIFS(终端客户销售统计表!$K:$K,终端客户销售统计表!$L:$L,$B7,终端客户销售统计表!$H:$H,$D7,终端客户销售统计表!$G:$G,"4月")+SUMIFS(终端客户销售统计表!$K:$K,终端客户销售统计表!$L:$L,$B7,终端客户销售统计表!$H:$H,$D7,终端客户销售统计表!$G:$G,"5月")+SUMIFS(终端客户销售统计表!$K:$K,终端客户销售统计表!$L:$L,$B7,终端客户销售统计表!$H:$H,$D7,终端客户销售统计表!$G:$G,"6月"))/10000 -> 0 | N7: =(SUMIFS(终端客户销售统计表!$K:$K,终端客户销售统计表!$L:$L,$B7,终端客户销售统计表!$H:$H,$D7,终端客户销售统计表!$G:$G,"7月")+SUMIFS(终端客户销售统计表!$K:$K,终端客户销售统计表!$L:$L,$B7,终端客户销售统计表!$H:$H,$D7,终端客户销售统计表!$G:$G,"8月")+SUMIFS(终端客户销售统计表!$K:$K,终端客户销售统计表!$L:$L,$B7,终端客户销售统计表!$H:$H,$D7,终端客户销售统计表!$G:$G,"9月"))/10000 -> 0 | O7: =(SUMIFS(终端客户销售统计表!$K:$K,终端客户销售统计表!$L:$L,$B7,终端客户销售统计表!$H:$H,$D7,终端客户销售统计表!$G:$G,"10月")+SUMIFS(终端客户销售统计表!$K:$K,终端客户销售统计表!$L:$L,$B7,终端客户销售统计表!$H:$H,$D7,终端客户销售统计表!$G:$G,"11月")+SUMIFS(终端客户销售统计表!$K:$K,终端客户销售统计表!$L:$L,$B7,终端客户销售统计表!$H:$H,$D7,终端客户销售统计表!$G:$G,"12月"))/10000 -> 0 | P7: =SUM(L7:O7) -> 100 | Q7: =IFERROR(P7/G7,"") -> 0.2 | R7: =(SUMIFS('代理商-进货明细表'!$I:$I,'代理商-进货明细表'!$B:$B,'代理商-产品进销存'!$B7,'代理商-进货明细表'!$F:$F,'代理商-产品进销存'!$D7,'代理商-进货明细表'!$E:$E,"1月")+SUMIFS('代理商-进货明细表'!$I:$I,'代理商-进货明细表'!$B:$B,'代理商-产品进销存'!$B7,'代理商-进货明细表'!$F:$F,'代理商-产品进销存'!$D7,'代理商-进货明细表'!$E:$E,"2月")+SUMIFS('代理商-进货明细表'!$I:$I,'代理商-进货明细表'!$B:$B,'代理商-产品进销存'!$B7,'代理商-进货明细表'!$F:$F,'代理商-产品进销存'!$D7,'代理商-进货明细表'!$E:$E,"3月"))/10000 -> 0 | S7: =(SUMIFS('代理商-进货明细表'!$I:$I,'代理商-进货明细表'!$B:$B,'代理商-产品进销存'!$B7,'代理商-进货明细表'!$F:$F,'代理商-产品进销存'!$D7,'代理商-进货明细表'!$E:$E,"4月")+SUMIFS('代理商-进货明细表'!$I:$I,'代理商-进货明细表'!$B:$B,'代理商-产品进销存'!$B7,'代理商-进货明细表'!$F:$F,'代理商-产品进销存'!$D7,'代理商-进货明细表'!$E:$E,"5月")+SUMIFS('代理商-进货明细表'!$I:$I,'代理商-进货明细表'!$B:$B,'代理商-产品进销存'!$B7,'代理商-进货明细表'!$F:$F,'代理商-产品进销存'!$D7,'代理商-进货明细表'!$E:$E,"6月"))/10000 -> 0 | T7: =(SUMIFS('代理商-进货明细表'!$I:$I,'代理商-进货明细表'!$B:$B,'代理商-产品进销存'!$B7,'代理商-进货明细表'!$F:$F,'代理商-产品进销存'!$D7,'代理商-进货明细表'!$E:$E,"7月")+SUMIFS('代理商-进货明细表'!$I:$I,'代理商-进货明细表'!$B:$B,'代理商-产品进销存'!$B7,'代理商-进货明细表'!$F:$F,'代理商-产品进销存'!$D7,'代理商-进货明细表'!$E:$E,"8月")+SUMIFS('代理商-进货明细表'!$I:$I,'代理商-进货明细表'!$B:$B,'代理商-产品进销存'!$B7,'代理商-进货明细表'!$F:$F,'代理商-产品进销存'!$D7,'代理商-进货明细表'!$E:$E,"9月"))/10000 -> 0 | U7: =(SUMIFS('代理商-进货明细表'!$I:$I,'代理商-进货明细表'!$B:$B,'代理商-产品进销存'!$B7,'代理商-进货明细表'!$F:$F,'代理商-产品进销存'!$D7,'代理商-进货明细表'!$E:$E,"10月")+SUMIFS('代理商-进货明细表'!$I:$I,'代理商-进货明细表'!$B:$B,'代理商-产品进销存'!$B7,'代理商-进货明细表'!$F:$F,'代理商-产品进销存'!$D7,'代理商-进货明细表'!$E:$E,"11月")+SUMIFS('代理商-进货明细表'!$I:$I,'代理商-进货明细表'!$B:$B,'代理商-产品进销存'!$B7,'代理商-进货明细表'!$F:$F,'代理商-产品进销存'!$D7,'代理商-进货明细表'!$E:$E,"12月"))/10000 -> 0 | V7: =SUM(R7:U7) -> 0 | W7: =R7-L7 -> -100 | X7: =S7-M7 -> 0 | Y7: =T7-N7 -> 0 | Z7: =U7-O7 -> 0 | AA7: =SUM(W7:Z7) -> -100
A8: A00002 | B8: 公司2 | D8: 时空之眼 | E8: 500 | F8: 10000 | G8: =E8*F8/10000 -> 500 | H8: =$G8*15% -> 75 | I8: =$G8*25% -> 125 | J8: =$G8*35% -> 175 | K8: =$G8*25% -> 125 | L8: =(SUMIFS(终端客户销售统计表!$K:$K,终端客户销售统计表!$L:$L,$B8,终端客户销售统计表!$H:$H,$D8,终端客户销售统计表!$G:$G,"1月")+SUMIFS(终端客户销售统计表!$K:$K,终端客户销售统计表!$L:$L,$B8,终端客户销售统计表!$H:$H,$D8,终端客户销售统计表!$G:$G,"2月")+SUMIFS(终端客户销售统计表!$K:$K,终端客户销售统计表!$L:$L,$B8,终端客户销售统计表!$H:$H,$D8,终端客户销售统计表!$G:$G,"3月"))/10000 -> 0 | M8: =(SUMIFS(终端客户销售统计表!$K:$K,终端客户销售统计表!$L:$L,$B8,终端客户销售统计表!$H:$H,$D8,终端客户销售统计表!$G:$G,"4月")+SUMIFS(终端客户销售统计表!$K:$K,终端客户销售统计表!$L:$L,$B8,终端客户销售统计表!$H:$H,$D8,终端客户销售统计表!$G:$G,"5月")+SUMIFS(终端客户销售统计表!$K:$K,终端客户销售统计表!$L:$L,$B8,终端客户销售统计表!$H:$H,$D8,终端客户销售统计表!$G:$G,"6月"))/10000 -> 100 | N8: =(SUMIFS(终端客户销售统计表!$K:$K,终端客户销售统计表!$L:$L,$B8,终端客户销售统计表!$H:$H,$D8,终端客户销售统计表!$G:$G,"7月")+SUMIFS(终端客户销售统计表!$K:$K,终端客户销售统计表!$L:$L,$B8,终端客户销售统计表!$H:$H,$D8,终端客户销售统计表!$G:$G,"8月")+SUMIFS(终端客户销售统计表!$K:$K,终端客户销售统计表!$L:$L,$B8,终端客户销售统计表!$H:$H,$D8,终端客户销售统计表!$G:$G,"9月"))/10000 -> 0 | O8: =(SUMIFS(终端客户销售统计表!$K:$K,终端客户销售统计表!$L:$L,$B8,终端客户销售统计表!$H:$H,$D8,终端客户销售统计表!$G:$G,"10月")+SUMIFS(终端客户销售统计表!$K:$K,终端客户销售统计表!$L:$L,$B8,终端客户销售统计表!$H:$H,$D8,终端客户销售统计表!$G:$G,"11月")+SUMIFS(终端客户销售统计表!$K:$K,终端客户销售统计表!$L:$L,$B8,终端客户销售统计表!$H:$H,$D8,终端客户销售统计表!$G:$G,"12月"))/10000 -> 0 | P8: =SUM(L8:O8) -> 100 | Q8: =IFERROR(P8/G8,"") -> 0.2 | R8: =(SUMIFS('代理商-进货明细表'!$I:$I,'代理商-进货明细表'!$B:$B,'代理商-产品进销存'!$B8,'代理商-进货明细表'!$F:$F,'代理商-产品进销存'!$D8,'代理商-进货明细表'!$E:$E,"1月")+SUMIFS('代理商-进货明细表'!$I:$I,'代理商-进货明细表'!$B:$B,'代理商-产品进销存'!$B8,'代理商-进货明细表'!$F:$F,'代理商-产品进销存'!$D8,'代理商-进货明细表'!$E:$E,"2月")+SUMIFS('代理商-进货明细表'!$I:$I,'代理商-进货明细表'!$B:$B,'代理商-产品进销存'!$B8,'代理商-进货明细表'!$F:$F,'代理商-产品进销存'!$D8,'代理商-进货明细表'!$E:$E,"3月"))/10000 -> 0 | S8: =(SUMIFS('代理商-进货明细表'!$I:$I,'代理商-进货明细表'!$B:$B,'代理商-产品进销存'!$B8,'代理商-进货明细表'!$F:$F,'代理商-产品进销存'!$D8,'代理商-进货明细表'!$E:$E,"4月")+SUMIFS('代理商-进货明细表'!$I:$I,'代理商-进货明细表'!$B:$B,'代理商-产品进销存'!$B8,'代理商-进货明细表'!$F:$F,'代理商-产品进销存'!$D8,'代理商-进货明细表'!$E:$E,"5月")+SUMIFS('代理商-进货明细表'!$I:$I,'代理商-进货明细表'!$B:$B,'代理商-产品进销存'!$B8,'代理商-进货明细表'!$F:$F,'代理商-产品进销存'!$D8,'代理商-进货明细表'!$E:$E,"6月"))/10000 -> 0 | T8: =(SUMIFS('代理商-进货明细表'!$I:$I,'代理商-进货明细表'!$B:$B,'代理商-产品进销存'!$B8,'代理商-进货明细表'!$F:$F,'代理商-产品进销存'!$D8,'代理商-进货明细表'!$E:$E,"7月")+SUMIFS('代理商-进货明细表'!$I:$I,'代理商-进货明细表'!$B:$B,'代理商-产品进销存'!$B8,'代理商-进货明细表'!$F:$F,'代理商-产品进销存'!$D8,'代理商-进货明细表'!$E:$E,"8月")+SUMIFS('代理商-进货明细表'!$I:$I,'代理商-进货明细表'!$B:$B,'代理商-产品进销存'!$B8,'代理商-进货明细表'!$F:$F,'代理商-产品进销存'!$D8,'代理商-进货明细表'!$E:$E,"9月"))/10000 -> 0 | U8: =(SUMIFS('代理商-进货明细表'!$I:$I,'代理商-进货明细表'!$B:$B,'代理商-产品进销存'!$B8,'代理商-进货明细表'!$F:$F,'代理商-产品进销存'!$D8,'代理商-进货明细表'!$E:$E,"10月")+SUMIFS('代理商-进货明细表'!$I:$I,'代理商-进货明细表'!$B:$B,'代理商-产品进销存'!$B8,'代理商-进货明细表'!$F:$F,'代理商-产品进销存'!$D8,'代理商-进货明细表'!$E:$E,"11月")+SUMIFS('代理商-进货明细表'!$I:$I,'代理商-进货明细表'!$B:$B,'代理商-产品进销存'!$B8,'代理商-进货明细表'!$F:$F,'代理商-产品进销存'!$D8,'代理商-进货明细表'!$E:$E,"12月"))/10000 -> 0 | V8: =SUM(R8:U8) -> 0 | W8: =R8-L8 -> 0 | X8: =S8-M8 -> -100 | Y8: =T8-N8 -> 0 | Z8: =U8-O8 -> 0 | AA8: =SUM(W8:Z8) -> -100
A9: A00002 | B9: 公司2 | D9: 小旋风 | E9: 500 | F9: 10000 | G9: =E9*F9/10000 -> 500 | H9: =$G9*15% -> 75 | I9: =$G9*25% -> 125 | J9: =$G9*35% -> 175 | K9: =$G9*25% -> 125 | L9: =(SUMIFS(终端客户销售统计表!$K:$K,终端客户销售统计表!$L:$L,$B9,终端客户销售统计表!$H:$H,$D9,终端客户销售统计表!$G:$G,"1月")+SUMIFS(终端客户销售统计表!$K:$K,终端客户销售统计表!$L:$L,$B9,终端客户销售统计表!$H:$H,$D9,终端客户销售统计表!$G:$G,"2月")+SUMIFS(终端客户销售统计表!$K:$K,终端客户销售统计表!$L:$L,$B9,终端客户销售统计表!$H:$H,$D9,终端客户销售统计表!$G:$G,"3月"))/10000 -> 0 | M9: =(SUMIFS(终端客户销售统计表!$K:$K,终端客户销售统计表!$L:$L,$B9,终端客户销售统计表!$H:$H,$D9,终端客户销售统计表!$G:$G,"4月")+SUMIFS(终端客户销售统计表!$K:$K,终端客户销售统计表!$L:$L,$B9,终端客户销售统计表!$H:$H,$D9,终端客户销售统计表!$G:$G,"5月")+SUMIFS(终端客户销售统计表!$K:$K,终端客户销售统计表!$L:$L,$B9,终端客户销售统计表!$H:$H,$D9,终端客户销售统计表!$G:$G,"6月"))/10000 -> 0 | N9: =(SUMIFS(终端客户销售统计表!$K:$K,终端客户销售统计表!$L:$L,$B9,终端客户销售统计表!$H:$H,$D9,终端客户销售统计表!$G:$G,"7月")+SUMIFS(终端客户销售统计表!$K:$K,终端客户销售统计表!$L:$L,$B9,终端客户销售统计表!$H:$H,$D9,终端客户销售统计表!$G:$G,"8月")+SUMIFS(终端客户销售统计表!$K:$K,终端客户销售统计表!$L:$L,$B9,终端客户销售统计表!$H:$H,$D9,终端客户销售统计表!$G:$G,"9月"))/10000 -> 100 | O9: =(SUMIFS(终端客户销售统计表!$K:$K,终端客户销售统计表!$L:$L,$B9,终端客户销售统计表!$H:$H,$D9,终端客户销售统计表!$G:$G,"10月")+SUMIFS(终端客户销售统计表!$K:$K,终端客户销售统计表!$L:$L,$B9,终端客户销售统计表!$H:$H,$D9,终端客户销售统计表!$G:$G,"11月")+SUMIFS(终端客户销售统计表!$K:$K,终端客户销售统计表!$L:$L,$B9,终端客户销售统计表!$H:$H,$D9,终端客户销售统计表!$G:$G,"12月"))/10000 -> 0 | P9: =SUM(L9:O9) -> 100 | Q9: =IFERROR(P9/G9,"") -> 0.2 | R9: =(SUMIFS('代理商-进货明细表'!$I:$I,'代理商-进货明细表'!$B:$B,'代理商-产品进销存'!$B9,'代理商-进货明细表'!$F:$F,'代理商-产品进销存'!$D9,'代理商-进货明细表'!$E:$E,"1月")+SUMIFS('代理商-进货明细表'!$I:$I,'代理商-进货明细表'!$B:$B,'代理商-产品进销存'!$B9,'代理商-进货明细表'!$F:$F,'代理商-产品进销存'!$D9,'代理商-进货明细表'!$E:$E,"2月")+SUMIFS('代理商-进货明细表'!$I:$I,'代理商-进货明细表'!$B:$B,'代理商-产品进销存'!$B9,'代理商-进货明细表'!$F:$F,'代理商-产品进销存'!$D9,'代理商-进货明细表'!$E:$E,"3月"))/10000 -> 0 | S9: =(SUMIFS('代理商-进货明细表'!$I:$I,'代理商-进货明细表'!$B:$B,'代理商-产品进销存'!$B9,'代理商-进货明细表'!$F:$F,'代理商-产品进销存'!$D9,'代理商-进货明细表'!$E:$E,"4月")+SUMIFS('代理商-进货明细表'!$I:$I,'代理商-进货明细表'!$B:$B,'代理商-产品进销存'!$B9,'代理商-进货明细表'!$F:$F,'代理商-产品进销存'!$D9,'代理商-进货明细表'!$E:$E,"5月")+SUMIFS('代理商-进货明细表'!$I:$I,'代理商-进货明细表'!$B:$B,'代理商-产品进销存'!$B9,'代理商-进货明细表'!$F:$F,'代理商-产品进销存'!$D9,'代理商-进货明细表'!$E:$E,"6月"))/10000 -> 0 | T9: =(SUMIFS('代理商-进货明细表'!$I:$I,'代理商-进货明细表'!$B:$B,'代理商-产品进销存'!$B9,'代理商-进货明细表'!$F:$F,'代理商-产品进销存'!$D9,'代理商-进货明细表'!$E:$E,"7月")+SUMIFS('代理商-进货明细表'!$I:$I,'代理商-进货明细表'!$B:$B,'代理商-产品进销存'!$B9,'代理商-进货明细表'!$F:$F,'代理商-产品进销存'!$D9,'代理商-进货明细表'!$E:$E,"8月")+SUMIFS('代理商-进货明细表'!$I:$I,'代理商-进货明细表'!$B:$B,'代理商-产品进销存'!$B9,'代理商-进货明细表'!$F:$F,'代理商-产品进销存'!$D9,'代理商-进货明细表'!$E:$E,"9月"))/10000 -> 0 | U9: =(SUMIFS('代理商-进货明细表'!$I:$I,'代理商-进货明细表'!$B:$B,'代理商-产品进销存'!$B9,'代理商-进货明细表'!$F:$F,'代理商-产品进销存'!$D9,'代理商-进货明细表'!$E:$E,"10月")+SUMIFS('代理商-进货明细表'!$I:$I,'代理商-进货明细表'!$B:$B,'代理商-产品进销存'!$B9,'代理商-进货明细表'!$F:$F,'代理商-产品进销存'!$D9,'代理商-进货明细表'!$E:$E,"11月")+SUMIFS('代理商-进货明细表'!$I:$I,'代理商-进货明细表'!$B:$B,'代理商-产品进销存'!$B9,'代理商-进货明细表'!$F:$F,'代理商-产品进销存'!$D9,'代理商-进货明细表'!$E:$E,"12月"))/10000 -> 0 | V9: =SUM(R9:U9) -> 0 | W9: =R9-L9 -> 0 | X9: =S9-M9 -> 0 | Y9: =T9-N9 -> -100 | Z9: =U9-O9 -> 0 | AA9: =SUM(W9:Z9) -> -100
A10: A00002 | B10: 公司2 | D10: OK7 | E10: 500 | F10: 10000 | G10: =E10*F10/10000 -> 500 | H10: =$G10*15% -> 75 | I10: =$G10*25% -> 125 | J10: =$G10*35% -> 175 | K10: =$G10*25% -> 125 | L10: =(SUMIFS(终端客户销售统计表!$K:$K,终端客户销售统计表!$L:$L,$B10,终端客户销售统计表!$H:$H,$D10,终端客户销售统计表!$G:$G,"1月")+SUMIFS(终端客户销售统计表!$K:$K,终端客户销售统计表!$L:$L,$B10,终端客户销售统计表!$H:$H,$D10,终端客户销售统计表!$G:$G,"2月")+SUMIFS(终端客户销售统计表!$K:$K,终端客户销售统计表!$L:$L,$B10,终端客户销售统计表!$H:$H,$D10,终端客户销售统计表!$G:$G,"3月"))/10000 -> 0 | M10: =(SUMIFS(终端客户销售统计表!$K:$K,终端客户销售统计表!$L:$L,$B10,终端客户销售统计表!$H:$H,$D10,终端客户销售统计表!$G:$G,"4月")+SUMIFS(终端客户销售统计表!$K:$K,终端客户销售统计表!$L:$L,$B10,终端客户销售统计表!$H:$H,$D10,终端客户销售统计表!$G:$G,"5月")+SUMIFS(终端客户销售统计表!$K:$K,终端客户销售统计表!$L:$L,$B10,终端客户销售统计表!$H:$H,$D10,终端客户销售统计表!$G:$G,"6月"))/10000 -> 0 | N10: =(SUMIFS(终端客户销售统计表!$K:$K,终端客户销售统计表!$L:$L,$B10,终端客户销售统计表!$H:$H,$D10,终端客户销售统计表!$G:$G,"7月")+SUMIFS(终端客户销售统计表!$K:$K,终端客户销售统计表!$L:$L,$B10,终端客户销售统计表!$H:$H,$D10,终端客户销售统计表!$G:$G,"8月")+SUMIFS(终端客户销售统计表!$K:$K,终端客户销售统计表!$L:$L,$B10,终端客户销售统计表!$H:$H,$D10,终端客户销售统计表!$G:$G,"9月"))/10000 -> 0 | O10: =(SUMIFS(终端客户销售统计表!$K:$K,终端客户销售统计表!$L:$L,$B10,终端客户销售统计表!$H:$H,$D10,终端客户销售统计表!$G:$G,"10月")+SUMIFS(终端客户销售统计表!$K:$K,终端客户销售统计表!$L:$L,$B10,终端客户销售统计表!$H:$H,$D10,终端客户销售统计表!$G:$G,"11月")+SUMIFS(终端客户销售统计表!$K:$K,终端客户销售统计表!$L:$L,$B10,终端客户销售统计表!$H:$H,$D10,终端客户销售统计表!$G:$G,"12月"))/10000 -> 100 | P10: =SUM(L10:O10) -> 100 | Q10: =IFERROR(P10/G10,"") -> 0.2 | R10: =(SUMIFS('代理商-进货明细表'!$I:$I,'代理商-进货明细表'!$B:$B,'代理商-产品进销存'!$B10,'代理商-进货明细表'!$F:$F,'代理商-产品进销存'!$D10,'代理商-进货明细表'!$E:$E,"1月")+SUMIFS('代理商-进货明细表'!$I:$I,'代理商-进货明细表'!$B:$B,'代理商-产品进销存'!$B10,'代理商-进货明细表'!$F:$F,'代理商-产品进销存'!$D10,'代理商-进货明细表'!$E:$E,"2月")+SUMIFS('代理商-进货明细表'!$I:$I,'代理商-进货明细表'!$B:$B,'代理商-产品进销存'!$B10,'代理商-进货明细表'!$F:$F,'代理商-产品进销存'!$D10,'代理商-进货明细表'!$E:$E,"3月"))/10000 -> 0 | S10: =(SUMIFS('代理商-进货明细表'!$I:$I,'代理商-进货明细表'!$B:$B,'代理商-产品进销存'!$B10,'代理商-进货明细表'!$F:$F,'代理商-产品进销存'!$D10,'代理商-进货明细表'!$E:$E,"4月")+SUMIFS('代理商-进货明细表'!$I:$I,'代理商-进货明细表'!$B:$B,'代理商-产品进销存'!$B10,'代理商-进货明细表'!$F:$F,'代理商-产品进销存'!$D10,'代理商-进货明细表'!$E:$E,"5月")+SUMIFS('代理商-进货明细表'!$I:$I,'代理商-进货明细表'!$B:$B,'代理商-产品进销存'!$B10,'代理商-进货明细表'!$F:$F,'代理商-产品进销存'!$D10,'代理商-进货明细表'!$E:$E,"6月"))/10000 -> 0 | T10: =(SUMIFS('代理商-进货明细表'!$I:$I,'代理商-进货明细表'!$B:$B,'代理商-产品进销存'!$B10,'代理商-进货明细表'!$F:$F,'代理商-产品进销存'!$D10,'代理商-进货明细表'!$E:$E,"7月")+SUMIFS('代理商-进货明细表'!$I:$I,'代理商-进货明细表'!$B:$B,'代理商-产品进销存'!$B10,'代理商-进货明细表'!$F:$F,'代理商-产品进销存'!$D10,'代理商-进货明细表'!$E:$E,"8月")+SUMIFS('代理商-进货明细表'!$I:$I,'代理商-进货明细表'!$B:$B,'代理商-产品进销存'!$B10,'代理商-进货明细表'!$F:$F,'代理商-产品进销存'!$D10,'代理商-进货明细表'!$E:$E,"9月"))/10000 -> 0 | U10: =(SUMIFS('代理商-进货明细表'!$I:$I,'代理商-进货明细表'!$B:$B,'代理商-产品进销存'!$B10,'代理商-进货明细表'!$F:$F,'代理商-产品进销存'!$D10,'代理商-进货明细表'!$E:$E,"10月")+SUMIFS('代理商-进货明细表'!$I:$I,'代理商-进货明细表'!$B:$B,'代理商-产品进销存'!$B10,'代理商-进货明细表'!$F:$F,'代理商-产品进销存'!$D10,'代理商-进货明细表'!$E:$E,"11月")+SUMIFS('代理商-进货明细表'!$I:$I,'代理商-进货明细表'!$B:$B,'代理商-产品进销存'!$B10,'代理商-进货明细表'!$F:$F,'代理商-产品进销存'!$D10,'代理商-进货明细表'!$E:$E,"12月"))/10000 -> 0 | V10: =SUM(R10:U10) -> 0 | W10: =R10-L10 -> 0 | X10: =S10-M10 -> 0 | Y10: =T10-N10 -> 0 | Z10: =U10-O10 -> -100 | AA10: =SUM(W10:Z10) -> -100
A11: A00003 | B11: 公司3 | D11: Ultra | E11: 500 | F11: 10000 | G11: =E11*F11/10000 -> 500 | H11: =$G11*15% -> 75 | I11: =$G11*25% -> 125 | J11: =$G11*35% -> 175 | K11: =$G11*25% -> 125 | L11: =(SUMIFS(终端客户销售统计表!$K:$K,终端客户销售统计表!$L:$L,$B11,终端客户销售统计表!$H:$H,$D11,终端客户销售统计表!$G:$G,"1月")+SUMIFS(终端客户销售统计表!$K:$K,终端客户销售统计表!$L:$L,$B11,终端客户销售统计表!$H:$H,$D11,终端客户销售统计表!$G:$G,"2月")+SUMIFS(终端客户销售统计表!$K:$K,终端客户销售统计表!$L:$L,$B11,终端客户销售统计表!$H:$H,$D11,终端客户销售统计表!$G:$G,"3月"))/10000 -> 100 | M11: =(SUMIFS(终端客户销售统计表!$K:$K,终端客户销售统计表!$L:$L,$B11,终端客户销售统计表!$H:$H,$D11,终端客户销售统计表!$G:$G,"4月")+SUMIFS(终端客户销售统计表!$K:$K,终端客户销售统计表!$L:$L,$B11,终端客户销售统计表!$H:$H,$D11,终端客户销售统计表!$G:$G,"5月")+SUMIFS(终端客户销售统计表!$K:$K,终端客户销售统计表!$L:$L,$B11,终端客户销售统计表!$H:$H,$D11,终端客户销售统计表!$G:$G,"6月"))/10000 -> 0 | N11: =(SUMIFS(终端客户销售统计表!$K:$K,终端客户销售统计表!$L:$L,$B11,终端客户销售统计表!$H:$H,$D11,终端客户销售统计表!$G:$G,"7月")+SUMIFS(终端客户销售统计表!$K:$K,终端客户销售统计表!$L:$L,$B11,终端客户销售统计表!$H:$H,$D11,终端客户销售统计表!$G:$G,"8月")+SUMIFS(终端客户销售统计表!$K:$K,终端客户销售统计表!$L:$L,$B11,终端客户销售统计表!$H:$H,$D11,终端客户销售统计表!$G:$G,"9月"))/10000 -> 0 | O11: =(SUMIFS(终端客户销售统计表!$K:$K,终端客户销售统计表!$L:$L,$B11,终端客户销售统计表!$H:$H,$D11,终端客户销售统计表!$G:$G,"10月")+SUMIFS(终端客户销售统计表!$K:$K,终端客户销售统计表!$L:$L,$B11,终端客户销售统计表!$H:$H,$D11,终端客户销售统计表!$G:$G,"11月")+SUMIFS(终端客户销售统计表!$K:$K,终端客户销售统计表!$L:$L,$B11,终端客户销售统计表!$H:$H,$D11,终端客户销售统计表!$G:$G,"12月"))/10000 -> 0 | P11: =SUM(L11:O11) -> 100 | Q11: =IFERROR(P11/G11,"") -> 0.2 | R11: =(SUMIFS('代理商-进货明细表'!$I:$I,'代理商-进货明细表'!$B:$B,'代理商-产品进销存'!$B11,'代理商-进货明细表'!$F:$F,'代理商-产品进销存'!$D11,'代理商-进货明细表'!$E:$E,"1月")+SUMIFS('代理商-进货明细表'!$I:$I,'代理商-进货明细表'!$B:$B,'代理商-产品进销存'!$B11,'代理商-进货明细表'!$F:$F,'代理商-产品进销存'!$D11,'代理商-进货明细表'!$E:$E,"2月")+SUMIFS('代理商-进货明细表'!$I:$I,'代理商-进货明细表'!$B:$B,'代理商-产品进销存'!$B11,'代理商-进货明细表'!$F:$F,'代理商-产品进销存'!$D11,'代理商-进货明细表'!$E:$E,"3月"))/10000 -> 0 | S11: =(SUMIFS('代理商-进货明细表'!$I:$I,'代理商-进货明细表'!$B:$B,'代理商-产品进销存'!$B11,'代理商-进货明细表'!$F:$F,'代理商-产品进销存'!$D11,'代理商-进货明细表'!$E:$E,"4月")+SUMIFS('代理商-进货明细表'!$I:$I,'代理商-进货明细表'!$B:$B,'代理商-产品进销存'!$B11,'代理商-进货明细表'!$F:$F,'代理商-产品进销存'!$D11,'代理商-进货明细表'!$E:$E,"5月")+SUMIFS('代理商-进货明细表'!$I:$I,'代理商-进货明细表'!$B:$B,'代理商-产品进销存'!$B11,'代理商-进货明细表'!$F:$F,'代理商-产品进销存'!$D11,'代理商-进货明细表'!$E:$E,"6月"))/10000 -> 0 | T11: =(SUMIFS('代理商-进货明细表'!$I:$I,'代理商-进货明细表'!$B:$B,'代理商-产品进销存'!$B11,'代理商-进货明细表'!$F:$F,'代理商-产品进销存'!$D11,'代理商-进货明细表'!$E:$E,"7月")+SUMIFS('代理商-进货明细表'!$I:$I,'代理商-进货明细表'!$B:$B,'代理商-产品进销存'!$B11,'代理商-进货明细表'!$F:$F,'代理商-产品进销存'!$D11,'代理商-进货明细表'!$E:$E,"8月")+SUMIFS('代理商-进货明细表'!$I:$I,'代理商-进货明细表'!$B:$B,'代理商-产品进销存'!$B11,'代理商-进货明细表'!$F:$F,'代理商-产品进销存'!$D11,'代理商-进货明细表'!$E:$E,"9月"))/10000 -> 0 | U11: =(SUMIFS('代理商-进货明细表'!$I:$I,'代理商-进货明细表'!$B:$B,'代理商-产品进销存'!$B11,'代理商-进货明细表'!$F:$F,'代理商-产品进销存'!$D11,'代理商-进货明细表'!$E:$E,"10月")+SUMIFS('代理商-进货明细表'!$I:$I,'代理商-进货明细表'!$B:$B,'代理商-产品进销存'!$B11,'代理商-进货明细表'!$F:$F,'代理商-产品进销存'!$D11,'代理商-进货明细表'!$E:$E,"11月")+SUMIFS('代理商-进货明细表'!$I:$I,'代理商-进货明细表'!$B:$B,'代理商-产品进销存'!$B11,'代理商-进货明细表'!$F:$F,'代理商-产品进销存'!$D11,'代理商-进货明细表'!$E:$E,"12月"))/10000 -> 0 | V11: =SUM(R11:U11) -> 0 | W11: =R11-L11 -> -100 | X11: =S11-M11 -> 0 | Y11: =T11-N11 -> 0 | Z11: =U11-O11 -> 0 | AA11: =SUM(W11:Z11) -> -100
A12: A00003 | B12: 公司3 | D12: 时空之眼 | E12: 500 | F12: 10000 | G12: =E12*F12/10000 -> 500 | H12: =$G12*15% -> 75 | I12: =$G12*25% -> 125 | J12: =$G12*35% -> 175 | K12: =$G12*25% -> 125 | L12: =(SUMIFS(终端客户销售统计表!$K:$K,终端客户销售统计表!$L:$L,$B12,终端客户销售统计表!$H:$H,$D12,终端客户销售统计表!$G:$G,"1月")+SUMIFS(终端客户销售统计表!$K:$K,终端客户销售统计表!$L:$L,$B12,终端客户销售统计表!$H:$H,$D12,终端客户销售统计表!$G:$G,"2月")+SUMIFS(终端客户销售统计表!$K:$K,终端客户销售统计表!$L:$L,$B12,终端客户销售统计表!$H:$H,$D12,终端客户销售统计表!$G:$G,"3月"))/10000 -> 0 | M12: =(SUMIFS(终端客户销售统计表!$K:$K,终端客户销售统计表!$L:$L,$B12,终端客户销售统计表!$H:$H,$D12,终端客户销售统计表!$G:$G,"4月")+SUMIFS(终端客户销售统计表!$K:$K,终端客户销售统计表!$L:$L,$B12,终端客户销售统计表!$H:$H,$D12,终端客户销售统计表!$G:$G,"5月")+SUMIFS(终端客户销售统计表!$K:$K,终端客户销售统计表!$L:$L,$B12,终端客户销售统计表!$H:$H,$D12,终端客户销售统计表!$G:$G,"6月"))/10000 -> 100 | N12: =(SUMIFS(终端客户销售统计表!$K:$K,终端客户销售统计表!$L:$L,$B12,终端客户销售统计表!$H:$H,$D12,终端客户销售统计表!$G:$G,"7月")+SUMIFS(终端客户销售统计表!$K:$K,终端客户销售统计表!$L:$L,$B12,终端客户销售统计表!$H:$H,$D12,终端客户销售统计表!$G:$G,"8月")+SUMIFS(终端客户销售统计表!$K:$K,终端客户销售统计表!$L:$L,$B12,终端客户销售统计表!$H:$H,$D12,终端客户销售统计表!$G:$G,"9月"))/10000 -> 0 | O12: =(SUMIFS(终端客户销售统计表!$K:$K,终端客户销售统计表!$L:$L,$B12,终端客户销售统计表!$H:$H,$D12,终端客户销售统计表!$G:$G,"10月")+SUMIFS(终端客户销售统计表!$K:$K,终端客户销售统计表!$L:$L,$B12,终端客户销售统计表!$H:$H,$D12,终端客户销售统计表!$G:$G,"11月")+SUMIFS(终端客户销售统计表!$K:$K,终端客户销售统计表!$L:$L,$B12,终端客户销售统计表!$H:$H,$D12,终端客户销售统计表!$G:$G,"12月"))/10000 -> 0 | P12: =SUM(L12:O12) -> 100 | Q12: =IFERROR(P12/G12,"") -> 0.2 | R12: =(SUMIFS('代理商-进货明细表'!$I:$I,'代理商-进货明细表'!$B:$B,'代理商-产品进销存'!$B12,'代理商-进货明细表'!$F:$F,'代理商-产品进销存'!$D12,'代理商-进货明细表'!$E:$E,"1月")+SUMIFS('代理商-进货明细表'!$I:$I,'代理商-进货明细表'!$B:$B,'代理商-产品进销存'!$B12,'代理商-进货明细表'!$F:$F,'代理商-产品进销存'!$D12,'代理商-进货明细表'!$E:$E,"2月")+SUMIFS('代理商-进货明细表'!$I:$I,'代理商-进货明细表'!$B:$B,'代理商-产品进销存'!$B12,'代理商-进货明细表'!$F:$F,'代理商-产品进销存'!$D12,'代理商-进货明细表'!$E:$E,"3月"))/10000 -> 0 | S12: =(SUMIFS('代理商-进货明细表'!$I:$I,'代理商-进货明细表'!$B:$B,'代理商-产品进销存'!$B12,'代理商-进货明细表'!$F:$F,'代理商-产品进销存'!$D12,'代理商-进货明细表'!$E:$E,"4月")+SUMIFS('代理商-进货明细表'!$I:$I,'代理商-进货明细表'!$B:$B,'代理商-产品进销存'!$B12,'代理商-进货明细表'!$F:$F,'代理商-产品进销存'!$D12,'代理商-进货明细表'!$E:$E,"5月")+SUMIFS('代理商-进货明细表'!$I:$I,'代理商-进货明细表'!$B:$B,'代理商-产品进销存'!$B12,'代理商-进货明细表'!$F:$F,'代理商-产品进销存'!$D12,'代理商-进货明细表'!$E:$E,"6月"))/10000 -> 0 | T12: =(SUMIFS('代理商-进货明细表'!$I:$I,'代理商-进货明细表'!$B:$B,'代理商-产品进销存'!$B12,'代理商-进货明细表'!$F:$F,'代理商-产品进销存'!$D12,'代理商-进货明细表'!$E:$E,"7月")+SUMIFS('代理商-进货明细表'!$I:$I,'代理商-进货明细表'!$B:$B,'代理商-产品进销存'!$B12,'代理商-进货明细表'!$F:$F,'代理商-产品进销存'!$D12,'代理商-进货明细表'!$E:$E,"8月")+SUMIFS('代理商-进货明细表'!$I:$I,'代理商-进货明细表'!$B:$B,'代理商-产品进销存'!$B12,'代理商-进货明细表'!$F:$F,'代理商-产品进销存'!$D12,'代理商-进货明细表'!$E:$E,"9月"))/10000 -> 0 | U12: =(SUMIFS('代理商-进货明细表'!$I:$I,'代理商-进货明细表'!$B:$B,'代理商-产品进销存'!$B12,'代理商-进货明细表'!$F:$F,'代理商-产品进销存'!$D12,'代理商-进货明细表'!$E:$E,"10月")+SUMIFS('代理商-进货明细表'!$I:$I,'代理商-进货明细表'!$B:$B,'代理商-产品进销存'!$B12,'代理商-进货明细表'!$F:$F,'代理商-产品进销存'!$D12,'代理商-进货明细表'!$E:$E,"11月")+SUMIFS('代理商-进货明细表'!$I:$I,'代理商-进货明细表'!$B:$B,'代理商-产品进销存'!$B12,'代理商-进货明细表'!$F:$F,'代理商-产品进销存'!$D12,'代理商-进货明细表'!$E:$E,"12月"))/10000 -> 0 | V12: =SUM(R12:U12) -> 0 | W12: =R12-L12 -> 0 | X12: =S12-M12 -> -100 | Y12: =T12-N12 -> 0 | Z12: =U12-O12 -> 0 | AA12: =SUM(W12:Z12) -> -100
A13: A00003 | B13: 公司3 | D13: 小旋风 | E13: 500 | F13: 10000 | G13: =E13*F13/10000 -> 500 | H13: =$G13*15% -> 75 | I13: =$G13*25% -> 125 | J13: =$G13*35% -> 175 | K13: =$G13*25% -> 125 | L13: =(SUMIFS(终端客户销售统计表!$K:$K,终端客户销售统计表!$L:$L,$B13,终端客户销售统计表!$H:$H,$D13,终端客户销售统计表!$G:$G,"1月")+SUMIFS(终端客户销售统计表!$K:$K,终端客户销售统计表!$L:$L,$B13,终端客户销售统计表!$H:$H,$D13,终端客户销售统计表!$G:$G,"2月")+SUMIFS(终端客户销售统计表!$K:$K,终端客户销售统计表!$L:$L,$B13,终端客户销售统计表!$H:$H,$D13,终端客户销售统计表!$G:$G,"3月"))/10000 -> 0 | M13: =(SUMIFS(终端客户销售统计表!$K:$K,终端客户销售统计表!$L:$L,$B13,终端客户销售统计表!$H:$H,$D13,终端客户销售统计表!$G:$G,"4月")+SUMIFS(终端客户销售统计表!$K:$K,终端客户销售统计表!$L:$L,$B13,终端客户销售统计表!$H:$H,$D13,终端客户销售统计表!$G:$G,"5月")+SUMIFS(终端客户销售统计表!$K:$K,终端客户销售统计表!$L:$L,$B13,终端客户销售统计表!$H:$H,$D13,终端客户销售统计表!$G:$G,"6月"))/10000 -> 0 | N13: =(SUMIFS(终端客户销售统计表!$K:$K,终端客户销售统计表!$L:$L,$B13,终端客户销售统计表!$H:$H,$D13,终端客户销售统计表!$G:$G,"7月")+SUMIFS(终端客户销售统计表!$K:$K,终端客户销售统计表!$L:$L,$B13,终端客户销售统计表!$H:$H,$D13,终端客户销售统计表!$G:$G,"8月")+SUMIFS(终端客户销售统计表!$K:$K,终端客户销售统计表!$L:$L,$B13,终端客户销售统计表!$H:$H,$D13,终端客户销售统计表!$G:$G,"9月"))/10000 -> 100 | O13: =(SUMIFS(终端客户销售统计表!$K:$K,终端客户销售统计表!$L:$L,$B13,终端客户销售统计表!$H:$H,$D13,终端客户销售统计表!$G:$G,"10月")+SUMIFS(终端客户销售统计表!$K:$K,终端客户销售统计表!$L:$L,$B13,终端客户销售统计表!$H:$H,$D13,终端客户销售统计表!$G:$G,"11月")+SUMIFS(终端客户销售统计表!$K:$K,终端客户销售统计表!$L:$L,$B13,终端客户销售统计表!$H:$H,$D13,终端客户销售统计表!$G:$G,"12月"))/10000 -> 0 | P13: =SUM(L13:O13) -> 100 | Q13: =IFERROR(P13/G13,"") -> 0.2 | R13: =(SUMIFS('代理商-进货明细表'!$I:$I,'代理商-进货明细表'!$B:$B,'代理商-产品进销存'!$B13,'代理商-进货明细表'!$F:$F,'代理商-产品进销存'!$D13,'代理商-进货明细表'!$E:$E,"1月")+SUMIFS('代理商-进货明细表'!$I:$I,'代理商-进货明细表'!$B:$B,'代理商-产品进销存'!$B13,'代理商-进货明细表'!$F:$F,'代理商-产品进销存'!$D13,'代理商-进货明细表'!$E:$E,"2月")+SUMIFS('代理商-进货明细表'!$I:$I,'代理商-进货明细表'!$B:$B,'代理商-产品进销存'!$B13,'代理商-进货明细表'!$F:$F,'代理商-产品进销存'!$D13,'代理商-进货明细表'!$E:$E,"3月"))/10000 -> 0 | S13: =(SUMIFS('代理商-进货明细表'!$I:$I,'代理商-进货明细表'!$B:$B,'代理商-产品进销存'!$B13,'代理商-进货明细表'!$F:$F,'代理商-产品进销存'!$D13,'代理商-进货明细表'!$E:$E,"4月")+SUMIFS('代理商-进货明细表'!$I:$I,'代理商-进货明细表'!$B:$B,'代理商-产品进销存'!$B13,'代理商-进货明细表'!$F:$F,'代理商-产品进销存'!$D13,'代理商-进货明细表'!$E:$E,"5月")+SUMIFS('代理商-进货明细表'!$I:$I,'代理商-进货明细表'!$B:$B,'代理商-产品进销存'!$B13,'代理商-进货明细表'!$F:$F,'代理商-产品进销存'!$D13,'代理商-进货明细表'!$E:$E,"6月"))/10000 -> 0 | T13: =(SUMIFS('代理商-进货明细表'!$I:$I,'代理商-进货明细表'!$B:$B,'代理商-产品进销存'!$B13,'代理商-进货明细表'!$F:$F,'代理商-产品进销存'!$D13,'代理商-进货明细表'!$E:$E,"7月")+SUMIFS('代理商-进货明细表'!$I:$I,'代理商-进货明细表'!$B:$B,'代理商-产品进销存'!$B13,'代理商-进货明细表'!$F:$F,'代理商-产品进销存'!$D13,'代理商-进货明细表'!$E:$E,"8月")+SUMIFS('代理商-进货明细表'!$I:$I,'代理商-进货明细表'!$B:$B,'代理商-产品进销存'!$B13,'代理商-进货明细表'!$F:$F,'代理商-产品进销存'!$D13,'代理商-进货明细表'!$E:$E,"9月"))/10000 -> 0 | U13: =(SUMIFS('代理商-进货明细表'!$I:$I,'代理商-进货明细表'!$B:$B,'代理商-产品进销存'!$B13,'代理商-进货明细表'!$F:$F,'代理商-产品进销存'!$D13,'代理商-进货明细表'!$E:$E,"10月")+SUMIFS('代理商-进货明细表'!$I:$I,'代理商-进货明细表'!$B:$B,'代理商-产品进销存'!$B13,'代理商-进货明细表'!$F:$F,'代理商-产品进销存'!$D13,'代理商-进货明细表'!$E:$E,"11月")+SUMIFS('代理商-进货明细表'!$I:$I,'代理商-进货明细表'!$B:$B,'代理商-产品进销存'!$B13,'代理商-进货明细表'!$F:$F,'代理商-产品进销存'!$D13,'代理商-进货明细表'!$E:$E,"12月"))/10000 -> 0 | V13: =SUM(R13:U13) -> 0 | W13: =R13-L13 -> 0 | X13: =S13-M13 -> 0 | Y13: =T13-N13 -> -100 | Z13: =U13-O13 -> 0 | AA13: =SUM(W13:Z13) -> -100
A14: A00003 | B14: 公司3 | D14: OK7 | E14: 500 | F14: 10000 | G14: =E14*F14/10000 -> 500 | H14: =$G14*15% -> 75 | I14: =$G14*25% -> 125 | J14: =$G14*35% -> 175 | K14: =$G14*25% -> 125 | L14: =(SUMIFS(终端客户销售统计表!$K:$K,终端客户销售统计表!$L:$L,$B14,终端客户销售统计表!$H:$H,$D14,终端客户销售统计表!$G:$G,"1月")+SUMIFS(终端客户销售统计表!$K:$K,终端客户销售统计表!$L:$L,$B14,终端客户销售统计表!$H:$H,$D14,终端客户销售统计表!$G:$G,"2月")+SUMIFS(终端客户销售统计表!$K:$K,终端客户销售统计表!$L:$L,$B14,终端客户销售统计表!$H:$H,$D14,终端客户销售统计表!$G:$G,"3月"))/10000 -> 0 | M14: =(SUMIFS(终端客户销售统计表!$K:$K,终端客户销售统计表!$L:$L,$B14,终端客户销售统计表!$H:$H,$D14,终端客户销售统计表!$G:$G,"4月")+SUMIFS(终端客户销售统计表!$K:$K,终端客户销售统计表!$L:$L,$B14,终端客户销售统计表!$H:$H,$D14,终端客户销售统计表!$G:$G,"5月")+SUMIFS(终端客户销售统计表!$K:$K,终端客户销售统计表!$L:$L,$B14,终端客户销售统计表!$H:$H,$D14,终端客户销售统计表!$G:$G,"6月"))/10000 -> 0 | N14: =(SUMIFS(终端客户销售统计表!$K:$K,终端客户销售统计表!$L:$L,$B14,终端客户销售统计表!$H:$H,$D14,终端客户销售统计表!$G:$G,"7月")+SUMIFS(终端客户销售统计表!$K:$K,终端客户销售统计表!$L:$L,$B14,终端客户销售统计表!$H:$H,$D14,终端客户销售统计表!$G:$G,"8月")+SUMIFS(终端客户销售统计表!$K:$K,终端客户销售统计表!$L:$L,$B14,终端客户销售统计表!$H:$H,$D14,终端客户销售统计表!$G:$G,"9月"))/10000 -> 0 | O14: =(SUMIFS(终端客户销售统计表!$K:$K,终端客户销售统计表!$L:$L,$B14,终端客户销售统计表!$H:$H,$D14,终端客户销售统计表!$G:$G,"10月")+SUMIFS(终端客户销售统计表!$K:$K,终端客户销售统计表!$L:$L,$B14,终端客户销售统计表!$H:$H,$D14,终端客户销售统计表!$G:$G,"11月")+SUMIFS(终端客户销售统计表!$K:$K,终端客户销售统计表!$L:$L,$B14,终端客户销售统计表!$H:$H,$D14,终端客户销售统计表!$G:$G,"12月"))/10000 -> 100 | P14: =SUM(L14:O14) -> 100 | Q14: =IFERROR(P14/G14,"") -> 0.2 | R14: =(SUMIFS('代理商-进货明细表'!$I:$I,'代理商-进货明细表'!$B:$B,'代理商-产品进销存'!$B14,'代理商-进货明细表'!$F:$F,'代理商-产品进销存'!$D14,'代理商-进货明细表'!$E:$E,"1月")+SUMIFS('代理商-进货明细表'!$I:$I,'代理商-进货明细表'!$B:$B,'代理商-产品进销存'!$B14,'代理商-进货明细表'!$F:$F,'代理商-产品进销存'!$D14,'代理商-进货明细表'!$E:$E,"2月")+SUMIFS('代理商-进货明细表'!$I:$I,'代理商-进货明细表'!$B:$B,'代理商-产品进销存'!$B14,'代理商-进货明细表'!$F:$F,'代理商-产品进销存'!$D14,'代理商-进货明细表'!$E:$E,"3月"))/10000 -> 0 | S14: =(SUMIFS('代理商-进货明细表'!$I:$I,'代理商-进货明细表'!$B:$B,'代理商-产品进销存'!$B14,'代理商-进货明细表'!$F:$F,'代理商-产品进销存'!$D14,'代理商-进货明细表'!$E:$E,"4月")+SUMIFS('代理商-进货明细表'!$I:$I,'代理商-进货明细表'!$B:$B,'代理商-产品进销存'!$B14,'代理商-进货明细表'!$F:$F,'代理商-产品进销存'!$D14,'代理商-进货明细表'!$E:$E,"5月")+SUMIFS('代理商-进货明细表'!$I:$I,'代理商-进货明细表'!$B:$B,'代理商-产品进销存'!$B14,'代理商-进货明细表'!$F:$F,'代理商-产品进销存'!$D14,'代理商-进货明细表'!$E:$E,"6月"))/10000 -> 0 | T14: =(SUMIFS('代理商-进货明细表'!$I:$I,'代理商-进货明细表'!$B:$B,'代理商-产品进销存'!$B14,'代理商-进货明细表'!$F:$F,'代理商-产品进销存'!$D14,'代理商-进货明细表'!$E:$E,"7月")+SUMIFS('代理商-进货明细表'!$I:$I,'代理商-进货明细表'!$B:$B,'代理商-产品进销存'!$B14,'代理商-进货明细表'!$F:$F,'代理商-产品进销存'!$D14,'代理商-进货明细表'!$E:$E,"8月")+SUMIFS('代理商-进货明细表'!$I:$I,'代理商-进货明细表'!$B:$B,'代理商-产品进销存'!$B14,'代理商-进货明细表'!$F:$F,'代理商-产品进销存'!$D14,'代理商-进货明细表'!$E:$E,"9月"))/10000 -> 0 | U14: =(SUMIFS('代理商-进货明细表'!$I:$I,'代理商-进货明细表'!$B:$B,'代理商-产品进销存'!$B14,'代理商-进货明细表'!$F:$F,'代理商-产品进销存'!$D14,'代理商-进货明细表'!$E:$E,"10月")+SUMIFS('代理商-进货明细表'!$I:$I,'代理商-进货明细表'!$B:$B,'代理商-产品进销存'!$B14,'代理商-进货明细表'!$F:$F,'代理商-产品进销存'!$D14,'代理商-进货明细表'!$E:$E,"11月")+SUMIFS('代理商-进货明细表'!$I:$I,'代理商-进货明细表'!$B:$B,'代理商-产品进销存'!$B14,'代理商-进货明细表'!$F:$F,'代理商-产品进销存'!$D14,'代理商-进货明细表'!$E:$E,"12月"))/10000 -> 0 | V14: =SUM(R14:U14) -> 0 | W14: =R14-L14 -> 0 | X14: =S14-M14 -> 0 | Y14: =T14-N14 -> 0 | Z14: =U14-O14 -> -100 | AA14: =SUM(W14:Z14) -> -100
A15: A00004 | B15: 公司4 | D15: Ultra | L15: =(SUMIFS(终端客户销售统计表!$K:$K,终端客户销售统计表!$L:$L,$B15,终端客户销售统计表!$H:$H,$D15,终端客户销售统计表!$G:$G,"1月")+SUMIFS(终端客户销售统计表!$K:$K,终端客户销售统计表!$L:$L,$B15,终端客户销售统计表!$H:$H,$D15,终端客户销售统计表!$G:$G,"2月")+SUMIFS(终端客户销售统计表!$K:$K,终端客户销售统计表!$L:$L,$B15,终端客户销售统计表!$H:$H,$D15,终端客户销售统计表!$G:$G,"3月"))/10000 -> 100 | M15: =(SUMIFS(终端客户销售统计表!$K:$K,终端客户销售统计表!$L:$L,$B15,终端客户销售统计表!$H:$H,$D15,终端客户销售统计表!$G:$G,"4月")+SUMIFS(终端客户销售统计表!$K:$K,终端客户销售统计表!$L:$L,$B15,终端客户销售统计表!$H:$H,$D15,终端客户销售统计表!$G:$G,"5月")+SUMIFS(终端客户销售统计表!$K:$K,终端客户销售统计表!$L:$L,$B15,终端客户销售统计表!$H:$H,$D15,终端客户销售统计表!$G:$G,"6月"))/10000 -> 0 | N15: =(SUMIFS(终端客户销售统计表!$K:$K,终端客户销售统计表!$L:$L,$B15,终端客户销售统计表!$H:$H,$D15,终端客户销售统计表!$G:$G,"7月")+SUMIFS(终端客户销售统计表!$K:$K,终端客户销售统计表!$L:$L,$B15,终端客户销售统计表!$H:$H,$D15,终端客户销售统计表!$G:$G,"8月")+SUMIFS(终端客户销售统计表!$K:$K,终端客户销售统计表!$L:$L,$B15,终端客户销售统计表!$H:$H,$D15,终端客户销售统计表!$G:$G,"9月"))/10000 -> 0 | O15: =(SUMIFS(终端客户销售统计表!$K:$K,终端客户销售统计表!$L:$L,$B15,终端客户销售统计表!$H:$H,$D15,终端客户销售统计表!$G:$G,"10月")+SUMIFS(终端客户销售统计表!$K:$K,终端客户销售统计表!$L:$L,$B15,终端客户销售统计表!$H:$H,$D15,终端客户销售统计表!$G:$G,"11月")+SUMIFS(终端客户销售统计表!$K:$K,终端客户销售统计表!$L:$L,$B15,终端客户销售统计表!$H:$H,$D15,终端客户销售统计表!$G:$G,"12月"))/10000 -> 0 | P15: =SUM(L15:O15) -> 100 | Q15: =IFERROR(P15/G15,"") | R15: =(SUMIFS('代理商-进货明细表'!$I:$I,'代理商-进货明细表'!$B:$B,'代理商-产品进销存'!$B15,'代理商-进货明细表'!$F:$F,'代理商-产品进销存'!$D15,'代理商-进货明细表'!$E:$E,"1月")+SUMIFS('代理商-进货明细表'!$I:$I,'代理商-进货明细表'!$B:$B,'代理商-产品进销存'!$B15,'代理商-进货明细表'!$F:$F,'代理商-产品进销存'!$D15,'代理商-进货明细表'!$E:$E,"2月")+SUMIFS('代理商-进货明细表'!$I:$I,'代理商-进货明细表'!$B:$B,'代理商-产品进销存'!$B15,'代理商-进货明细表'!$F:$F,'代理商-产品进销存'!$D15,'代理商-进货明细表'!$E:$E,"3月"))/10000 -> 0 | S15: =(SUMIFS('代理商-进货明细表'!$I:$I,'代理商-进货明细表'!$B:$B,'代理商-产品进销存'!$B15,'代理商-进货明细表'!$F:$F,'代理商-产品进销存'!$D15,'代理商-进货明细表'!$E:$E,"4月")+SUMIFS('代理商-进货明细表'!$I:$I,'代理商-进货明细表'!$B:$B,'代理商-产品进销存'!$B15,'代理商-进货明细表'!$F:$F,'代理商-产品进销存'!$D15,'代理商-进货明细表'!$E:$E,"5月")+SUMIFS('代理商-进货明细表'!$I:$I,'代理商-进货明细表'!$B:$B,'代理商-产品进销存'!$B15,'代理商-进货明细表'!$F:$F,'代理商-产品进销存'!$D15,'代理商-进货明细表'!$E:$E,"6月"))/10000 -> 0 | T15: =(SUMIFS('代理商-进货明细表'!$I:$I,'代理商-进货明细表'!$B:$B,'代理商-产品进销存'!$B15,'代理商-进货明细表'!$F:$F,'代理商-产品进销存'!$D15,'代理商-进货明细表'!$E:$E,"7月")+SUMIFS('代理商-进货明细表'!$I:$I,'代理商-进货明细表'!$B:$B,'代理商-产品进销存'!$B15,'代理商-进货明细表'!$F:$F,'代理商-产品进销存'!$D15,'代理商-进货明细表'!$E:$E,"8月")+SUMIFS('代理商-进货明细表'!$I:$I,'代理商-进货明细表'!$B:$B,'代理商-产品进销存'!$B15,'代理商-进货明细表'!$F:$F,'代理商-产品进销存'!$D15,'代理商-进货明细表'!$E:$E,"9月"))/10000 -> 0 | U15: =(SUMIFS('代理商-进货明细表'!$I:$I,'代理商-进货明细表'!$B:$B,'代理商-产品进销存'!$B15,'代理商-进货明细表'!$F:$F,'代理商-产品进销存'!$D15,'代理商-进货明细表'!$E:$E,"10月")+SUMIFS('代理商-进货明细表'!$I:$I,'代理商-进货明细表'!$B:$B,'代理商-产品进销存'!$B15,'代理商-进货明细表'!$F:$F,'代理商-产品进销存'!$D15,'代理商-进货明细表'!$E:$E,"11月")+SUMIFS('代理商-进货明细表'!$I:$I,'代理商-进货明细表'!$B:$B,'代理商-产品进销存'!$B15,'代理商-进货明细表'!$F:$F,'代理商-产品进销存'!$D15,'代理商-进货明细表'!$E:$E,"12月"))/10000 -> 0 | V15: =SUM(R15:U15) -> 0 | W15: =R15-L15 -> -100 | X15: =S15-M15 -> 0 | Y15: =T15-N15 -> 0 | Z15: =U15-O15 -> 0 | AA15: =SUM(W15:Z15) -> -100
A16: A00004 | B16: 公司4 | D16: 时空之眼 | L16: =(SUMIFS(终端客户销售统计表!$K:$K,终端客户销售统计表!$L:$L,$B16,终端客户销售统计表!$H:$H,$D16,终端客户销售统计表!$G:$G,"1月")+SUMIFS(终端客户销售统计表!$K:$K,终端客户销售统计表!$L:$L,$B16,终端客户销售统计表!$H:$H,$D16,终端客户销售统计表!$G:$G,"2月")+SUMIFS(终端客户销售统计表!$K:$K,终端客户销售统计表!$L:$L,$B16,终端客户销售统计表!$H:$H,$D16,终端客户销售统计表!$G:$G,"3月"))/10000 -> 0 | M16: =(SUMIFS(终端客户销售统计表!$K:$K,终端客户销售统计表!$L:$L,$B16,终端客户销售统计表!$H:$H,$D16,终端客户销售统计表!$G:$G,"4月")+SUMIFS(终端客户销售统计表!$K:$K,终端客户销售统计表!$L:$L,$B16,终端客户销售统计表!$H:$H,$D16,终端客户销售统计表!$G:$G,"5月")+SUMIFS(终端客户销售统计表!$K:$K,终端客户销售统计表!$L:$L,$B16,终端客户销售统计表!$H:$H,$D16,终端客户销售统计表!$G:$G,"6月"))/10000 -> 100 | N16: =(SUMIFS(终端客户销售统计表!$K:$K,终端客户销售统计表!$L:$L,$B16,终端客户销售统计表!$H:$H,$D16,终端客户销售统计表!$G:$G,"7月")+SUMIFS(终端客户销售统计表!$K:$K,终端客户销售统计表!$L:$L,$B16,终端客户销售统计表!$H:$H,$D16,终端客户销售统计表!$G:$G,"8月")+SUMIFS(终端客户销售统计表!$K:$K,终端客户销售统计表!$L:$L,$B16,终端客户销售统计表!$H:$H,$D16,终端客户销售统计表!$G:$G,"9月"))/10000 -> 0 | O16: =(SUMIFS(终端客户销售统计表!$K:$K,终端客户销售统计表!$L:$L,$B16,终端客户销售统计表!$H:$H,$D16,终端客户销售统计表!$G:$G,"10月")+SUMIFS(终端客户销售统计表!$K:$K,终端客户销售统计表!$L:$L,$B16,终端客户销售统计表!$H:$H,$D16,终端客户销售统计表!$G:$G,"11月")+SUMIFS(终端客户销售统计表!$K:$K,终端客户销售统计表!$L:$L,$B16,终端客户销售统计表!$H:$H,$D16,终端客户销售统计表!$G:$G,"12月"))/10000 -> 0 | P16: =SUM(L16:O16) -> 100 | Q16: =IFERROR(P16/G16,"") | R16: =(SUMIFS('代理商-进货明细表'!$I:$I,'代理商-进货明细表'!$B:$B,'代理商-产品进销存'!$B16,'代理商-进货明细表'!$F:$F,'代理商-产品进销存'!$D16,'代理商-进货明细表'!$E:$E,"1月")+SUMIFS('代理商-进货明细表'!$I:$I,'代理商-进货明细表'!$B:$B,'代理商-产品进销存'!$B16,'代理商-进货明细表'!$F:$F,'代理商-产品进销存'!$D16,'代理商-进货明细表'!$E:$E,"2月")+SUMIFS('代理商-进货明细表'!$I:$I,'代理商-进货明细表'!$B:$B,'代理商-产品进销存'!$B16,'代理商-进货明细表'!$F:$F,'代理商-产品进销存'!$D16,'代理商-进货明细表'!$E:$E,"3月"))/10000 -> 0 | S16: =(SUMIFS('代理商-进货明细表'!$I:$I,'代理商-进货明细表'!$B:$B,'代理商-产品进销存'!$B16,'代理商-进货明细表'!$F:$F,'代理商-产品进销存'!$D16,'代理商-进货明细表'!$E:$E,"4月")+SUMIFS('代理商-进货明细表'!$I:$I,'代理商-进货明细表'!$B:$B,'代理商-产品进销存'!$B16,'代理商-进货明细表'!$F:$F,'代理商-产品进销存'!$D16,'代理商-进货明细表'!$E:$E,"5月")+SUMIFS('代理商-进货明细表'!$I:$I,'代理商-进货明细表'!$B:$B,'代理商-产品进销存'!$B16,'代理商-进货明细表'!$F:$F,'代理商-产品进销存'!$D16,'代理商-进货明细表'!$E:$E,"6月"))/10000 -> 0 | T16: =(SUMIFS('代理商-进货明细表'!$I:$I,'代理商-进货明细表'!$B:$B,'代理商-产品进销存'!$B16,'代理商-进货明细表'!$F:$F,'代理商-产品进销存'!$D16,'代理商-进货明细表'!$E:$E,"7月")+SUMIFS('代理商-进货明细表'!$I:$I,'代理商-进货明细表'!$B:$B,'代理商-产品进销存'!$B16,'代理商-进货明细表'!$F:$F,'代理商-产品进销存'!$D16,'代理商-进货明细表'!$E:$E,"8月")+SUMIFS('代理商-进货明细表'!$I:$I,'代理商-进货明细表'!$B:$B,'代理商-产品进销存'!$B16,'代理商-进货明细表'!$F:$F,'代理商-产品进销存'!$D16,'代理商-进货明细表'!$E:$E,"9月"))/10000 -> 0 | U16: =(SUMIFS('代理商-进货明细表'!$I:$I,'代理商-进货明细表'!$B:$B,'代理商-产品进销存'!$B16,'代理商-进货明细表'!$F:$F,'代理商-产品进销存'!$D16,'代理商-进货明细表'!$E:$E,"10月")+SUMIFS('代理商-进货明细表'!$I:$I,'代理商-进货明细表'!$B:$B,'代理商-产品进销存'!$B16,'代理商-进货明细表'!$F:$F,'代理商-产品进销存'!$D16,'代理商-进货明细表'!$E:$E,"11月")+SUMIFS('代理商-进货明细表'!$I:$I,'代理商-进货明细表'!$B:$B,'代理商-产品进销存'!$B16,'代理商-进货明细表'!$F:$F,'代理商-产品进销存'!$D16,'代理商-进货明细表'!$E:$E,"12月"))/10000 -> 0 | V16: =SUM(R16:U16) -> 0 | W16: =R16-L16 -> 0 | X16: =S16-M16 -> -100 | Y16: =T16-N16 -> 0 | Z16: =U16-O16 -> 0 | AA16: =SUM(W16:Z16) -> -100
A17: A00004 | B17: 公司4 | D17: 小旋风 | L17: =(SUMIFS(终端客户销售统计表!$K:$K,终端客户销售统计表!$L:$L,$B17,终端客户销售统计表!$H:$H,$D17,终端客户销售统计表!$G:$G,"1月")+SUMIFS(终端客户销售统计表!$K:$K,终端客户销售统计表!$L:$L,$B17,终端客户销售统计表!$H:$H,$D17,终端客户销售统计表!$G:$G,"2月")+SUMIFS(终端客户销售统计表!$K:$K,终端客户销售统计表!$L:$L,$B17,终端客户销售统计表!$H:$H,$D17,终端客户销售统计表!$G:$G,"3月"))/10000 -> 0 | M17: =(SUMIFS(终端客户销售统计表!$K:$K,终端客户销售统计表!$L:$L,$B17,终端客户销售统计表!$H:$H,$D17,终端客户销售统计表!$G:$G,"4月")+SUMIFS(终端客户销售统计表!$K:$K,终端客户销售统计表!$L:$L,$B17,终端客户销售统计表!$H:$H,$D17,终端客户销售统计表!$G:$G,"5月")+SUMIFS(终端客户销售统计表!$K:$K,终端客户销售统计表!$L:$L,$B17,终端客户销售统计表!$H:$H,$D17,终端客户销售统计表!$G:$G,"6月"))/10000 -> 0 | N17: =(SUMIFS(终端客户销售统计表!$K:$K,终端客户销售统计表!$L:$L,$B17,终端客户销售统计表!$H:$H,$D17,终端客户销售统计表!$G:$G,"7月")+SUMIFS(终端客户销售统计表!$K:$K,终端客户销售统计表!$L:$L,$B17,终端客户销售统计表!$H:$H,$D17,终端客户销售统计表!$G:$G,"8月")+SUMIFS(终端客户销售统计表!$K:$K,终端客户销售统计表!$L:$L,$B17,终端客户销售统计表!$H:$H,$D17,终端客户销售统计表!$G:$G,"9月"))/10000 -> 100 | O17: =(SUMIFS(终端客户销售统计表!$K:$K,终端客户销售统计表!$L:$L,$B17,终端客户销售统计表!$H:$H,$D17,终端客户销售统计表!$G:$G,"10月")+SUMIFS(终端客户销售统计表!$K:$K,终端客户销售统计表!$L:$L,$B17,终端客户销售统计表!$H:$H,$D17,终端客户销售统计表!$G:$G,"11月")+SUMIFS(终端客户销售统计表!$K:$K,终端客户销售统计表!$L:$L,$B17,终端客户销售统计表!$H:$H,$D17,终端客户销售统计表!$G:$G,"12月"))/10000 -> 0 | P17: =SUM(L17:O17) -> 100 | Q17: =IFERROR(P17/G17,"") | R17: =(SUMIFS('代理商-进货明细表'!$I:$I,'代理商-进货明细表'!$B:$B,'代理商-产品进销存'!$B17,'代理商-进货明细表'!$F:$F,'代理商-产品进销存'!$D17,'代理商-进货明细表'!$E:$E,"1月")+SUMIFS('代理商-进货明细表'!$I:$I,'代理商-进货明细表'!$B:$B,'代理商-产品进销存'!$B17,'代理商-进货明细表'!$F:$F,'代理商-产品进销存'!$D17,'代理商-进货明细表'!$E:$E,"2月")+SUMIFS('代理商-进货明细表'!$I:$I,'代理商-进货明细表'!$B:$B,'代理商-产品进销存'!$B17,'代理商-进货明细表'!$F:$F,'代理商-产品进销存'!$D17,'代理商-进货明细表'!$E:$E,"3月"))/10000 -> 0 | S17: =(SUMIFS('代理商-进货明细表'!$I:$I,'代理商-进货明细表'!$B:$B,'代理商-产品进销存'!$B17,'代理商-进货明细表'!$F:$F,'代理商-产品进销存'!$D17,'代理商-进货明细表'!$E:$E,"4月")+SUMIFS('代理商-进货明细表'!$I:$I,'代理商-进货明细表'!$B:$B,'代理商-产品进销存'!$B17,'代理商-进货明细表'!$F:$F,'代理商-产品进销存'!$D17,'代理商-进货明细表'!$E:$E,"5月")+SUMIFS('代理商-进货明细表'!$I:$I,'代理商-进货明细表'!$B:$B,'代理商-产品进销存'!$B17,'代理商-进货明细表'!$F:$F,'代理商-产品进销存'!$D17,'代理商-进货明细表'!$E:$E,"6月"))/10000 -> 0 | T17: =(SUMIFS('代理商-进货明细表'!$I:$I,'代理商-进货明细表'!$B:$B,'代理商-产品进销存'!$B17,'代理商-进货明细表'!$F:$F,'代理商-产品进销存'!$D17,'代理商-进货明细表'!$E:$E,"7月")+SUMIFS('代理商-进货明细表'!$I:$I,'代理商-进货明细表'!$B:$B,'代理商-产品进销存'!$B17,'代理商-进货明细表'!$F:$F,'代理商-产品进销存'!$D17,'代理商-进货明细表'!$E:$E,"8月")+SUMIFS('代理商-进货明细表'!$I:$I,'代理商-进货明细表'!$B:$B,'代理商-产品进销存'!$B17,'代理商-进货明细表'!$F:$F,'代理商-产品进销存'!$D17,'代理商-进货明细表'!$E:$E,"9月"))/10000 -> 0 | U17: =(SUMIFS('代理商-进货明细表'!$I:$I,'代理商-进货明细表'!$B:$B,'代理商-产品进销存'!$B17,'代理商-进货明细表'!$F:$F,'代理商-产品进销存'!$D17,'代理商-进货明细表'!$E:$E,"10月")+SUMIFS('代理商-进货明细表'!$I:$I,'代理商-进货明细表'!$B:$B,'代理商-产品进销存'!$B17,'代理商-进货明细表'!$F:$F,'代理商-产品进销存'!$D17,'代理商-进货明细表'!$E:$E,"11月")+SUMIFS('代理商-进货明细表'!$I:$I,'代理商-进货明细表'!$B:$B,'代理商-产品进销存'!$B17,'代理商-进货明细表'!$F:$F,'代理商-产品进销存'!$D17,'代理商-进货明细表'!$E:$E,"12月"))/10000 -> 0 | V17: =SUM(R17:U17) -> 0 | W17: =R17-L17 -> 0 | X17: =S17-M17 -> 0 | Y17: =T17-N17 -> -100 | Z17: =U17-O17 -> 0 | AA17: =SUM(W17:Z17) -> -100
A18: A00004 | B18: 公司4 | D18: OK7 | L18: =(SUMIFS(终端客户销售统计表!$K:$K,终端客户销售统计表!$L:$L,$B18,终端客户销售统计表!$H:$H,$D18,终端客户销售统计表!$G:$G,"1月")+SUMIFS(终端客户销售统计表!$K:$K,终端客户销售统计表!$L:$L,$B18,终端客户销售统计表!$H:$H,$D18,终端客户销售统计表!$G:$G,"2月")+SUMIFS(终端客户销售统计表!$K:$K,终端客户销售统计表!$L:$L,$B18,终端客户销售统计表!$H:$H,$D18,终端客户销售统计表!$G:$G,"3月"))/10000 -> 0 | M18: =(SUMIFS(终端客户销售统计表!$K:$K,终端客户销售统计表!$L:$L,$B18,终端客户销售统计表!$H:$H,$D18,终端客户销售统计表!$G:$G,"4月")+SUMIFS(终端客户销售统计表!$K:$K,终端客户销售统计表!$L:$L,$B18,终端客户销售统计表!$H:$H,$D18,终端客户销售统计表!$G:$G,"5月")+SUMIFS(终端客户销售统计表!$K:$K,终端客户销售统计表!$L:$L,$B18,终端客户销售统计表!$H:$H,$D18,终端客户销售统计表!$G:$G,"6月"))/10000 -> 0 | N18: =(SUMIFS(终端客户销售统计表!$K:$K,终端客户销售统计表!$L:$L,$B18,终端客户销售统计表!$H:$H,$D18,终端客户销售统计表!$G:$G,"7月")+SUMIFS(终端客户销售统计表!$K:$K,终端客户销售统计表!$L:$L,$B18,终端客户销售统计表!$H:$H,$D18,终端客户销售统计表!$G:$G,"8月")+SUMIFS(终端客户销售统计表!$K:$K,终端客户销售统计表!$L:$L,$B18,终端客户销售统计表!$H:$H,$D18,终端客户销售统计表!$G:$G,"9月"))/10000 -> 0 | O18: =(SUMIFS(终端客户销售统计表!$K:$K,终端客户销售统计表!$L:$L,$B18,终端客户销售统计表!$H:$H,$D18,终端客户销售统计表!$G:$G,"10月")+SUMIFS(终端客户销售统计表!$K:$K,终端客户销售统计表!$L:$L,$B18,终端客户销售统计表!$H:$H,$D18,终端客户销售统计表!$G:$G,"11月")+SUMIFS(终端客户销售统计表!$K:$K,终端客户销售统计表!$L:$L,$B18,终端客户销售统计表!$H:$H,$D18,终端客户销售统计表!$G:$G,"12月"))/10000 -> 100 | P18: =SUM(L18:O18) -> 100 | Q18: =IFERROR(P18/G18,"") | R18: =(SUMIFS('代理商-进货明细表'!$I:$I,'代理商-进货明细表'!$B:$B,'代理商-产品进销存'!$B18,'代理商-进货明细表'!$F:$F,'代理商-产品进销存'!$D18,'代理商-进货明细表'!$E:$E,"1月")+SUMIFS('代理商-进货明细表'!$I:$I,'代理商-进货明细表'!$B:$B,'代理商-产品进销存'!$B18,'代理商-进货明细表'!$F:$F,'代理商-产品进销存'!$D18,'代理商-进货明细表'!$E:$E,"2月")+SUMIFS('代理商-进货明细表'!$I:$I,'代理商-进货明细表'!$B:$B,'代理商-产品进销存'!$B18,'代理商-进货明细表'!$F:$F,'代理商-产品进销存'!$D18,'代理商-进货明细表'!$E:$E,"3月"))/10000 -> 0 | S18: =(SUMIFS('代理商-进货明细表'!$I:$I,'代理商-进货明细表'!$B:$B,'代理商-产品进销存'!$B18,'代理商-进货明细表'!$F:$F,'代理商-产品进销存'!$D18,'代理商-进货明细表'!$E:$E,"4月")+SUMIFS('代理商-进货明细表'!$I:$I,'代理商-进货明细表'!$B:$B,'代理商-产品进销存'!$B18,'代理商-进货明细表'!$F:$F,'代理商-产品进销存'!$D18,'代理商-进货明细表'!$E:$E,"5月")+SUMIFS('代理商-进货明细表'!$I:$I,'代理商-进货明细表'!$B:$B,'代理商-产品进销存'!$B18,'代理商-进货明细表'!$F:$F,'代理商-产品进销存'!$D18,'代理商-进货明细表'!$E:$E,"6月"))/10000 -> 0 | T18: =(SUMIFS('代理商-进货明细表'!$I:$I,'代理商-进货明细表'!$B:$B,'代理商-产品进销存'!$B18,'代理商-进货明细表'!$F:$F,'代理商-产品进销存'!$D18,'代理商-进货明细表'!$E:$E,"7月")+SUMIFS('代理商-进货明细表'!$I:$I,'代理商-进货明细表'!$B:$B,'代理商-产品进销存'!$B18,'代理商-进货明细表'!$F:$F,'代理商-产品进销存'!$D18,'代理商-进货明细表'!$E:$E,"8月")+SUMIFS('代理商-进货明细表'!$I:$I,'代理商-进货明细表'!$B:$B,'代理商-产品进销存'!$B18,'代理商-进货明细表'!$F:$F,'代理商-产品进销存'!$D18,'代理商-进货明细表'!$E:$E,"9月"))/10000 -> 0 | U18: =(SUMIFS('代理商-进货明细表'!$I:$I,'代理商-进货明细表'!$B:$B,'代理商-产品进销存'!$B18,'代理商-进货明细表'!$F:$F,'代理商-产品进销存'!$D18,'代理商-进货明细表'!$E:$E,"10月")+SUMIFS('代理商-进货明细表'!$I:$I,'代理商-进货明细表'!$B:$B,'代理商-产品进销存'!$B18,'代理商-进货明细表'!$F:$F,'代理商-产品进销存'!$D18,'代理商-进货明细表'!$E:$E,"11月")+SUMIFS('代理商-进货明细表'!$I:$I,'代理商-进货明细表'!$B:$B,'代理商-产品进销存'!$B18,'代理商-进货明细表'!$F:$F,'代理商-产品进销存'!$D18,'代理商-进货明细表'!$E:$E,"12月"))/10000 -> 0 | V18: =SUM(R18:U18) -> 0 | W18: =R18-L18 -> 0 | X18: =S18-M18 -> 0 | Y18: =T18-N18 -> 0 | Z18: =U18-O18 -> -100 | AA18: =SUM(W18:Z18) -> -100
A19: A00005 | B19: 公司5 | D19: Ultra | L19: =(SUMIFS(终端客户销售统计表!$K:$K,终端客户销售统计表!$L:$L,$B19,终端客户销售统计表!$H:$H,$D19,终端客户销售统计表!$G:$G,"1月")+SUMIFS(终端客户销售统计表!$K:$K,终端客户销售统计表!$L:$L,$B19,终端客户销售统计表!$H:$H,$D19,终端客户销售统计表!$G:$G,"2月")+SUMIFS(终端客户销售统计表!$K:$K,终端客户销售统计表!$L:$L,$B19,终端客户销售统计表!$H:$H,$D19,终端客户销售统计表!$G:$G,"3月"))/10000 -> 100 | M19: =(SUMIFS(终端客户销售统计表!$K:$K,终端客户销售统计表!$L:$L,$B19,终端客户销售统计表!$H:$H,$D19,终端客户销售统计表!$G:$G,"4月")+SUMIFS(终端客户销售统计表!$K:$K,终端客户销售统计表!$L:$L,$B19,终端客户销售统计表!$H:$H,$D19,终端客户销售统计表!$G:$G,"5月")+SUMIFS(终端客户销售统计表!$K:$K,终端客户销售统计表!$L:$L,$B19,终端客户销售统计表!$H:$H,$D19,终端客户销售统计表!$G:$G,"6月"))/10000 -> 0 | N19: =(SUMIFS(终端客户销售统计表!$K:$K,终端客户销售统计表!$L:$L,$B19,终端客户销售统计表!$H:$H,$D19,终端客户销售统计表!$G:$G,"7月")+SUMIFS(终端客户销售统计表!$K:$K,终端客户销售统计表!$L:$L,$B19,终端客户销售统计表!$H:$H,$D19,终端客户销售统计表!$G:$G,"8月")+SUMIFS(终端客户销售统计表!$K:$K,终端客户销售统计表!$L:$L,$B19,终端客户销售统计表!$H:$H,$D19,终端客户销售统计表!$G:$G,"9月"))/10000 -> 0 | O19: =(SUMIFS(终端客户销售统计表!$K:$K,终端客户销售统计表!$L:$L,$B19,终端客户销售统计表!$H:$H,$D19,终端客户销售统计表!$G:$G,"10月")+SUMIFS(终端客户销售统计表!$K:$K,终端客户销售统计表!$L:$L,$B19,终端客户销售统计表!$H:$H,$D19,终端客户销售统计表!$G:$G,"11月")+SUMIFS(终端客户销售统计表!$K:$K,终端客户销售统计表!$L:$L,$B19,终端客户销售统计表!$H:$H,$D19,终端客户销售统计表!$G:$G,"12月"))/10000 -> 0 | P19: =SUM(L19:O19) -> 100 | Q19: =IFERROR(P19/G19,"") | R19: =(SUMIFS('代理商-进货明细表'!$I:$I,'代理商-进货明细表'!$B:$B,'代理商-产品进销存'!$B19,'代理商-进货明细表'!$F:$F,'代理商-产品进销存'!$D19,'代理商-进货明细表'!$E:$E,"1月")+SUMIFS('代理商-进货明细表'!$I:$I,'代理商-进货明细表'!$B:$B,'代理商-产品进销存'!$B19,'代理商-进货明细表'!$F:$F,'代理商-产品进销存'!$D19,'代理商-进货明细表'!$E:$E,"2月")+SUMIFS('代理商-进货明细表'!$I:$I,'代理商-进货明细表'!$B:$B,'代理商-产品进销存'!$B19,'代理商-进货明细表'!$F:$F,'代理商-产品进销存'!$D19,'代理商-进货明细表'!$E:$E,"3月"))/10000 -> 0 | S19: =(SUMIFS('代理商-进货明细表'!$I:$I,'代理商-进货明细表'!$B:$B,'代理商-产品进销存'!$B19,'代理商-进货明细表'!$F:$F,'代理商-产品进销存'!$D19,'代理商-进货明细表'!$E:$E,"4月")+SUMIFS('代理商-进货明细表'!$I:$I,'代理商-进货明细表'!$B:$B,'代理商-产品进销存'!$B19,'代理商-进货明细表'!$F:$F,'代理商-产品进销存'!$D19,'代理商-进货明细表'!$E:$E,"5月")+SUMIFS('代理商-进货明细表'!$I:$I,'代理商-进货明细表'!$B:$B,'代理商-产品进销存'!$B19,'代理商-进货明细表'!$F:$F,'代理商-产品进销存'!$D19,'代理商-进货明细表'!$E:$E,"6月"))/10000 -> 0 | T19: =(SUMIFS('代理商-进货明细表'!$I:$I,'代理商-进货明细表'!$B:$B,'代理商-产品进销存'!$B19,'代理商-进货明细表'!$F:$F,'代理商-产品进销存'!$D19,'代理商-进货明细表'!$E:$E,"7月")+SUMIFS('代理商-进货明细表'!$I:$I,'代理商-进货明细表'!$B:$B,'代理商-产品进销存'!$B19,'代理商-进货明细表'!$F:$F,'代理商-产品进销存'!$D19,'代理商-进货明细表'!$E:$E,"8月")+SUMIFS('代理商-进货明细表'!$I:$I,'代理商-进货明细表'!$B:$B,'代理商-产品进销存'!$B19,'代理商-进货明细表'!$F:$F,'代理商-产品进销存'!$D19,'代理商-进货明细表'!$E:$E,"9月"))/10000 -> 0 | U19: =(SUMIFS('代理商-进货明细表'!$I:$I,'代理商-进货明细表'!$B:$B,'代理商-产品进销存'!$B19,'代理商-进货明细表'!$F:$F,'代理商-产品进销存'!$D19,'代理商-进货明细表'!$E:$E,"10月")+SUMIFS('代理商-进货明细表'!$I:$I,'代理商-进货明细表'!$B:$B,'代理商-产品进销存'!$B19,'代理商-进货明细表'!$F:$F,'代理商-产品进销存'!$D19,'代理商-进货明细表'!$E:$E,"11月")+SUMIFS('代理商-进货明细表'!$I:$I,'代理商-进货明细表'!$B:$B,'代理商-产品进销存'!$B19,'代理商-进货明细表'!$F:$F,'代理商-产品进销存'!$D19,'代理商-进货明细表'!$E:$E,"12月"))/10000 -> 0 | V19: =SUM(R19:U19) -> 0 | W19: =R19-L19 -> -100 | X19: =S19-M19 -> 0 | Y19: =T19-N19 -> 0 | Z19: =U19-O19 -> 0 | AA19: =SUM(W19:Z19) -> -100
