Workbook

Sheet 经营预测
K1: 单位：万元 | U1: 单位：万元
B2: 项目 | C2: 2024年 | D2: 2025年1-10月 | E2: 2025年 | F2: 2025年（口径调整） | G2: 2026年 | H2: 2027年 | I2: 2028年 | J2: 2029年 | K2: 2030年 | M2: 项 目 | N2: 2024年 | O2: 2025年1-10月 | P2: 2025年 | Q2: 2026年 | R2: 2027年 | S2: 2028年 | T2: 2029年 | U2: 2030年
B3: 营业收入 | C3: 77.08 | D3: 131.60918 | E3: 350 | G3: =收入预测!H8 -> 1061.9469 | H3: =收入预测!H16 -> 1951.3274 | I3: =收入预测!H24 -> 5066.3717 | J3: =收入预测!T8 -> 10049.558 | K3: =收入预测!T16 -> 20046.018 | M3: 销售商品、提供劳务收到的现金 | N3: 180.41 | O3: 195.87942 | P3: =E3*1.13 -> 395.5 | Q3: =G3*1.13 -> 1200 | R3: =H3*1.13 -> 2205 | S3: =I3*1.13 -> 5725 | T3: =J3*1.13 -> 11356 | U3: =K3*1.13 -> 22652 | V3: =SUM(N3:U3)-O3 -> 43713.91
B4: 营业成本 | C4: 39.35 | D4: 63.75483 | E4: 170.5372 | G4: =G3*(1-G31) -> 478.31858 | H4: =H3*(1-H31) -> 921.46018 | I4: =I3*(1-I31) -> 1853.9823 | J4: =J3*(1-J31) -> 3166.9027 | K4: =K3*(1-K31) -> 7297.5221 | M4: 收到的税费返还 | O4: 222.40477 | P4: =O4 -> 222.40477 | V4: =SUM(N4:U4)-O4 -> 222.40477
B5: 折旧摊销 | C5: =3.25+19.89 -> 23.14 | D5: =22.77+0.53 -> 23.3 | E5: =D5/D4*E4 -> 62.324952 | F5: 30 | G5: =E5+F5+Q13*95%/10*30% -> 105.14995 | H5: =G5+R13*95%/10*60%+130 -> 260.79995 | I5: =H5+S13*95%/10*2 -> 346.29995 | J5: =I5*1.2 -> 415.55994 | K5: =J5*1.2 -> 498.67193 | M5: 收到其他与经营活动有关的现金 | N5: 28.15 | O5: 7.314914 | P5: 8 | Q5: 10 | R5: 10 | S5: 10 | T5: 10 | U5: 10 | V5: =SUM(N5:U5)-O5 -> 86.15
B6: 人员费用 | C6: =4.3+19.46 -> 23.76 | D6: =11.21+4.16 -> 15.37 | E6: =D6/D4*E4 -> 41.113069 | F6: =费用预测!K33+费用预测!K34 -> 156.70548 | G6: =(E6+F6)*(1+10%) -> 217.6004 | H6: =G6*(1+10%) -> 239.36044 | I6: =H6*2 -> 478.72088 | J6: =I6*2 -> 957.44177 | K6: =J6*2 -> 1914.8835 | M6: 经营活动现金流入小计 | N6: =SUM(N3:N5) -> 208.56 | O6: =SUM(O3:O5) -> 425.5991 | P6: =SUM(P3:P5) -> 625.90477 | Q6: =SUM(Q3:Q5) -> 1210 | R6: =SUM(R3:R5) -> 2215 | S6: =SUM(S3:S5) -> 5735 | T6: =SUM(T3:T5) -> 11366 | U6: =SUM(U3:U5) -> 22662 | V6: =SUM(N6:U6)-O6 -> 44022.465
B7: 毛利润 | C7: =C3-C4 -> 37.73 | D7: =D3-D4 -> 67.854346 | E7: =E3-E4 -> 179.4628 | G7: =G3-G4 -> 583.62832 | H7: =H3-H4 -> 1029.8673 | I7: =I3-I4 -> 3212.3894 | J7: =J3-J4 -> 6882.6549 | K7: =K3-K4 -> 12748.496 | M7: 购买商品、接受劳务支付的现金 | N7: 49.82 | O7: 84.959986 | P7: =O7+45 -> 129.95999 | Q7: =(G4-G5-G6)*1.5 -> 233.35235 | R7: =(H4-H5-H6)*1.5 -> 631.94967 | S7: =(I4-I5-I6)*1.2 -> 1234.7538 | T7: =(J4-J5-J6)*1.2 -> 2152.6811 | U7: =(K4-K5-K6)*1.2 -> 5860.76 | V7: =SUM(N7:U7)-O7 -> 10293.277
B8: 税金及附加 | C8: 0.12 | D8: 0.157954 | E8: 1 | G8: =(Q3/1.13-Q7/1.13)*12% -> 102.65285 | H8: =(R3/1.13-R7/1.13)*12% -> 167.04959 | I8: =(S3/1.13-S7/1.13)*12% -> 476.84031 | J8: =(T3/1.13-T7/1.13)*12% -> 977.3436 | K8: =(U3/1.13-U7/1.13)*12% -> 1783.1405 | M8: 支付给职工以及为职工支付的现金 | N8: 639.63 | O8: 781.24658 | P8: =E10+E15+E20+费用预测!E83 -> 1039.7765 | Q8: =G6+G10+G15+G20 -> 1185.3755 | R8: =H6+H10+H15+H20 -> 1444.0621 | S8: =I6+I10+I15+I20 -> 2030.9344 | T8: =J6+J10+J15+J20 -> 3088.6876 | U8: =K6+K10+K15+K20 -> 4894.9705 | V8: =SUM(N8:U8)-O8 -> 14323.437
B9: 销售费用 | C9: 293.72 | D9: 616.32 | E9: =SUM(E10:E13) -> 817.31927 | G9: =E9*(1+G33) -> 980.78312 | H9: =G9*(1+H33) -> 1324.0572 | I9: =H9*(1+I33) -> 1853.6801 | J9: =I9*(1+J33) -> 2780.5201 | K9: =J9*(1+K33) -> 4170.7802 | M9: 支付的各项税费 | N9: 0.12 | O9: 0.209619 | P9: =E8 -> 1 | Q9: =(Q3/1.13*13%-Q7/1.13*13%)*1.12 -> 124.55212 | R9: =(R3/1.13*13%-R7/1.13*13%)*1.12 -> 202.68684 | S9: =(S3/1.13*13%-S7/1.13*13%)*1.12 -> 578.56624 | T9: =(T3/1.13*13%-T7/1.13*13%)*1.12 -> 1185.8436 | U9: =(U3/1.13*13%-U7/1.13*13%)*1.12 -> 2163.5438 | V9: =SUM(N9:U9)-O9 -> 4256.3126
B10: 人员费用 | C10: 167.89 | D10: 356.28 | E10: =D10+费用预测!E15 -> 509.63327 | G10: =E10*(1+$G$34) -> 560.59659 | H10: =G10*(1+$H$33) -> 756.8054 | I10: =H10*(1+$I$33) -> 1059.5276 | J10: =I10*(1+$J$33) -> 1589.2913 | K10: =J10*(1+$K$33) -> 2383.937 | M10: 支付其他与经营活动有关的现金 | N10: 265.55 | O10: 415.40128 | P10: =O10/10*13 -> 540.02167 | Q10: =G11+G16+G19+G13+G21+G23 -> 778.57962 | R10: =H11+H16+H19+H13+H21+H23 -> 947.78938 | S10: =I11+I16+I19+I13+I21+I23 -> 1190.5582 | T10: =J11+J16+J19+J13+J21+J23 -> 1585.8619 | U10: =K11+K16+K19+K13+K21+K23 -> 2158.8199 | V10: =SUM(N10:U10)-O10 -> 7467.1807
B11: 市场费用 | C11: 76.24 | D11: 183.67 | E11: =D11+25 -> 208.67 | G11: =E11*(1+$G$33) -> 250.404 | H11: =G11*(1+$H$33) -> 338.0454 | I11: =H11*(1+$I$33) -> 473.26356 | J11: =I11*(1+$J$33) -> 709.89534 | K11: =J11*(1+$K$33) -> 1064.843 | M11: 经营活动现金流出小计 | N11: =SUM(N7:N10) -> 955.12 | O11: =SUM(O7:O10) -> 1281.8175 | P11: =SUM(P7:P10) -> 1710.7582 | Q11: =SUM(Q7:Q10) -> 2321.8595 | R11: =SUM(R7:R10) -> 3226.488 | S11: =SUM(S7:S10) -> 5034.8126 | T11: =SUM(T7:T10) -> 8013.0742 | U11: =SUM(U7:U10) -> 15078.094 | V11: =SUM(N11:U11)-O11 -> 36340.207 | W11: =V6-V11-V12 -> 0
B12: 折旧摊销 | C12: =0.09+3.08 -> 3.17 | D12: =0.09+2.56 -> 2.65 | E12: =D12/10*12 -> 3.18 | G12: =E12*(1+$G$33) -> 3.816 | H12: =G12*(1+$H$33) -> 5.1516 | I12: =H12*(1+$I$33) -> 7.21224 | J12: =I12*(1+$J$33) -> 10.81836 | K12: =J12*(1+$K$33) -> 16.22754 | M12: 经营活动产生的现金流量净额 | N12: =N6-N11 -> -746.56 | O12: =O6-O11 -> -856.21837 | P12: =P6-P11 -> -1084.8534 | Q12: =Q6-Q11 -> -1111.8595 | R12: =R6-R11 -> -1011.488 | S12: =S6-S11 -> 700.18738 | T12: =T6-T11 -> 3352.9258 | U12: =U6-U11 -> 7583.9058 | V12: =SUM(N12:U12)-O12 -> 7682.2579
B13: 日常费用 | C13: =C9-C10-C11 -> 49.59 | D13: =D9-D10-D11-D12 -> 73.72 | E13: =D13/10*13 -> 95.836 | G13: =E13*(1+$G$33) -> 115.0032 | H13: =G13*(1+$H$33) -> 155.25432 | I13: =H13*(1+$I$33) -> 217.35605 | J13: =I13*(1+$J$33) -> 326.03407 | K13: =J13*(1+$K$33) -> 489.05111 | M13: 购建固定资产、无形资产和其他长期资产支付的现金 | N13: 184.38 | O13: 246.79169 | P13: =O13+45 -> 291.79169 | Q13: 450 | R13: 450 | S13: 450 | T13: 50 | U13: 50 | V13: =SUM(N13:U13)-O13 -> 1926.1717
B14: 管理费用 | C14: 182.19 | D14: 182.27 | E14: =SUM(E15:E18) -> 253.35743 | G14: =SUM(G15:G18) -> 409.91183 | H14: =SUM(H15:H18) -> 450.90301 | I14: =SUM(I15:I18) -> 495.99332 | J14: =SUM(J15:J18) -> 545.59265 | K14: =SUM(K15:K18) -> 600.15191 | M14: 投资活动现金流出小计 | N14: =SUM(N13:N13) -> 184.38 | O14: =SUM(O13:O13) -> 246.79169 | P14: =SUM(P13:P13) -> 291.79169 | Q14: =SUM(Q13:Q13) -> 450 | R14: =SUM(R13:R13) -> 450 | S14: =SUM(S13:S13) -> 450 | T14: =SUM(T13:T13) -> 50 | U14: =SUM(U13:U13) -> 50 | V14: =SUM(N14:U14)-O14 -> 1926.1717
B15: 人员费用 | C15: 76.97 | D15: 73.01 | E15: =D15+费用预测!E39 -> 122.24543 | F15: =费用预测!K31+费用预测!K35 -> 119.28969 | G15: =(E15+F15)*(1+G34) -> 265.68863 | H15: =G15*(1+H34) -> 292.25749 | I15: =H15*(1+I34) -> 321.48324 | J15: =I15*(1+J34) -> 353.63157 | K15: =J15*(1+K34) -> 388.99472 | M15: 投资活动产生的现金流量净额 | N15: =-N14 -> -184.38 | O15: =-O14 -> -246.79169 | P15: =-P14 -> -291.79169 | Q15: =-Q14 -> -450 | R15: =-R14 -> -450 | S15: =-S14 -> -450 | T15: =-T14 -> -50 | U15: =-U14 -> -50 | V15: =SUM(N15:U15)-O15 -> -1926.1717
B16: 公共费用 | C16: 33.98 | D16: 28.1 | E16: =D16/10*12 -> 33.72 | G16: =E16*(1+G34) -> 37.092 | H16: =G16*(1+H34) -> 40.8012 | I16: =H16*(1+I34) -> 44.88132 | J16: =I16*(1+J34) -> 49.369452 | K16: =J16*(1+K34) -> 54.306397 | M16: 取得借款收到的现金 | V16: =SUM(N16:U16)-O16 -> 0
B17: 折旧摊销 | C17: 8.78 | D17: 1.98 | E17: =D17/10*12 -> 2.376 | G17: =E17*(1+G34) -> 2.6136 | H17: =G17*(1+H34) -> 2.87496 | I17: =H17*(1+I34) -> 3.162456 | J17: =I17*(1+J34) -> 3.4787016 | K17: =J17*(1+K34) -> 3.8265718 | M17: 收到其他与筹资活动有关的现金 | N17: 1020 | O17: 980 | P17: =O17 -> 980 | V17: =SUM(N17:U17)-O17 -> 2000
B18: 其他费用 | C18: =C14-C15-C16-C17 -> 62.46 | D18: =D14-D15-D16-D17 -> 79.18 | E18: =D18/10*12 -> 95.016 | G18: =E18*(1+G34) -> 104.5176 | H18: =G18*(1+H34) -> 114.96936 | I18: =H18*(1+I34) -> 126.4663 | J18: =I18*(1+J34) -> 139.11293 | K18: =J18*(1+K34) -> 153.02422 | M18: 筹资活动现金流入小计 | N18: =SUM(N16:N17) -> 1020 | O18: =SUM(O16:O17) -> 980 | P18: =SUM(P16:P17) -> 980 | Q18: =SUM(Q16:Q17) -> 0 | R18: =SUM(R16:R17) -> 0 | S18: =SUM(S16:S17) -> 0 | T18: =SUM(T16:T17) -> 0 | U18: =SUM(U16:U17) -> 0 | V18: =SUM(N18:U18)-O18 -> 2000
B19: 研发费用 | C19: 596.3 | D19: 415.91644 | E19: =SUM(E20:E23) -> 541.92201 | G19: =SUM(G20:G23) -> 301.06952 | H19: =SUM(H20:H23) -> 331.17648 | I19: =SUM(I20:I23) -> 364.29412 | J19: =SUM(J20:J23) -> 400.72354 | K19: =SUM(K20:K23) -> 440.79589 | M19: 偿还债务支付的现金 | V19: =SUM(N19:U19)-O19 -> 0
B20: 人员费用 | C20: 412.31 | D20: 301.5 | E20: =D20+费用预测!E80 -> 404.62228 | F20: =-费用预测!K31-费用预测!K33-费用预测!K34-费用预测!K35 -> -275.99517 | G20: =(E20+F20)*(1+G35) -> 141.48983 | H20: =G20*(1+H35) -> 155.63881 | I20: =H20*(1+I35) -> 171.20269 | J20: =I20*(1+J35) -> 188.32296 | K20: =J20*(1+K35) -> 207.15526 | M20: 分配股利、利润或偿付利息支付的现金 | N20: 13.63 | O20: 41.427498 | P20: =O20+6*3 -> 59.427498 | Q20: 100 | R20: 140 | S20: 160 | T20: 130 | V20: =SUM(N20:U20)-O20 -> 603.0575
B21: 公共费用 | C21: 47.59 | D21: 25.87 | E21: =D21/10*12 -> 31.044 | G21: =E21*(1+G35) -> 34.1484 | H21: =G21*(1+H35) -> 37.56324 | I21: =H21*(1+I35) -> 41.319564 | J21: =I21*(1+J35) -> 45.45152 | K21: =J21*(1+K35) -> 49.996672 | M21: 支付其他与筹资活动有关的现金 | N21: =59.17+0.08 -> 59.25 | O21: 54.2388 | P21: =O21/10*12 -> 65.08656 | Q21: =P21*1.1 -> 71.595216 | R21: =Q21*1.1 -> 78.754738 | S21: =R21*1.1 -> 86.630211 | T21: =S21*1.1 -> 95.293232 | U21: =T21*1.1 -> 104.82256 | V21: =SUM(N21:U21)-O21 -> 561.43251
B22: 折旧摊销 | C22: 88.51 | D22: 57.59 | E22: =D22/10*12 -> 69.108 | F22: -30 | G22: =E22*(1+G35)+Q13*95%/10*20% -> 84.5688 | H22: =G22*(1+H35) -> 93.02568 | I22: =H22*(1+I35) -> 102.32825 | J22: =I22*(1+J35) -> 112.56107 | K22: =J22*(1+K35) -> 123.81718 | M22: 筹资活动现金流出小计 | N22: =SUM(N19:N21) -> 72.88 | O22: =SUM(O19:O21) -> 95.666298 | P22: =SUM(P19:P21) -> 124.51406 | Q22: =SUM(Q19:Q21) -> 171.59522 | R22: =SUM(R19:R21) -> 218.75474 | S22: =SUM(S19:S21) -> 246.63021 | T22: =SUM(T19:T21) -> 225.29323 | U22: =SUM(U19:U21) -> 104.82256 | V22: =SUM(N22:U22)-O22 -> 1164.49
B23: 其他费用 | C23: =C19-C20-C21-C22 -> 47.89 | D23: =D19-D20-D21-D22 -> 30.956437 | E23: =D23/10*12 -> 37.147724 | G23: =E23*(1+G35) -> 40.862497 | H23: =G23*(1+H35) -> 44.948747 | I23: =H23*(1+I35) -> 49.443621 | J23: =I23*(1+J35) -> 54.387983 | K23: =J23*(1+K35) -> 59.826782 | M23: 筹资活动产生的现金流量净额 | N23: =N18-N22 -> 947.12 | O23: =O18-O22 -> 884.3337 | P23: =P18-P22 -> 855.48594 | Q23: =Q18-Q22 -> -171.59522 | R23: =R18-R22 -> -218.75474 | S23: =S18-S22 -> -246.63021 | T23: =T18-T22 -> -225.29323 | U23: =U18-U22 -> -104.82256 | V23: =SUM(N23:U23)-O23 -> 835.50999
B24: 财务费用 | C24: 18.23 | D24: 50.984381 | E24: 86.24 | G24: =Q20 -> 100 | H24: =R20 -> 140 | I24: =S20 -> 160 | J24: =T20 -> 130 | M24: 现金及现金等价物净增加额 | N24: =N12+N15+N23 -> 16.18 | O24: =O12+O15+O23 -> -218.67636 | P24: =P12+P15+P23 -> -521.15917 | Q24: =Q12+Q15+Q23 -> -1733.4548 | R24: =R12+R15+R23 -> -1680.2428 | S24: =S12+S15+S23 -> 3.5571703 | T24: =T12+T15+T23 -> 3077.6325 | U24: =U12+U15+U23 -> 7429.0832 | V24: =SUM(N24:U24)-O24 -> 6591.5962 | W24: =V23+V15+V12-V24 -> 0
B25: 加 : 其他收益 | C25: 25.82 | D25: 6.780108 | E25: 18.86 | G25: =Q5 -> 10 | H25: =R5 -> 10 | I25: =S5 -> 10 | J25: =T5 -> 10 | K25: =U5 -> 10 | M25: 加：期初现金及现金等价物余额 | N25: 273.76 | O25: =N26 -> 289.94 | P25: =O25 -> 289.94
B26: 信用减值损失 | C26: -2.8176 | D26: -4.663351 | E26: -5 | G26: -5 | H26: =-10 -> -10 | I26: -15 | J26: -20 | K26: -25 | M26: 期末现金及现金等价物余额 | N26: =N24+N25 -> 289.94 | O26: =O24+O25 -> 71.263644 | P26: =P24+P25 -> -231.21917 | Q26: =Q24+Q25 -> -1733.4548 | R26: =R24+R25 -> -1680.2428 | S26: =S24+S25 -> 3.5571703 | T26: =T24+T25 -> 3077.6325 | U26: =U24+U25 -> 7429.0832
B27: 资产减值损失 | C27: -0.025147 | D27: 0 | R27: 借款额度 | S27: =ROUND(SUM(P26:S26),-2) -> -3600
B28: 资产处置收益 | C28: -9.217147 | D28: 0 | N28: =N3+N4+N5-N7-N8-N9-N10-N13+N17-N20-N21-N24 -> 2.2737368e-13 | O28: =O3+O4+O5-O7-O8-O9-O10-O13+O17-O20-O21-O24 -> -2.5579538e-13 | P28: =P3+P4+P5-P7-P8-P9-P10-P13+P17-P20-P21-P24 -> 0 | Q28: =Q3+Q4+Q5-Q7-Q8-Q9-Q10-Q13+Q17-Q20-Q21-Q24 -> 0 | R28: =R3+R4+R5-R7-R8-R9-R10-R13+R17-R20-R21-R24 -> 0 | S28: =S3+S4+S5-S7-S8-S9-S10-S13+S17-S20-S21-S24 -> 4.5474735e-13 | T28: =T3+T4+T5-T7-T8-T9-T10-T13+T17-T20-T21-T24 -> 0 | U28: =U3+U4+U5-U7-U8-U9-U10-U13+U17-U20-U21-U24 -> 0
B29: 营业利润 | C29: =C3-C4-C8-C9-C14-C19-C24+C25+C26+C27+C28 -> -1039.0699 | D29: =D3-D4-D8-D9-D14-D19-D24+D25+D26+D27+D28 -> -1195.6777 | E29: =E3-E4-E8-E9-E14-E19-E24+E25+E26+E27+E28 -> -1506.5159 | G29: =G3-G4-G8-G9-G14-G19-G24+G25+G26+G27+G28 -> -1305.789 | H29: =H3-H4-H8-H9-H14-H19-H24+H25+H26+H27+H28 -> -1383.319 | I29: =I3-I4-I8-I9-I14-I19-I24+I25+I26+I27+I28 -> -143.41847 | J29: =J3-J4-J8-J9-J14-J19-J24+J25+J26+J27+J28 -> 2038.4749 | K29: =K3-K4-K8-K9-K14-K19-K24+K25+K26+K27+K28 -> 5738.627 | L29: =L28+L21+L16+L11+L5 -> 0
C30: =C7-C8-C9-C14-C19-C24+C25+C26+C27+C28-C29 -> 0 | D30: =D7-D8-D9-D14-D19-D24+D25+D26+D27+D28-D29 -> 0 | E30: =E7-E8-E9-E14-E19-E24+E25+E26+E27+E28-E29 -> 0 | F30: =F7-F8-F9-F14-F19-F24+F25+F26+F27+F28-F29 -> 0 | G30: =G7-G8-G9-G14-G19-G24+G25+G26+G27+G28-G29 -> 0 | H30: =H7-H8-H9-H14-H19-H24+H25+H26+H27+H28-H29 -> 0 | I30: =I7-I8-I9-I14-I19-I24+I25+I26+I27+I28-I29 -> 0 | J30: =J7-J8-J9-J14-J19-J24+J25+J26+J27+J28-J29 -> 0 | K30: =K7-K8-K9-K14-K19-K24+K25+K26+K27+K28-K29 -> 0
B31: 毛利率 | C31: =C7/C3 -> 0.48949144 | D31: =D7/D3 -> 0.51557458 | E31: =E7/E3 -> 0.51275086 | G31: =收入预测!M8 -> 0.54958333 | H31: =收入预测!M16 -> 0.52777778 | I31: =收入预测!M24 -> 0.63406114 | J31: =收入预测!Y8 -> 0.68487143 | K31: =收入预测!Y16 -> 0.6359615
B32: 营业收入增长率 | H32: =H3/G3-1 -> 0.8375 | I32: =I3/H3-1 -> 1.5963719 | J32: =J3/I3-1 -> 0.98358079 | K32: =K3/J3-1 -> 0.99471645
B33: 销售费用增长率 | G33: 0.2 | H33: 0.35 | I33: 0.4 | J33: 0.5 | K33: 0.5
B34: 管理费用增长率 | G34: 0.1 | H34: 0.1 | I34: 0.1 | J34: 0.1 | K34: 0.1
B35: 研发费用增长率 | G35: 0.1 | H35: 0.1 | I35: 0.1 | J35: 0.1 | K35: 0.1

Sheet 收入预测
B2: 2026年 | C2: 产品名称 | D2: 产品类型 | E2: 销售数量 | F2: 销售单价（含税） | G2: 含税销售 | H2: 销售收入（不含税） | I2: 单位BOM材料费 | J2: BOM材料成本 | K2: 毛利率 | M2: 平均毛利率 | N2: 2029年 | O2: 产品名称 | P2: 产品类型 | Q2: 销售数量 | R2: 销售单价（含税） | S2: 含税销售 | T2: 销售收入（不含税） | U2: 单位BOM材料费 | V2: BOM材料成本 | W2: 毛利率 | Y2: 平均毛利率
C3: 高视高清 | D3: RGP | E3: 1000 | F3: =500/10000 -> 0.05 | G3: =E3*F3 -> 50 | H3: =+E3*F3/1.13 -> 44.247788 | I3: =0.0065 -> 0.0065 | J3: =I3*E3 -> 6.5 | K3: 0.01 | L3: =H3*(1-K3) -> 43.80531 | O3: 高视高清 | P3: RGP | Q3: 3000 | R3: =500/10000 -> 0.05 | S3: =Q3*R3 -> 150 | T3: =+Q3*R3/1.13 -> 132.74336 | U3: =0.0065 -> 0.0065 | V3: =U3*Q3 -> 19.5 | W3: 0.65 | X3: =T3*(1-W3) -> 46.460177
C4: 高视高清 | D4: 离焦镜片（副） | E4: 25000 | F4: =350/10000 -> 0.035 | G4: =E4*F4 -> 875 | H4: =+E4*F4/1.13 -> 774.33628 | I4: =0.0175/1.13 -> 0.015486726 | J4: =I4*E4 -> 387.16814 | K4: 0.75 | L4: =H4*(1-K4) -> 193.58407 | O4: 高视高清 | P4: 离焦镜片（副） | Q4: 100000 | R4: =350/10000 -> 0.035 | S4: =Q4*R4 -> 3500 | T4: =+Q4*R4/1.13 -> 3097.3451 | U4: =0.0175/1.13 -> 0.015486726 | V4: =U4*Q4 -> 1548.6726 | W4: 0.8 | X4: =T4*(1-W4) -> 619.46903
C5: 高视高清 | D5: OK镜（国内） | E5: 5000 | F5: =550/10000 -> 0.055 | G5: =E5*F5 -> 275 | H5: =+E5*F5/1.13 -> 243.36283 | I5: =0.01 -> 0.01 | J5: =I5*E5 -> 50 | K5: 0.01 | L5: =H5*(1-K5) -> 240.9292 | O5: 高视高清 | P5: OK镜（国内） | Q5: 90000 | R5: =550/10000 -> 0.055 | S5: =Q5*R5 -> 4950 | T5: =+Q5*R5/1.13 -> 4380.531 | U5: =0.01 -> 0.01 | V5: =U5*Q5 -> 900 | W5: 0.65 | X5: =T5*(1-W5) -> 1533.1858
C6: 高视高清 | D6: OK镜（国际） | F6: =700/10000 -> 0.07 | G6: =E6*F6 -> 0 | H6: =+E6*F6/1.13 -> 0 | I6: 0.01 | J6: =I6*E6 -> 0 | L6: =H6*(1-K6) -> 0 | O6: 高视高清 | P6: OK镜（国际） | Q6: 20000 | R6: =700/10000 -> 0.07 | S6: =Q6*R6 -> 1400 | T6: =+Q6*R6/1.13 -> 1238.9381 | U6: =0.01 -> 0.01 | V6: =U6*Q6 -> 200 | W6: 0.8 | X6: =T6*(1-W6) -> 247.78761
L7: =H7*(1-K7) -> 0 | O7: 高视高清 | P7: 隐形眼镜 | S7: =T7*1.13 -> 1356 | T7: 1200 | W7: 0.4 | X7: =T7*(1-W7) -> 720
C8: 总计 | G8: =SUM(G3:G7) -> 1200 | H8: =SUM(H3:H7) -> 1061.9469 | J8: =SUM(J3:J7) -> 443.66814 | K8: =J8/1.13 -> 392.62667 | L8: =SUM(L3:L7) -> 478.31858 | M8: =1-L8/H8 -> 0.54958333 | O8: 总计 | S8: =SUM(S3:S7) -> 11356 | T8: =SUM(T3:T7) -> 10049.558 | V8: =SUM(V3:V7) -> 2668.1726 | W8: =V8/1.13 -> 2361.2147 | X8: =SUM(X3:X7) -> 3166.9027 | Y8: =1-X8/T8 -> 0.68487143
B10: 2027年 | C10: 产品名称 | D10: 产品类型 | E10: 销售数量 | F10: 销售单价（含税） | G10: 含税销售 | H10: 销售收入（不含税） | I10: 单位BOM材料费 | J10: BOM材料成本 | K10: 毛利率 | M10: 平均毛利率 | N10: 2030年 | O10: 产品名称 | P10: 产品类型 | Q10: 销售数量 | R10: 销售单价（含税） | S10: 含税销售 | T10: 销售收入（不含税） | U10: 单位BOM材料费 | V10: BOM材料成本 | W10: 毛利率 | Y10: 平均毛利率
C11: 高视高清 | D11: RGP | E11: 1500 | F11: =500/10000 -> 0.05 | G11: =E11*F11 -> 75 | H11: =+E11*F11/1.13 -> 66.371681 | I11: =0.0065 -> 0.0065 | J11: =I11*E11 -> 9.75 | K11: 0.25 | L11: =H11*(1-K11) -> 49.778761 | O11: 高视高清 | P11: RGP | Q11: 5000 | R11: =500/10000 -> 0.05 | S11: =Q11*R11 -> 250 | T11: =+Q11*R11/1.13 -> 221.23894 | U11: =0.0065 -> 0.0065 | V11: =U11*Q11 -> 32.5 | W11: 0.65 | X11: =T11*(1-W11) -> 77.433628
C12: 高视高清 | D12: 离焦镜片（副） | E12: 32000 | F12: =350/10000 -> 0.035 | G12: =E12*F12 -> 1120 | H12: =+E12*F12/1.13 -> 991.15044 | I12: =0.0175/1.13 -> 0.015486726 | J12: =I12*E12 -> 495.57522 | K12: 0.75 | L12: =H12*(1-K12) -> 247.78761 | O12: 高视高清 | P12: 离焦镜片（副） | Q12: 150000 | R12: =350/10000 -> 0.035 | S12: =Q12*R12 -> 5250 | T12: =+Q12*R12/1.13 -> 4646.0177 | U12: =0.0175/1.13 -> 0.015486726 | V12: =U12*Q12 -> 2323.0088 | W12: 0.8 | X12: =T12*(1-W12) -> 929.20354
C13: 高视高清 | D13: OK镜（国内） | E13: 12000 | F13: =550/10000 -> 0.055 | G13: =E13*F13 -> 660 | H13: =+E13*F13/1.13 -> 584.0708 | I13: =0.01 -> 0.01 | J13: =I13*E13 -> 120 | K13: 0.25 | L13: =H13*(1-K13) -> 438.0531 | O13: 高视高清 | P13: OK镜（国内） | Q13: 150000 | R13: =550/10000 -> 0.055 | S13: =Q13*R13 -> 8250 | T13: =+Q13*R13/1.13 -> 7300.885 | U13: =0.01 -> 0.01 | V13: =U13*Q13 -> 1500 | W13: 0.65 | X13: =T13*(1-W13) -> 2555.3097
C14: 高视高清 | D14: OK镜（国际） | E14: 5000 | F14: =700/10000 -> 0.07 | G14: =E14*F14 -> 350 | H14: =+E14*F14/1.13 -> 309.73451 | I14: =0.01 -> 0.01 | J14: =I14*E14 -> 50 | K14: 0.4 | L14: =H14*(1-K14) -> 185.84071 | O14: 高视高清 | P14: OK镜（国际） | Q14: =Q6*2 -> 40000 | R14: =700/10000 -> 0.07 | S14: =Q14*R14 -> 2800 | T14: =+Q14*R14/1.13 -> 2477.8761 | U14: =0.01 -> 0.01 | V14: =U14*Q14 -> 400 | W14: 0.8 | X14: =T14*(1-W14) -> 495.57522
L15: =H15*(1-K15) -> 0 | O15: 高视高清 | P15: 隐形眼镜 | S15: =T15*1.13 -> 6102 | T15: 5400 | W15: 0.4 | X15: =T15*(1-W15) -> 3240
C16: 总计 | G16: =SUM(G11:G15) -> 2205 | H16: =SUM(H11:H15) -> 1951.3274 | J16: =SUM(J11:J15) -> 675.32522 | K16: =J16/1.13 -> 597.63294 | L16: =SUM(L11:L15) -> 921.46018 | M16: =1-L16/H16 -> 0.52777778 | O16: 总计 | S16: =SUM(S11:S15) -> 22652 | T16: =SUM(T11:T15) -> 20046.018 | V16: =SUM(V11:V15) -> 4255.5088 | W16: =V16/1.13 -> 3765.937 | X16: =SUM(X11:X15) -> 7297.5221 | Y16: =1-X16/T16 -> 0.6359615
B18: 2028年 | C18: 产品名称 | D18: 产品类型 | E18: 销售数量 | F18: 销售单价（含税） | G18: 含税销售 | H18: 销售收入（不含税） | I18: 单位BOM材料费 | J18: BOM材料成本 | K18: 毛利率 | M18: 平均毛利率
C19: 高视高清 | D19: RGP | E19: 2000 | F19: =500/10000 -> 0.05 | G19: =E19*F19 -> 100 | H19: =+E19*F19/1.13 -> 88.495575 | I19: =0.0065 -> 0.0065 | J19: =I19*E19 -> 13 | K19: 0.65 | L19: =H19*(1-K19) -> 30.973451
C20: 高视高清 | D20: 离焦镜片（副） | E20: 70000 | F20: =350/10000 -> 0.035 | G20: =E20*F20 -> 2450 | H20: =+E20*F20/1.13 -> 2168.1416 | I20: =0.0175/1.13 -> 0.015486726 | J20: =I20*E20 -> 1084.0708 | K20: 0.75 | L20: =H20*(1-K20) -> 542.0354
C21: 高视高清 | D21: OK镜（国内） | E21: 45000 | F21: =550/10000 -> 0.055 | G21: =E21*F21 -> 2475 | H21: =+E21*F21/1.13 -> 2190.2655 | I21: =0.01 -> 0.01 | J21: =I21*E21 -> 450 | K21: 0.5 | L21: =H21*(1-K21) -> 1095.1327
C22: 高视高清 | D22: OK镜（国际） | E22: 10000 | F22: =700/10000 -> 0.07 | G22: =E22*F22 -> 700 | H22: =+E22*F22/1.13 -> 619.46903 | I22: =0.01 -> 0.01 | J22: =I22*E22 -> 100 | K22: 0.7 | L22: =H22*(1-K22) -> 185.84071
L23: =H23*(1-K23) -> 0
C24: 总计 | G24: =SUM(G19:G23) -> 5725 | H24: =SUM(H19:H23) -> 5066.3717 | J24: =SUM(J19:J23) -> 1647.0708 | K24: =J24/1.13 -> 1457.5848 | L24: =SUM(L19:L23) -> 1853.9823 | M24: =1-L24/H24 -> 0.63406114
D27: 总金额 | E27: 年摊销金额 | F27: 一台机床24小时3班倒年可生产OK镜5W
C28: 无形资产摊销 | D28: 13000000 | E28: =D28/10 -> 1300000 | F28: 一台机床工作8小时可生产OK镜2W
C29: 工时 | D29: 6分钟
A31: 硬性接触镜（欧普） | E31: 角膜塑形镜（爱博） | I31: 人工晶状体
A32: 年销量 | B32: =B40 -> 666247 | E32: 年销量 | F32: 402854 | I32: 年销量 | J32: 1738454
A33: 直接材料 | B33: =51924350.83+8623021.41 -> 60547372 | C33: =B33/B32 -> 90.878266 | E33: 直接材料 | F33: 8232991.1 | G33: =F33/F32 -> 20.436662 | I33: 直接材料 | J33: 12649664 | K33: =J33/J32 -> 7.2763872
A34: 直接人工 | B34: 17715830 | C34: =B34/B32 -> 26.590484 | E34: 直接人工 | F34: 10687786 | G34: =F34/F32 -> 26.530172 | I34: 直接人工 | J34: 18227674 | K34: =J34/J32 -> 10.48499
A35: 制造费用 | B35: 9687902.6 | C35: =B35/B32 -> 14.541007 | E35: 制造费用 | F35: 14925787 | G35: =F35/F32 -> 37.050116 | I35: 制造费用 | J35: 32832420 | K35: =J35/J32 -> 18.885987
A36: 运费 | B36: 1156975.8 | C36: =B36/B32 -> 1.7365568 | E36: 成本合计 | F36: =SUM(F33:F35) -> 33846564 | G36: =SUM(G33:G35) -> 84.016949 | I36: 成本合计 | J36: =SUM(J33:J35) -> 63709758 | K36: =SUM(K33:K35) -> 36.647365
A37: 成本合计 | B37: =SUM(B33:B36) -> 89108081 | C37: =SUM(C33:C36) -> 133.74631
A39: 营业成本 | B39: 89108081 | E39: 营业成本 | F39: 33846564 | I39: 营业成本 | J39: 63709758
A40: 销售量 | B40: 666247 | E40: 销售量 | F40: 402854 | I40: 销售量 | J40: 1738454
A41: 单位成本 | B41: =B39/B40 -> 133.74631 | E41: 单位成本 | F41: =F39/F40 -> 84.016949 | I41: 单位成本 | J41: =J39/J40 -> 36.647365
A42: 毛利率 | B42: 0.8831 | E42: 毛利率 | F42: 0.8568 | I42: 毛利率 | J42: 0.8916
A43: 收入金额 | B43: =B41/(1-B42) -> 1144.1088 | E43: 收入金额 | F43: =F41/(1-F42) -> 586.71054 | I43: 收入金额 | J43: =J41/(1-J42) -> 338.07532
E46: 隐形眼镜 | I46: 其他手术产品
E47: 年销量 | F47: 214121431 | I47: 年销量
E48: 直接材料 | F48: 1.7496986e+08 | G48: =F48/F47 -> 0.8171525 | I48: 直接材料 | J48: 11470485
E49: 直接人工 | F49: 52037829 | G49: =F49/F47 -> 0.24302952 | I49: 直接人工 | J49: 3363536
...

Sheet 费用预测
B2: 部门名称 | C2: 本期借方
B3: 【部门：高视高清-总经办】 | C3: 12000 | D3: =C3/10000 -> 1.2 | E3: =D3*3 -> 3.6 | H3: 科目名称 | I3: 本期借方 | J3: 借方累计
B4: 【部门：高视高清-销售部】 | C4: 169800 | D4: =C4/10000 -> 16.98 | E4: =D4*3 -> 50.94 | H4: 66021001\管理费用\水电物业费\物业费 | I4: 7752.83 | J4: 77528.3
B5: 【部门：高视高清-市场部】 | C5: 83700 | D5: =C5/10000 -> 8.37 | E5: =D5*3 -> 25.11 | H5: 66021002\管理费用\水电物业费\水费 | I5: 421.81 | J5: 2649.16
B6: 【部门：高视高清-总经办】 | C6: 8640 | D6: =C6/10000 -> 0.864 | E6: =D6/0.4*0.5 -> 1.08 | H6: 66021003\管理费用\水电物业费\电费 | I6: 2376.18 | J6: 17315.7
B7: 【部门：高视高清-销售部】 | C7: 200718 | D7: =C7/10000 -> 20.0718 | E7: =D7/0.4*0.5 -> 25.08975 | H7: 660211\管理费用\折旧 | I7: 1890.49 | J7: 19635.16
B8: 【部门：高视高清-市场部】 | C8: 191584.08 | D8: =C8/10000 -> 19.158408 | E8: =D8/0.4*0.5 -> 23.94801 | H8: 660212\管理费用\摊销费 | I8: 13.09 | J8: 130.9
B9: 【部门：高视高清-总经办】 | C9: 2700 | D9: =C9/10000 -> 0.27 | E9: =D9*3 -> 0.81 | H9: 660230\管理费用\使用权资产折旧 | I9: 16370.16 | J9: 163701.6
B10: 【部门：高视高清-销售部】 | C10: 33528.24 | D10: =C10/10000 -> 3.352824 | E10: =D10*3 -> 10.058472
B11: 【部门：高视高清-市场部】 | C11: 12714.12 | D11: =C11/10000 -> 1.271412 | E11: =D11*3 -> 3.814236 | H11: 科目名称
B12: 【部门：高视高清-总经办】 | C12: 1440 | D12: =C12/10000 -> 0.144 | E12: =D12*3 -> 0.432 | H12: 660217\管理费用\车辆费 | J12: 66371.68 | K12: =J12/10000 -> 6.637168
B13: 【部门：高视高清-销售部】 | C13: 20148 | D13: =C13/10000 -> 2.0148 | E13: =D13*3 -> 6.0444 | H13: 660232\管理费用\综合支持服务费 | I13: 143679.25 | J13: =I13*2 -> 287358.5 | K13: =J13/10000 -> 28.73585
B14: 【部门：高视高清-市场部】 | C14: 8088 | D14: =C14/10000 -> 0.8088 | E14: =D14*3 -> 2.4264 | H14: 660219\管理费用\咨询服务费 | J14: 41367.73 | K14: =J14/10000 -> 4.136773
B15: 销售费用合计 | E15: =SUM(E3:E14) -> 153.35327 | K15: =SUM(K12:K14) -> 39.509791
H16: 5301010107\研发支出\费用化支出\直接投入\使用权资产折旧 | I16: 23120.05 | J16: 230300.5
B17: 【部门：高视高清-总经办】 | C17: 28017 | D17: =C17/10000 -> 2.8017 | E17: =D17*3 -> 8.4051 | H17: 53010103\研发支出\费用化支出\折旧费用 | I17: 47223.12 | J17: 561329.71
B18: 【部门：高视高清-研发部】 | C18: 4398.83 | D18: =C18/10000 -> 0.439883 | E18: =D18*3 -> 1.319649 | H18: 53010106\研发支出\费用化支出\无形资产摊销 | I18: 1188.99 | J18: 14565.1
B19: 【部门：高视高清-生产部】 | C19: 9230.27 | D19: =C19/10000 -> 0.923027 | E19: =D19*3 -> 2.769081
B20: 【部门：高视高清-采购部】 | C20: 8848.57 | D20: =C20/10000 -> 0.884857 | E20: =D20*3 -> 2.654571
B21: 【部门：高视高清-质量管理部】 | C21: 15056.4 | D21: =C21/10000 -> 1.50564 | E21: =D21*3 -> 4.51692
B22: 【部门：高视高清-注册部】 | C22: 11751.3 | D22: =C22/10000 -> 1.17513 | E22: =D22*3 -> 3.52539
B23: 【部门：高视高清-总经办】 | C23: 105444 | D23: =C23/10000 -> 10.5444 | E23: =D23/0.4*0.5 -> 13.1805
B24: 【部门：高视高清-研发部】 | C24: 35640 | D24: =C24/10000 -> 3.564 | E24: =D24/0.4*0.5 -> 4.455
B25: 【部门：高视高清-采购部】 | C25: 6050.3 | D25: =C25/10000 -> 0.60503 | E25: =D25/0.4*0.5 -> 0.7562875 | G25: 27-10010033 | H25: 时空之眼ultra毛坯片 | K25: 片 | L25: 2 | M25: 15.4867 | N25: =L25*M25 -> 30.9734
B26: 【部门：高视高清-质量管理部】 | C26: 4716.98 | D26: =C26/10000 -> 0.471698 | E26: =D26/0.4*0.5 -> 0.5896225 | G26: 27-20050003 | H26: Ultra离焦镜片包装盒 | I26: 200×10.7×60mm | K26: 个 | L26: 1 | M26: 6.3028 | N26: =L26*M26 -> 6.3028
B27: 【部门：高视高清-总经办】 | C27: 3465.89 | D27: =C27/10000 -> 0.346589 | E27: =D27*3 -> 1.039767 | H27: 加工费 | N27: 61.95
B28: 【部门：高视高清-研发部】 | C28: 876.15 | D28: =C28/10000 -> 0.087615 | E28: =D28*3 -> 0.262845 | M28: 合计 | N28: =SUM(N25:N27) -> 99.2262
B29: 【部门：高视高清-生产部】 | C29: 1978.88 | D29: =C29/10000 -> 0.197888 | E29: =D29*3 -> 0.593664
B30: 【部门：高视高清-采购部】 | C30: 3150 | D30: =C30/10000 -> 0.315 | E30: =D30*3 -> 0.945 | G30: 人员费用口径调整 | H30: 部门 | I30: 1-10月发生 | J30: 11-12月预测 | K30: 合计
B31: 【部门：高视高清-质量管理部】 | C31: 3292.62 | D31: =C31/10000 -> 0.329262 | E31: =D31*3 -> 0.987786 | G31: 研发费用 | H31: 【部门：高视高清-总经办】 | I31: 36.25 | J31: =SUMIF(B40:B79,H31,E40:E79) -> 16.248161 | K31: =SUM(I31:J31) -> 52.49816
B32: 【部门：高视高清-注册部】 | C32: 1890.49 | D32: =C32/10000 -> 0.189049 | E32: =D32*3 -> 0.567147 | G32: 研发费用 | H32: 【部门：高视高清-研发部】 | I32: 88.13 | J32: =SUMIF(B41:B80,H32,E41:E80) -> 33.597115 | K32: =SUM(I32:J32) -> 121.72712
B33: 【部门：高视高清-总经办】 | C33: 2567.4 | D33: =C33/10000 -> 0.25674 | E33: =D33*3 -> 0.77022 | G33: 研发费用 | H33: 【部门：高视高清-生产部】 | I33: 34.5 | J33: =SUMIF(B42:B81,H33,E42:E81) -> 10.474607 | K33: =SUM(I33:J33) -> 44.974607
B34: 【部门：高视高清-研发部】 | C34: 467.28 | D34: =C34/10000 -> 0.046728 | E34: =D34*3 -> 0.140184 | G34: 研发费用 | H34: 【部门：高视高清-质量管理部】 | I34: 84.51 | J34: =SUMIF(B43:B82,H34,E43:E82) -> 27.220871 | K34: =SUM(I34:J34) -> 111.73087
B35: 【部门：高视高清-生产部】 | C35: 1055.4 | D35: =C35/10000 -> 0.10554 | E35: =D35*3 -> 0.31662 | G35: 研发费用 | H35: 【部门：高视高清-注册部】 | I35: 51.21 | J35: =SUMIF(B44:B83,H35,E44:E83) -> 15.58153 | K35: =SUM(I35:J35) -> 66.79153
B36: 【部门：高视高清-采购部】 | C36: 1680 | D36: =C36/10000 -> 0.168 | E36: =D36*3 -> 0.504
B37: 【部门：高视高清-质量管理部】 | C37: 1722.33 | D37: =C37/10000 -> 0.172233 | E37: =D37*3 -> 0.516699
B38: 【部门：高视高清-注册部】 | C38: 1397.92 | D38: =C38/10000 -> 0.139792 | E38: =D38*3 -> 0.419376
B39: 管理费用合计 | E39: =SUM(E17:E38) -> 49.235429
B40: 【部门：高视高清-总经办】 | C40: 22923 | D40: =C40/10000 -> 2.2923 | E40: =D40*3 -> 6.8769
B41: 【部门：高视高清-研发部】 | C41: 62763.93 | D41: =C41/10000 -> 6.276393 | E41: =D41*3 -> 18.829179
...
