Workbook

Sheet 基线
K1: 视力眼压 | N1: 散瞳验光 | T1: 对比敏感度
A2: id | B2: 到诊时间 | C2: 就诊门店 | D2: 姓名 | E2: 性别 | F2: 出生日期 | G2: 患者编号 | H2: 组别 | I2: 标签 | J2: 眼别 | K2: 裸眼远视力 | L2: 戴镜远视力 | M2: 裸眼近视力 | N2: 散瞳验光球镜 | O2: 散瞳验光柱镜 | P2: 散瞳验光轴位 | Q2: 散瞳验光等效球镜 | R2: 主视眼 | S2: 基线眼轴 | T2: A-3CPD | U2: B-6CPD | V2: C-12CPD | W2: D-18CPD
A3: ba483a9b-49d1-4937-abe3-c769465e9da1 | B3: 45577.007 | C3: 石家庄人民眼科 | D3: 张茗尘 | E3: 女 | F3: 41695 | G3: SJZ-GS-001 | H3: B | I3: 取镜 | J3: 右眼 | K3: 0.6 | L3: 1 | M3: 1 | N3: -0.5 | O3: -0.75 | P3: 170 | Q3: =N3+0.5*O3 -> -0.875 | R3: 右眼 | S3: 23.68 | T3: 170 | U3: 170 | V3: 100 | W3: 6
A4: ba483a9b-49d1-4937-abe3-c769465e9da1 | B4: 45577.007 | C4: 石家庄人民眼科 | H4: B | J4: 左眼 | K4: 0.5 | L4: 1 | M4: 1 | N4: -1.25 | O4: -0.75 | P4: 180 | Q4: =N4+0.5*O4 -> -1.625 | S4: 23.8 | T4: 170 | U4: 120 | V4: 60 | W4: 6
A5: f80c3992-759e-4c62-a732-cfb7922ce1e1 | B5: 45558.006 | C5: 石家庄人民眼科 | D5: 康安迪 | E5: 男 | F5: 42452 | G5: SJZ-GS-002 | H5: D | I5: 取镜 | J5: 右眼 | K5: 0.4 | L5: 1 | M5: 1 | N5: -0.75 | O5: -0.5 | P5: 25 | Q5: =N5+0.5*O5 -> -1 | R5: 右眼 | S5: 23.27 | T5: 170 | U5: 170 | V5: 100 | W5: 6
A6: f80c3992-759e-4c62-a732-cfb7922ce1e1 | B6: 45558.006 | C6: 石家庄人民眼科 | H6: D | J6: 左眼 | K6: 0.3 | L6: 1 | M6: 1 | N6: -1.5 | O6: 0 | P6: 0 | Q6: =N6+0.5*O6 -> -1.5 | S6: 23.61 | T6: 170 | U6: 170 | V6: 80 | W6: 24
A7: 6348836d-229d-45ab-a04a-396b558f46f0 | B7: 45570.007 | C7: 石家庄人民眼科 | D7: 李参炜 | E7: 男 | F7: 41383 | G7: SJZ-GS-003 | H7: B | I7: 取镜 | J7: 右眼 | K7: 0.5 | L7: 1 | M7: 1 | N7: -3.25 | O7: -0.75 | P7: 160 | Q7: =N7+0.5*O7 -> -3.625 | R7: 右眼 | S7: 24.57 | T7: 170 | U7: 170 | V7: 60 | W7: 15
A8: 6348836d-229d-45ab-a04a-396b558f46f0 | B8: 45570.007 | C8: 石家庄人民眼科 | H8: B | J8: 左眼 | K8: 0.5 | L8: 1 | M8: 1 | N8: -3.5 | O8: -0.75 | P8: 10 | Q8: =N8+0.5*O8 -> -3.875 | S8: 24.69 | T8: 170 | U8: 170 | V8: 60 | W8: 6
B9: 45604 | C9: 石家庄人民眼科 | D9: 王锦天 | E9: 男 | F9: 41579 | G9: SJZ-GS-004 | H9: A | I9: 取镜 | J9: 右眼 | K9: 0.2 | L9: 1 | M9: 1 | N9: -2.5 | O9: -0.5 | P9: 5 | Q9: =N9+0.5*O9 -> -2.75 | R9: 右眼 | S9: 23.64 | T9: 170 | U9: 120 | V9: 80 | W9: 6
C10: 石家庄人民眼科 | H10: A | J10: 左眼 | K10: 0.2 | L10: 1 | M10: 1 | N10: -2.75 | O10: -0.75 | P10: 150 | Q10: =N10+0.5*O10 -> -3.125 | S10: 23.76 | T10: 170 | U10: 170 | V10: 120 | W10: 24
B11: 45604 | C11: 石家庄人民眼科 | D11: 徐乐心 | E11: 男 | F11: 41504 | G11: SJZ-GS-005 | H11: C | I11: 取镜 | J11: 右眼 | K11: 0.15 | L11: 1 | M11: 1 | N11: -2.5 | O11: -0.75 | P11: 165 | Q11: =N11+0.5*O11 -> -2.875 | R11: 左眼 | S11: 25.29 | T11: 170 | U11: 170 | V11: 80 | W11: 24
C12: 石家庄人民眼科 | H12: C | J12: 左眼 | K12: 0.25 | L12: 1 | M12: 1 | N12: -2.75 | Q12: =N12+0.5*O12 -> -2.75 | S12: 25.48 | T12: 170 | U12: 170 | V12: 80 | W12: 6
B13: 45604 | C13: 石家庄人民眼科 | D13: 徐乐成 | E13: 男 | F13: 41504 | G13: SJZ-GS-006 | H13: A | I13: 取镜 | J13: 右眼 | K13: 0.2 | L13: 1 | M13: 1 | N13: -3 | O13: -0.75 | P13: 170 | Q13: =N13+0.5*O13 -> -3.375 | R13: 右眼 | S13: 25.43 | T13: 170 | U13: 170 | V13: 100 | W13: 24
C14: 石家庄人民眼科 | H14: A | J14: 左眼 | K14: 0.2 | L14: 1 | M14: 1 | N14: -2.75 | O14: -0.5 | P14: 5 | Q14: =N14+0.5*O14 -> -3 | S14: 25.24 | T14: 170 | U14: 170 | V14: 80 | W14: 6
B15: 45984 | C15: 石家庄人民眼科 | D15: 张楚尧 | E15: 男 | F15: 41966 | G15: SJZ-GS-007 | H15: D | I15: 取镜 | J15: 右眼 | K15: 0.3 | L15: 1 | M15: 1 | N15: -2 | O15: 0 | P15: 0 | Q15: =N15+0.5*O15 -> -2 | R15: 右眼 | S15: 24.92 | T15: 170 | U15: 170 | V15: 45 | W15: 4
C16: 石家庄人民眼科 | H16: D | J16: 左眼 | K16: 0.3 | L16: 1 | M16: 1 | N16: -2 | O16: -0.5 | P16: 155 | Q16: =N16+0.5*O16 -> -2.25 | S16: 25.2 | T16: 170 | U16: 170 | V16: 45 | W16: 6
B17: 45619 | C17: 石家庄人民眼科 | D17: 张海冰 | E17: 男 | F17: 41306 | G17: SJZ-GS-008 | H17: D | I17: 取镜 | J17: 右眼 | K17: 0.8 | L17: 1 | M17: 1 | N17: -0.5 | O17: -1.25 | P17: 170 | Q17: =N17+0.5*O17 -> -1.125 | R17: 右眼 | S17: 23.42 | T17: 170 | U17: 170 | V17: 80 | W17: 6
C18: 石家庄人民眼科 | H18: D | J18: 左眼 | K18: 0.8 | L18: 1 | M18: 1 | N18: -0.25 | O18: -1.25 | P18: 5 | Q18: =N18+0.5*O18 -> -0.875 | S18: 23.21 | T18: 170 | U18: 170 | V18: 60 | W18: 4
B19: 45634 | C19: 石家庄人民眼科 | D19: 李文晴 | E19: 女 | F19: 42299 | G19: SJZ-GS-009 | H19: C | I19: 取镜 | J19: 右眼 | K19: 0.5 | L19: 1 | M19: 1 | N19: -1.25 | O19: -0.25 | P19: 170 | Q19: =N19+0.5*O19 -> -1.375 | R19: 右眼 | S19: 24.03 | T19: 170 | U19: 170 | V19: 60 | W19: 6
C20: 石家庄人民眼科 | H20: C | J20: 左眼 | K20: 0.6 | L20: 1 | M20: 1 | N20: -0.75 | O20: -0.25 | P20: 165 | Q20: =N20+0.5*O20 -> -0.875 | S20: 23.99 | T20: 170 | U20: 170 | V20: 45 | W20: 6
B21: 45626 | C21: 石家庄人民眼科 | D21: 王可妍 | E21: 女 | F21: 40620 | G21: SJZ-GS-010 | H21: D | I21: 取镜 | J21: 右眼 | K21: 0.12 | L21: 1 | M21: 1 | N21: -3 | O21: -0.5 | P21: 170 | Q21: =N21+0.5*O21 -> -3.25 | R21: 右眼 | S21: 25.34 | T21: 170 | U21: 170 | V21: 60 | W21: 24
C22: 石家庄人民眼科 | H22: D | J22: 左眼 | K22: 0.12 | L22: 1 | M22: 1 | N22: -3 | O22: -0.5 | P22: 175 | Q22: =N22+0.5*O22 -> -3.25 | S22: 25.12 | T22: 170 | U22: 170 | V22: 80 | W22: 6
B23: 45626 | C23: 石家庄人民眼科 | D23: 檀沐析 | E23: 男 | F23: 42553 | G23: SJZ-GS-011 | H23: D | I23: 取镜 | J23: 右眼 | K23: 0.6 | L23: 1 | M23: 1 | N23: -1.5 | O23: -1.5 | P23: 180 | Q23: =N23+0.5*O23 -> -2.25 | R23: 右眼 | S23: 24.6 | T23: 170 | U23: 170 | V23: 80 | W23: 6
C24: 石家庄人民眼科 | H24: D | J24: 左眼 | K24: 0.4 | L24: 1 | M24: 1 | N24: -1.5 | O24: -1.5 | P24: 5 | Q24: =N24+0.5*O24 -> -2.25 | S24: 24.75 | T24: 170 | U24: 170 | V24: 80 | W24: 6
B25: 45626 | C25: 石家庄人民眼科 | D25: 李昭旭 | E25: 男 | F25: 42755 | G25: SJZ-GS-012 | H25: B | I25: 取镜 | J25: 右眼 | K25: 0.5 | L25: 1 | M25: 1 | N25: -1.75 | O25: -0.25 | P25: 175 | Q25: =N25+0.5*O25 -> -1.875 | R25: 左眼 | S25: 24.09 | T25: 170 | U25: 170 | V25: 60 | W25: 8
C26: 石家庄人民眼科 | H26: B | J26: 左眼 | K26: 0.5 | L26: 1 | M26: 1 | N26: -1.75 | O26: -0.5 | P26: 165 | Q26: =N26+0.5*O26 -> -2 | S26: 24.24 | T26: 170 | U26: 170 | V26: 60 | W26: 6
B27: 45647 | C27: 石家庄人民眼科 | D27: 温心语 | E27: 女 | F27: 43135 | G27: SJZ-GS-013 | H27: B | I27: 取镜 | J27: 右眼 | K27: 0.6 | L27: 1 | M27: 1 | N27: -1 | Q27: =N27+0.5*O27 -> -1 | R27: 右眼 | S27: 23.24 | T27: 170 | U27: 170 | V27: 80 | W27: 6
C28: 石家庄人民眼科 | H28: B | J28: 左眼 | K28: 0.6 | L28: 1 | M28: 1 | N28: -0.5 | O28: -0.5 | P28: 180 | Q28: =N28+0.5*O28 -> -0.75 | S28: 23.22 | T28: 170 | U28: 170 | V28: 80 | W28: 6
B29: 45638 | C29: 石家庄人民眼科 | D29: 刘梓萌 | E29: 女 | F29: 42825 | G29: SJZ-GS-014 | H29: D | I29: 取镜 | J29: 右眼 | K29: 0.5 | L29: 1 | M29: 1 | N29: -0.5 | O29: -0.5 | P29: 175 | Q29: =N29+0.5*O29 -> -0.75 | R29: 右眼 | S29: 24.79 | T29: 170 | U29: 170 | V29: 80 | W29: 6
C30: 石家庄人民眼科 | H30: D | J30: 左眼 | K30: 0.6 | L30: 1 | M30: 1 | N30: -0.5 | O30: -0.75 | P30: 170 | Q30: =N30+0.5*O30 -> -0.875 | S30: 24.73 | T30: 170 | U30: 170 | V30: 60 | W30: 4
B31: 45626 | C31: 石家庄人民眼科 | D31: 秦丞远 | E31: 男 | F31: 42004 | G31: SJZ-GS-015 | H31: A | I31: 取镜 | J31: 右眼 | K31: 0.4 | L31: 1 | M31: 1 | N31: -1.75 | O31: -0.25 | P31: 150 | Q31: =N31+0.5*O31 -> -1.875 | R31: 右眼 | S31: 25.03 | T31: 170 | U31: 170 | V31: 80 | W31: 24
C32: 石家庄人民眼科 | H32: A | J32: 左眼 | K32: 0.4 | L32: 1 | M32: 1 | N32: -2.5 | O32: -0.75 | P32: 165 | Q32: =N32+0.5*O32 -> -2.875 | S32: 25.41 | T32: 170 | U32: 170 | V32: 20 | W32: 65
B33: 45635 | C33: 石家庄人民眼科 | D33: 李诗涵 | E33: 女 | F33: 42616 | G33: SJZ-GS-016 | H33: C | I33: 取镜 | J33: 右眼 | K33: 0.4 | L33: 1 | M33: 1 | Q33: =N33+0.5*O33 -> 0 | R33: 右眼 | S33: 23.72 | T33: 170 | U33: 120 | V33: 0 | W33: 0
C34: 石家庄人民眼科 | H34: C | J34: 左眼 | K34: 0.4 | L34: 1 | M34: 1 | Q34: =N34+0.5*O34 -> 0 | S34: 23.89 | T34: 170 | U34: 170 | V34: 120 | W34: 0
B35: 45643 | C35: 石家庄人民眼科 | D35: 崔赵兮 | E35: 女 | F35: 42811 | G35: SJZ-GS-017 | H35: D | I35: 取镜 | J35: 右眼 | K35: 0.4 | L35: 1 | M35: 1 | N35: -0.75 | O35: -0.25 | P35: 170 | Q35: =N35+0.5*O35 -> -0.875 | R35: 右眼 | S35: 23.68 | T35: 170 | U35: 170 | V35: 45 | W35: 4
C36: 石家庄人民眼科 | H36: D | J36: 左眼 | K36: 0.15 | L36: 1 | M36: 1 | N36: -1.25 | Q36: =N36+0.5*O36 -> -1.25 | S36: 23.89 | T36: 170 | U36: 170 | V36: 80 | W36: 6
B37: 45647 | C37: 石家庄人民眼科 | D37: 刘镐泽 | E37: 男 | F37: 41944 | G37: SJZ-GS-018 | H37: D | I37: 取镜 | J37: 右眼 | K37: 0.2 | L37: 1 | M37: 1 | N37: -2.75 | O37: -0.75 | P37: 175 | Q37: =N37+0.5*O37 -> -3.125 | R37: 右眼 | S37: 25.32 | T37: 170 | U37: 100 | V37: 60 | W37: 24
C38: 石家庄人民眼科 | H38: D | J38: 左眼 | K38: 0.3 | L38: 1 | M38: 1 | N38: -1.75 | O38: -1.5 | P38: 170 | Q38: =N38+0.5*O38 -> -2.5 | S38: 25.03 | T38: 170 | U38: 170 | V38: 30 | W38: 6
B39: 45647 | C39: 石家庄人民眼科 | D39: 何昊轩 | E39: 男 | F39: 40870 | G39: SJZ-GS-019 | H39: A | I39: 取镜 | J39: 右眼 | K39: 0.3 | L39: 1 | M39: 1 | N39: -2 | O39: -0.75 | P39: 170 | Q39: =N39+0.5*O39 -> -2.375 | R39: 右眼 | S39: 24.97 | T39: 170 | U39: 170 | V39: 45 | W39: 6
C40: 石家庄人民眼科 | H40: A | J40: 左眼 | K40: 0.5 | L40: 1 | M40: 1 | N40: -0.75 | O40: -1 | P40: 165 | Q40: =N40+0.5*O40 -> -1.25 | S40: 24.47 | T40: 170 | U40: 170 | V40: 60 | W40: 6
...

Sheet 六个月复查 
H1: 视力眼压 | K1: 散瞳验光 | S1: 对比敏感度
A2: 就诊门店 | B2: 姓名 | C2: 性别 | D2: 出生日期 | E2: 患者编号 | F2: 组别 | G2: 眼别 | H2: 戴镜远视力 | I2: 戴镜近视力 | J2: 基线散瞳验光等效球镜 | K2: 散瞳验光球镜 | L2: 散瞳验光柱镜 | M2: 散瞳验光轴位 | N2: 6个月散瞳验光等效球镜 | O2: 散瞳验光等效球镜变化 | P2: 基线眼轴 | Q2: 6个月眼轴 | R2: 6个月眼轴变化量 | S2: A-3CPD | T2: B-6CPD | U2: C-12CPD | V2: D-18CPD
A3: =[1]取镜!C3 -> 石家庄人民眼科 | B3: =[1]取镜!D3 -> 张茗尘 | C3: =[1]取镜!E3 -> 女 | D3: =[1]取镜!F3 -> 41695 | E3: SJZ-GS-001 | F3: B | G3: 右眼 | H3: 1 | I3: 1 | J3: -0.875 | K3: -0.5 | L3: -1.5 | M3: 170 | N3: -1.25 | O3: =N3-J3 -> -0.375 | P3: 23.68 | Q3: 23.77 | R3: 0.09 | S3: 170 | T3: 170 | U3: 15 | V3: 4
A4: =[1]取镜!C4 -> 石家庄人民眼科 | B4: =[1]取镜!D4 -> 0 | C4: =[1]取镜!E4 -> 0 | D4: =[1]取镜!F4 -> 0 | E4: SJZ-GS-001 | F4: B | G4: 左眼 | H4: 1 | I4: 1 | J4: -1.625 | K4: -1 | L4: -1.5 | M4: 5 | N4: -1.75 | O4: =N4-J4 -> -0.125 | P4: 23.8 | Q4: 23.88 | R4: 0.08 | S4: 170 | T4: 170 | U4: 35 | V4: 6
A5: =[1]取镜!C5 -> 石家庄人民眼科 | B5: =[1]取镜!D5 -> 康安迪 | C5: =[1]取镜!E5 -> 男 | D5: =[1]取镜!F5 -> 42452 | E5: SJZ-GS-002 | F5: D | G5: 右眼 | H5: 1 | I5: 1 | J5: -1 | K5: -0.75 | L5: -0.5 | M5: 5 | N5: -1 | O5: =N5-J5 -> 0 | P5: 23.27 | Q5: 23.35 | R5: 0.08 | S5: 170 | T5: 170 | U5: 9 | V5: 4
A6: =[1]取镜!C6 -> 石家庄人民眼科 | B6: =[1]取镜!D6 -> 0 | C6: =[1]取镜!E6 -> 0 | D6: =[1]取镜!F6 -> 0 | E6: SJZ-GS-002 | F6: D | G6: 左眼 | H6: 1 | I6: 1 | J6: -1.5 | K6: -1.5 | L6: -0.5 | M6: 160 | N6: -1.75 | O6: =N6-J6 -> -0.25 | P6: 23.61 | Q6: 23.73 | R6: 0.12 | S6: 170 | T6: 170 | U6: 25 | V6: 8
A7: =[1]取镜!C7 -> 石家庄人民眼科 | B7: =[1]取镜!D7 -> 李参炜 | C7: =[1]取镜!E7 -> 男 | D7: =[1]取镜!F7 -> 41383 | E7: SJZ-GS-003 | F7: B | G7: 右眼 | H7: 1 | I7: 1 | J7: -3.625 | K7: -3.75 | L7: -1.25 | M7: 175 | N7: -4.375 | O7: =N7-J7 -> -0.75 | P7: 24.57 | Q7: 24.8 | R7: 0.23 | S7: 170 | T7: 170 | U7: 60 | V7: 15
A8: =[1]取镜!C8 -> 石家庄人民眼科 | B8: =[1]取镜!D8 -> 0 | C8: =[1]取镜!E8 -> 0 | D8: =[1]取镜!F8 -> 0 | E8: SJZ-GS-003 | F8: B | G8: 左眼 | H8: 1 | I8: 1 | J8: -3.875 | K8: -3.5 | L8: -1.25 | M8: 10 | N8: -4.125 | O8: =N8-J8 -> -0.25 | P8: 24.69 | Q8: 24.82 | R8: 0.13 | S8: 170 | T8: 170 | U8: 60 | V8: 15
A9: =[1]取镜!C9 -> 石家庄人民眼科 | B9: =[1]取镜!D9 -> 王锦天 | C9: =[1]取镜!E9 -> 男 | D9: =[1]取镜!F9 -> 41579 | E9: SJZ-GS-004 | F9: A | G9: 右眼 | H9: 1 | I9: 1 | J9: -2.75 | K9: -2.5 | L9: -0.75 | M9: 5 | N9: -2.875 | O9: =N9-J9 -> -0.125 | P9: 23.64 | Q9: 23.62 | R9: -0.02 | S9: 170 | T9: 170 | U9: 35 | V9: 8
A10: =[1]取镜!C10 -> 石家庄人民眼科 | B10: =[1]取镜!D10 -> 0 | C10: =[1]取镜!E10 -> 0 | D10: =[1]取镜!F10 -> 0 | E10: SJZ-GS-004 | F10: A | G10: 左眼 | H10: 1 | I10: 1 | J10: -3.125 | K10: -2.75 | L10: -0.5 | M10: 155 | N10: -3 | O10: =N10-J10 -> 0.125 | P10: 23.76 | Q10: 23.73 | R10: -0.03 | S10: 170 | T10: 170 | U10: 80 | V10: 65
A11: =[1]取镜!C11 -> 石家庄人民眼科 | B11: =[1]取镜!D11 -> 徐乐心 | C11: =[1]取镜!E11 -> 男 | D11: =[1]取镜!F11 -> 41504 | E11: SJZ-GS-005 | F11: C | G11: 右眼 | H11: 1 | I11: 1 | J11: -2.875 | K11: -2.25 | L11: -1 | M11: 170 | N11: -2.75 | O11: =N11-J11 -> 0.125 | P11: 25.29 | Q11: 25.28 | R11: -0.01 | S11: 170 | T11: 170 | U11: 80 | V11: 24
A12: =[1]取镜!C12 -> 石家庄人民眼科 | B12: =[1]取镜!D12 -> 0 | C12: =[1]取镜!E12 -> 0 | D12: =[1]取镜!F12 -> 0 | E12: SJZ-GS-005 | F12: C | G12: 左眼 | H12: 1 | I12: 1 | J12: -2.75 | K12: -3 | L12: -0.5 | M12: 5 | N12: -3.25 | O12: =N12-J12 -> -0.5 | P12: 25.48 | Q12: 25.5 | R12: 0.02 | S12: 170 | T12: 170 | U12: 80 | V12: 6
A13: =[1]取镜!C13 -> 石家庄人民眼科 | B13: =[1]取镜!D13 -> 徐乐成 | C13: =[1]取镜!E13 -> 男 | D13: 41504 | E13: SJZ-GS-006 | F13: A | G13: 右眼 | H13: 1 | I13: 1 | J13: -3.375 | K13: -2.75 | L13: -1 | M13: 175 | N13: -3.25 | O13: =N13-J13 -> 0.125 | P13: 25.43 | Q13: 25.42 | R13: -0.01 | S13: 170 | T13: 170 | U13: 80 | V13: 24
A14: =[1]取镜!C14 -> 石家庄人民眼科 | B14: =[1]取镜!D14 -> 0 | C14: =[1]取镜!E14 -> 0 | D14: =[1]取镜!F14 -> 0 | E14: SJZ-GS-006 | F14: A | G14: 左眼 | H14: 1 | I14: 1 | J14: -3 | K14: -2.75 | L14: -1 | M14: 5 | N14: -3.25 | O14: =N14-J14 -> -0.25 | P14: 25.24 | Q14: 25.3 | R14: 0.06 | S14: 170 | T14: 170 | U14: 80 | V14: 6
A15: =[1]取镜!C15 -> 石家庄人民眼科 | B15: =[1]取镜!D15 -> 张楚尧 | C15: =[1]取镜!E15 -> 男 | D15: =[1]取镜!F15 -> 41966 | E15: SJZ-GS-007 | F15: D | G15: 右眼 | H15: 1 | I15: 1 | J15: -2 | K15: -2 | L15: -0.25 | M15: 15 | N15: -2.125 | O15: =N15-J15 -> -0.125 | P15: 24.92 | Q15: 24.94 | R15: 0.02 | S15: 170 | T15: 170 | U15: 45 | V15: 15
A16: =[1]取镜!C16 -> 石家庄人民眼科 | B16: =[1]取镜!D16 -> 0 | C16: =[1]取镜!E16 -> 0 | D16: =[1]取镜!F16 -> 0 | E16: SJZ-GS-007 | F16: D | G16: 左眼 | H16: 1 | I16: 1 | J16: -2.25 | K16: -1.75 | L16: -0.75 | M16: 155 | N16: -2.125 | O16: =N16-J16 -> 0.125 | P16: 25.2 | Q16: 25.03 | R16: -0.17 | S16: 170 | T16: 170 | U16: 60 | V16: 8
A17: =[1]取镜!C17 -> 石家庄人民眼科 | B17: =[1]取镜!D17 -> 张海冰 | C17: =[1]取镜!E17 -> 男 | D17: =[1]取镜!F17 -> 41306 | E17: SJZ-GS-008 | F17: D | G17: 右眼 | H17: 1 | I17: 1 | J17: -1.125 | K17: -0.5 | L17: -1.75 | M17: 170 | N17: -1.375 | O17: =N17-J17 -> -0.25 | P17: 23.42 | Q17: 23.52 | R17: 0.1 | S17: 170 | T17: 170 | U17: 120 | V17: 65
A18: =[1]取镜!C18 -> 石家庄人民眼科 | B18: =[1]取镜!D18 -> 0 | C18: =[1]取镜!E18 -> 0 | D18: =[1]取镜!F18 -> 0 | E18: SJZ-GS-008 | F18: D | G18: 左眼 | H18: 1 | I18: 1 | J18: -0.875 | L18: -2.25 | M18: 5 | N18: =K18+0.5*L18 -> -1.125 | O18: =N18-J18 -> -0.25 | P18: 23.21 | Q18: 23.26 | R18: 0.05 | S18: 170 | T18: 170 | U18: 80 | V18: 24
A19: =[1]取镜!C19 -> 石家庄人民眼科 | B19: =[1]取镜!D19 -> 李文晴 | C19: =[1]取镜!E19 -> 女 | D19: =[1]取镜!F19 -> 42299 | E19: SJZ-GS-009 | F19: C | G19: 右眼 | H19: 1 | I19: 1 | J19: -1.375 | K19: -1.5 | L19: -0.5 | M19: 165 | N19: -1.75 | O19: =N19-J19 -> -0.375 | P19: 24.03 | Q19: 24.14 | R19: 0.11 | S19: 170 | T19: 170 | U19: 60 | V19: 8
A20: =[1]取镜!C20 -> 石家庄人民眼科 | B20: =[1]取镜!D20 -> 0 | C20: =[1]取镜!E20 -> 0 | D20: =[1]取镜!F20 -> 0 | E20: SJZ-GS-009 | F20: C | G20: 左眼 | H20: 1 | I20: 1 | J20: -0.875 | K20: -1 | L20: -0.75 | M20: 175 | N20: -1.375 | O20: =N20-J20 -> -0.5 | P20: 23.99 | Q20: 24.08 | R20: 0.09 | S20: 170 | T20: 170 | U20: 120 | V20: 8
A21: =[1]取镜!C21 -> 石家庄人民眼科 | B21: =[1]取镜!D21 -> 王可妍 | C21: =[1]取镜!E21 -> 女 | D21: =[1]取镜!F21 -> 40620 | E21: SJZ-GS-010 | F21: D | G21: 右眼 | H21: 1 | I21: 1 | J21: -3.25 | K21: -2.75 | L21: 0 | M21: 0 | N21: -2.75 | O21: =N21-J21 -> 0.5 | P21: 25.34 | Q21: 25.19 | R21: -0.15 | S21: 170 | T21: 170 | U21: 120 | V21: 3
A22: =[1]取镜!C22 -> 石家庄人民眼科 | B22: ss | C22: =[1]取镜!E22 -> 0 | D22: =[1]取镜!F22 -> 0 | E22: SJZ-GS-010 | F22: D | G22: 左眼 | H22: 1 | I22: 1 | J22: -3.25 | K22: -3 | L22: -0.5 | M22: 165 | N22: -3.25 | O22: =N22-J22 -> 0 | P22: 25.12 | Q22: 25.21 | R22: 0.09 | S22: 170 | T22: 80 | U22: 80 | V22: 35
A23: =[1]取镜!C23 -> 石家庄人民眼科 | B23: =[1]取镜!D23 -> 檀沐析 | C23: =[1]取镜!E23 -> 男 | D23: =[1]取镜!F23 -> 42553 | E23: =[1]取镜!G23 -> SJZ-GS-011 | F23: D | G23: 右眼 | H23: 1 | I23: 1 | J23: -2.25 | K23: -1.75 | L23: -1.25 | M23: 175 | N23: -2.375 | O23: =N23-J23 -> -0.125 | P23: 24.6 | Q23: 24.92 | R23: 0.32 | S23: 170 | T23: 170 | U23: 120 | V23: 8
A24: =[1]取镜!C24 -> 石家庄人民眼科 | B24: =[1]取镜!D24 -> 0 | C24: =[1]取镜!E24 -> 0 | D24: =[1]取镜!F24 -> 0 | E24: SJZ-GS-011 | F24: D | G24: 左眼 | H24: 1 | I24: 1 | J24: -2.25 | K24: -1.5 | L24: -1.5 | M24: 5 | N24: -2.25 | O24: =N24-J24 -> 0 | P24: 24.75 | Q24: 25.02 | R24: 0.27 | S24: 170 | T24: 120 | U24: 25 | V24: 3
A25: =[1]取镜!C25 -> 石家庄人民眼科 | B25: =[1]取镜!D25 -> 李昭旭 | C25: =[1]取镜!E25 -> 男 | D25: =[1]取镜!F25 -> 42755 | E25: SJZ-GS-012 | F25: B | G25: 右眼 | H25: 0.8 | I25: 1 | J25: -1.875 | K25: -2.5 | L25: -0.5 | M25: 180 | N25: -2.75 | O25: =N25-J25 -> -0.875 | P25: 24.09 | Q25: 24.34 | R25: 0.25 | S25: 170 | T25: 80 | U25: 35 | V25: 8
A26: =[1]取镜!C26 -> 石家庄人民眼科 | B26: =[1]取镜!D26 -> 0 | C26: =[1]取镜!E26 -> 0 | D26: =[1]取镜!F26 -> 0 | E26: SJZ-GS-012 | F26: B | G26: 左眼 | H26: 0.8 | I26: 1 | J26: -2 | K26: -2 | L26: -0.5 | M26: 165 | N26: -2.25 | O26: =N26-J26 -> -0.25 | P26: 24.24 | Q26: 24.46 | R26: 0.22 | S26: 170 | T26: 170 | U26: 60 | V26: 24
A27: =[1]取镜!C27 -> 石家庄人民眼科 | B27: =[1]取镜!D27 -> 温心语 | C27: =[1]取镜!E27 -> 女 | D27: =[1]取镜!F27 -> 43135 | E27: SJZ-GS-013 | F27: B | G27: 右眼 | H27: 1 | I27: 1 | J27: -1 | K27: -1.75 | L27: -0.75 | M27: 180 | N27: -2.125 | O27: =N27-J27 -> -1.125 | P27: 23.24 | Q27: 23.48 | R27: 0.24 | S27: 170 | T27: 170 | U27: 60 | V27: 15
A28: =[1]取镜!C28 -> 石家庄人民眼科 | B28: =[1]取镜!D28 -> 0 | C28: =[1]取镜!E28 -> 0 | D28: =[1]取镜!F28 -> 0 | E28: SJZ-GS-013 | F28: B | G28: 左眼 | H28: 1 | I28: 1 | J28: -0.75 | K28: -1 | L28: -1 | M28: 175 | N28: -1.5 | O28: =N28-J28 -> -0.75 | P28: 23.22 | Q28: 23.37 | R28: 0.15 | S28: 170 | T28: 170 | U28: 80 | V28: 24
A29: =[1]取镜!C29 -> 石家庄人民眼科 | B29: =[1]取镜!D29 -> 刘梓萌 | C29: =[1]取镜!E29 -> 女 | D29: =[1]取镜!F29 -> 42825 | E29: SJZ-GS-014 | F29: D | G29: 右眼 | H29: 1 | I29: 1 | J29: -0.75 | K29: -0.5 | L29: -1 | M29: 180 | N29: -1 | O29: =N29-J29 -> -0.25 | P29: 24.79 | Q29: 24.79 | R29: 0 | S29: 170 | T29: 170 | U29: 80 | V29: 6
A30: =[1]取镜!C30 -> 石家庄人民眼科 | B30: =[1]取镜!D30 -> 0 | C30: =[1]取镜!E30 -> 0 | D30: =[1]取镜!F30 -> 0 | E30: SJZ-GS-014 | F30: D | G30: 左眼 | H30: 1 | I30: 1 | J30: -0.875 | K30: -0.75 | L30: -1.25 | M30: 170 | N30: -1.375 | O30: =N30-J30 -> -0.5 | P30: 24.73 | Q30: 24.88 | R30: 0.15 | S30: 170 | T30: 170 | U30: 60 | V30: 4
A31: =[1]取镜!C31 -> 石家庄人民眼科 | B31: =[1]取镜!D31 -> 秦丞远 | C31: =[1]取镜!E31 -> 男 | D31: =[1]取镜!F31 -> 42004 | E31: SJZ-GS-015 | F31: A | G31: 右眼 | H31: 1 | I31: 1 | J31: -1.875 | K31: -2.25 | L31: -0.5 | M31: 165 | N31: -2.5 | O31: =N31-J31 -> -0.625 | P31: 25.03 | Q31: 25.14 | R31: 0.11 | S31: 170 | T31: 170 | U31: 60 | V31: 24
A32: =[1]取镜!C32 -> 石家庄人民眼科 | B32: =[1]取镜!D32 -> 0 | C32: =[1]取镜!E32 -> 0 | D32: =[1]取镜!F32 -> 0 | E32: SJZ-GS-015 | F32: A | G32: 左眼 | H32: 1 | I32: 1 | J32: -2.875 | K32: -2.5 | L32: -0.75 | M32: 175 | N32: -2.875 | O32: =N32-J32 -> 0 | P32: 25.41 | Q32: 25.45 | R32: 0.04 | S32: 170 | T32: 170 | U32: 120 | V32: 15
A33: =[1]取镜!C33 -> 石家庄人民眼科 | B33: =[1]取镜!D33 -> 李诗涵 | C33: =[1]取镜!E33 -> 女 | D33: =[1]取镜!F33 -> 42616 | E33: SJZ-GS-016 | F33: C | G33: 右眼 | H33: 1 | I33: 1 | K33: -1 | L33: 0 | M33: 0 | N33: -1 | O33: =N33-J33 -> -1 | P33: 23.72 | Q33: 23.65 | R33: -0.07 | S33: 170 | T33: 170 | U33: 45 | V33: 15
A34: =[1]取镜!C34 -> 石家庄人民眼科 | B34: =[1]取镜!D34 -> 0 | C34: =[1]取镜!E34 -> 0 | D34: =[1]取镜!F34 -> 0 | E34: SJZ-GS-016 | F34: C | G34: 左眼 | H34: 1 | I34: 1 | K34: -1.25 | L34: -0.25 | M34: 160 | N34: -1.375 | O34: =N34-J34 -> -1.375 | P34: 23.89 | Q34: 23.82 | R34: -0.07 | S34: 170 | T34: 170 | U34: 15 | V34: 15
A35: =[1]取镜!C35 -> 石家庄人民眼科 | B35: =[1]取镜!D35 -> 崔赵兮 | C35: =[1]取镜!E35 -> 女 | D35: =[1]取镜!F35 -> 42811 | E35: SJZ-GS-017 | F35: D | G35: 右眼 | H35: 1 | I35: 1 | J35: -0.875 | K35: -1.25 | L35: -0.75 | M35: 180 | N35: -1.625 | O35: =N35-J35 -> -0.75 | P35: 23.68 | Q35: 23.83 | R35: 0.15 | S35: 170 | T35: 170 | U35: 35 | V35: 24
A36: =[1]取镜!C36 -> 石家庄人民眼科 | B36: =[1]取镜!D36 -> 0 | C36: =[1]取镜!E36 -> 0 | D36: =[1]取镜!F36 -> 0 | E36: SJZ-GS-017 | F36: D | G36: 左眼 | H36: 1 | I36: 1 | J36: -1.25 | K36: -1.5 | L36: -0.75 | M36: 175 | N36: -1.875 | O36: =N36-J36 -> -0.625 | P36: 23.89 | Q36: 24.06 | R36: 0.17 | S36: 170 | T36: 170 | U36: 9 | V36: 6
A37: =[1]取镜!C37 -> 石家庄人民眼科 | B37: =[1]取镜!D37 -> 刘镐泽 | C37: =[1]取镜!E37 -> 男 | D37: =[1]取镜!F37 -> 41944 | E37: SJZ-GS-018 | F37: D | G37: 右眼 | H37: 1 | I37: 1 | J37: -3.125 | K37: -3 | L37: -1.5 | M37: 175 | N37: -3.75 | O37: =N37-J37 -> -0.625 | P37: 25.32 | Q37: 25.46 | R37: 0.14 | S37: 170 | T37: 170 | U37: 6 | V37: 4
A38: =[1]取镜!C38 -> 石家庄人民眼科 | B38: =[1]取镜!D38 -> 0 | C38: =[1]取镜!E38 -> 0 | D38: =[1]取镜!F38 -> 0 | E38: SJZ-GS-018 | F38: D | G38: 左眼 | H38: 1 | I38: 1 | J38: -2.5 | K38: -2 | L38: -2 | M38: 165 | N38: -3 | O38: =N38-J38 -> -0.5 | P38: 25.03 | Q38: 25.19 | R38: 0.16 | S38: 120 | T38: 170 | U38: 45 | V38: 8
A39: =[1]取镜!C39 -> 石家庄人民眼科 | B39: =[1]取镜!D39 -> 何昊轩 | C39: =[1]取镜!E39 -> 男 | D39: =[1]取镜!F39 -> 40870 | E39: SJZ-GS-019 | F39: A | G39: 右眼 | H39: 1 | I39: 1 | J39: -2.375 | K39: -1.75 | L39: -1 | M39: 170 | N39: -2.25 | O39: =N39-J39 -> 0.125 | P39: 24.97 | Q39: 24.87 | R39: -0.1 | S39: 170 | T39: 170 | U39: 15 | V39: 0
A40: =[1]取镜!C40 -> 石家庄人民眼科 | B40: =[1]取镜!D40 -> 0 | C40: =[1]取镜!E40 -> 0 | D40: =[1]取镜!F40 -> 0 | E40: SJZ-GS-019 | F40: A | G40: 左眼 | H40: 1 | I40: 1 | J40: -1.25 | K40: -0.5 | L40: -1.5 | M40: 170 | N40: -1.25 | O40: =N40-J40 -> 0 | P40: 24.47 | Q40: 24.43 | R40: -0.04 | S40: 170 | T40: 170 | U40: 15 | V40: 4
...
