Workbook

Sheet 经营预测
I1: 单位：万元 | R1: 单位：万元
B2: 项目 | C2: 2024年 | D2: 2025年 | E2: 2026年 | F2: 2027年 | G2: 2028年 | H2: 2029年 | I2: 2030年 | K2: 项 目 | L2: 2024年 | M2: 2025年 | N2: 2026年 | O2: 2027年 | P2: 2028年 | Q2: 2029年 | R2: 2030年
B3: 营业收入 | C3: 77.08 | D3: 241.77 | E3: =收入预测!H8 -> 1061.9469 | F3: =收入预测!H16 -> 1951.3274 | G3: =收入预测!H24 -> 5066.3717 | H3: =收入预测!T8 -> 10049.558 | I3: =收入预测!T16 -> 20046.018 | K3: 销售商品、提供劳务收到的现金 | L3: 180.41 | M3: 277.04342 | N3: =E3*1.13 -> 1200 | O3: =F3*1.13 -> 2205 | P3: =G3*1.13 -> 5725 | Q3: =H3*1.13 -> 11356 | R3: =I3*1.13 -> 22652 | S3: =SUM(L3:R3)-#REF! -> #REF!
B4: 营业成本 | C4: 39.35 | D4: 99.91 | E4: =SUM(E5:E8) -> 476.91 | F4: =F3*(1-F33) -> 921.46018 | G4: =G3*(1-G33) -> 1853.9823 | H4: =H3*(1-H33) -> 3166.9027 | I4: =I3*(1-I33) -> 7297.5221 | K4: 收到的税费返还 | M4: 222.40477 | S4: =SUM(L4:R4)-#REF! -> #REF!
B5: 折旧摊销 | C5: =3.25+19.89 -> 23.14 | D5: 28.36 | E5: 52.93 | F5: =E5+O13*95%/10*60% -> 52.93 | G5: =F5+P13*95%/10*2 -> 138.43 | H5: =G5*1.2 -> 166.116 | I5: =H5*1.2 -> 199.3392 | K5: 收到其他与经营活动有关的现金 | L5: 28.15 | M5: 7.363421 | N5: 0.5 | O5: 10 | P5: 10 | Q5: 10 | R5: 10 | S5: =SUM(L5:R5)-#REF! -> #REF!
B6: 人员费用 | C6: =4.3+19.46 -> 23.76 | D6: =5.22+13.3 -> 18.52 | E6: 103.94 | F6: =E6*(1+20%) -> 124.728 | G6: =F6*2 -> 249.456 | H6: =G6*2 -> 498.912 | I6: =H6*2 -> 997.824 | K6: 经营活动现金流入小计 | L6: =SUM(L3:L5) -> 208.56 | M6: =SUM(M3:M5) -> 506.81161 | N6: =SUM(N3:N5) -> 1200.5 | O6: =SUM(O3:O5) -> 2215 | P6: =SUM(P3:P5) -> 5735 | Q6: =SUM(Q3:Q5) -> 11366 | R6: =SUM(R3:R5) -> 22662 | S6: =SUM(L6:R6)-#REF! -> #REF!
B7: 公共费用 | D7: 16.28 | E7: 12.16 | F7: =E7*(1+10%) -> 13.376 | G7: =F7*(1+10%) -> 14.7136 | H7: =G7*(1+10%) -> 16.18496 | I7: =H7*(1+10%) -> 17.803456 | K7: 购买商品、接受劳务支付的现金 | L7: 49.82 | M7: 92.968107 | N7: 351.06275 | O7: =F8+F25 -> 784.45818 | P7: =G8+G25 -> 1510.8179 | Q7: =H8+H25 -> 2551.0684 | R7: =I8+I25 -> 6154.4721 | S7: =SUM(L7:R7)-#REF! -> #REF!
B8: 材料 | D8: =27.45+9.31 -> 36.76 | E8: 307.88 | F8: =F4-F5-F6-F7 -> 730.42618 | G8: =G4-G5-G6-G7 -> 1451.3827 | H8: =H4-H5-H6-H7 -> 2485.6897 | I8: =I4-I5-I6-I7 -> 6082.5555 | K8: 支付给职工以及为职工支付的现金 | L8: 639.63 | M8: 881.04215 | N8: 886.01751 | O8: =F6+F12+F17+F22 -> 1025.216 | P8: =G6+G12+G17+G22 -> 1289.1697 | Q8: =H6+H12+H17+H22 -> 1769.3506 | R8: =I6+I12+I17+I22 -> 2561.7833 | S8: =SUM(L8:R8)-#REF! -> #REF!
B9: 毛利润 | C9: =C3-C4 -> 37.73 | D9: =D3-D4 -> 141.86 | E9: =E3-E4 -> 585.0369 | F9: =F3-F4 -> 1029.8673 | G9: =G3-G4 -> 3212.3894 | H9: =H3-H4 -> 6882.6549 | I9: =I3-I4 -> 12748.496 | K9: 支付的各项税费 | L9: 0.12 | M9: 0.209619 | N9: 50.898789 | O9: =(O3/1.13*13%-O7/1.13*13%)*1.12 -> 183.03619 | P9: =(P3/1.13*13%-P7/1.13*13%-P13*13%)*1.12 -> 477.4755 | Q9: =(Q3/1.13*13%-Q7/1.13*13%)*1.12 -> 1134.5115 | R9: =(R3/1.13*13%-R7/1.13*13%)*1.12 -> 2125.6992 | S9: =SUM(L9:R9)-#REF! -> #REF!
B10: 税金及附加 | C10: 0.12 | D10: 0.19 | E10: 5.45 | F10: =(O3/1.13-O7/1.13)*12% -> 150.854 | G10: =(P3/1.13-P7/1.13)*12% -> 447.52376 | H10: =(Q3/1.13-Q7/1.13)*12% -> 935.03698 | I10: =(R3/1.13-R7/1.13)*12% -> 1751.9499 | K10: 支付其他与经营活动有关的现金 | L10: 265.55 | M10: 470.06572 | N10: 679.22588 | O10: =F13+F18+F21+F15+F23+F25 -> 1089.571 | P10: =G13+G18+G21+G15+G23+G25 -> 1247.8736 | Q10: =H13+H18+H21+H15+H23+H25 -> 1496.128 | R10: =I13+I18+I21+I15+I23+I25 -> 1807.2274 | S10: =SUM(L10:R10)-#REF! -> #REF!
B11: 销售费用 | C11: 293.72 | D11: =SUM(D12:D15) -> 817.68 | E11: =SUM(E12:E15) -> 908.53 | F11: =E11*(1+F35) -> 1090.236 | G11: =F11*(1+G35) -> 1308.2832 | H11: =G11*(1+H35) -> 1700.7682 | I11: =H11*(1+I35) -> 2210.9986 | K11: 经营活动现金流出小计 | L11: =SUM(L7:L10) -> 955.12 | M11: =SUM(M7:M10) -> 1444.2856 | N11: =SUM(N7:N10) -> 1967.2049 | O11: =SUM(O7:O10) -> 3082.2814 | P11: =SUM(P7:P10) -> 4525.3367 | Q11: =SUM(Q7:Q10) -> 6951.0585 | R11: =SUM(R7:R10) -> 12649.182 | S11: =SUM(L11:R11)-#REF! -> #REF! | T11: =S6-S11-S12 -> #REF!
B12: 人员费用 | C12: 167.89 | D12: 498.45 | E12: 463.69 | F12: =E12*(1+$F$35) -> 556.428 | G12: =F12*(1+$G$35) -> 667.7136 | H12: =G12*(1+$H$35) -> 868.02768 | I12: =H12*(1+$I$35) -> 1128.436 | K12: 经营活动产生的现金流量净额 | L12: =L6-L11 -> -746.56 | M12: =M6-M11 -> -937.47399 | N12: =N6-N11 -> -766.70493 | O12: =O6-O11 -> -867.28136 | P12: =P6-P11 -> 1209.6633 | Q12: =Q6-Q11 -> 4414.9415 | R12: =R6-R11 -> 10012.818 | S12: =SUM(L12:R12)-#REF! -> #REF!
B13: 市场费用 | C13: 76.24 | D13: =817.68-590.95 -> 226.73 | E13: =908.53-570.81 -> 337.72 | F13: =E13*(1+$F$35) -> 405.264 | G13: =F13*(1+$G$35) -> 486.3168 | H13: =G13*(1+$H$35) -> 632.21184 | I13: =H13*(1+$I$35) -> 821.87539 | K13: 购建固定资产、无形资产和其他长期资产支付的现金 | L13: 184.38 | M13: 272.9118 | N13: 480.25 | P13: 450 | Q13: 50 | R13: 50 | S13: =SUM(L13:R13)-#REF! -> #REF!
B14: 折旧摊销 | C14: =0.09+3.08 -> 3.17 | D14: 3.18 | E14: 2.53 | F14: =E14*(1+$F$35) -> 3.036 | G14: =F14*(1+$G$35) -> 3.6432 | H14: =G14*(1+$H$35) -> 4.73616 | I14: =H14*(1+$I$35) -> 6.157008 | K14: 投资活动现金流出小计 | L14: =SUM(L13:L13) -> 184.38 | M14: =SUM(M13:M13) -> 272.9118 | N14: =SUM(N13:N13) -> 480.25 | O14: =SUM(O13:O13) -> 0 | P14: =SUM(P13:P13) -> 450 | Q14: =SUM(Q13:Q13) -> 50 | R14: =SUM(R13:R13) -> 50 | S14: =SUM(L14:R14)-#REF! -> #REF!
B15: 日常费用 | C15: =C11-C12-C13 -> 49.59 | D15: 89.32 | E15: 104.59 | F15: =E15*(1+$F$35) -> 125.508 | G15: =F15*(1+$G$35) -> 150.6096 | H15: =G15*(1+$H$35) -> 195.79248 | I15: =H15*(1+$I$35) -> 254.53022 | K15: 投资活动产生的现金流量净额 | L15: =-L14 -> -184.38 | M15: =-M14 -> -272.9118 | N15: =-N14 -> -480.25 | O15: =-O14 -> 0 | P15: =-P14 -> -450 | Q15: =-Q14 -> -50 | R15: =-R14 -> -50 | S15: =SUM(L15:R15)-#REF! -> #REF!
B16: 管理费用 | C16: 182.19 | D16: =SUM(D17:D20) -> 256.62 | E16: =SUM(E17:E20) -> 256.18 | F16: =SUM(F17:F20) -> 268.989 | G16: =SUM(G17:G20) -> 282.43845 | H16: =SUM(H17:H20) -> 296.56037 | I16: =SUM(I17:I20) -> 311.38839 | K16: 取得借款收到的现金 | S16: =SUM(L16:R16)-#REF! -> #REF!
B17: 人员费用 | C17: 76.97 | D17: 106.55 | E17: 123.16 | F17: =E17*(1+F36) -> 129.318 | G17: =F17*(1+G36) -> 135.7839 | H17: =G17*(1+H36) -> 142.5731 | I17: =H17*(1+I36) -> 149.70175 | K17: 收到其他与筹资活动有关的现金 | L17: 1020 | M17: 1080 | S17: =SUM(L17:R17)-#REF! -> #REF!
B18: 公共费用 | C18: 33.98 | D18: 70.73 | E18: 71.08 | F18: =E18*(1+F36) -> 74.634 | G18: =F18*(1+G36) -> 78.3657 | H18: =G18*(1+H36) -> 82.283985 | I18: =H18*(1+I36) -> 86.398184 | K18: 筹资活动现金流入小计 | L18: =SUM(L16:L17) -> 1020 | M18: =SUM(M16:M17) -> 1080 | N18: =SUM(N16:N17) -> 0 | O18: =SUM(O16:O17) -> 0 | P18: =SUM(P16:P17) -> 0 | Q18: =SUM(Q16:Q17) -> 0 | R18: =SUM(R16:R17) -> 0 | S18: =SUM(L18:R18)-#REF! -> #REF!
B19: 折旧摊销 | C19: 8.78 | D19: 2.36 | E19: 1.06 | F19: =E19*(1+F36) -> 1.113 | G19: =F19*(1+G36) -> 1.16865 | H19: =G19*(1+H36) -> 1.2270825 | I19: =H19*(1+I36) -> 1.2884366 | K19: 偿还债务支付的现金 | S19: =SUM(L19:R19)-#REF! -> #REF!
B20: 其他费用 | C20: =C16-C17-C18-C19 -> 62.46 | D20: =256.62-179.64 -> 76.98 | E20: =256.18-195.3 -> 60.88 | F20: =E20*(1+F36) -> 63.924 | G20: =F20*(1+G36) -> 67.1202 | H20: =G20*(1+H36) -> 70.47621 | I20: =H20*(1+I36) -> 74.00002 | K20: 分配股利、利润或偿付利息支付的现金 | L20: 13.63 | M20: 41.427498 | N20: 102.5 | O20: 140 | P20: 160 | Q20: 130 | S20: =SUM(L20:R20)-#REF! -> #REF!
B21: 研发费用 | C21: 596.3 | D21: =SUM(D22:D25) -> 547.61 | E21: =SUM(E22:E25) -> 356.71 | F21: =SUM(F22:F25) -> 392.381 | G21: =SUM(G22:G25) -> 431.6191 | H21: =SUM(H22:H25) -> 474.78101 | I21: =SUM(I22:I25) -> 522.25911 | K21: 支付其他与筹资活动有关的现金 | L21: =59.17+0.08 -> 59.25 | M21: =58.9348+0.31 -> 59.2448 | N21: 59.22 | O21: =N21*1.1 -> 65.142 | P21: =O21*1.1 -> 71.6562 | Q21: =P21*1.1 -> 78.82182 | R21: =Q21*1.1 -> 86.704002 | S21: =SUM(L21:R21)-#REF! -> #REF!
B22: 人员费用 | C22: 412.31 | D22: 373.76 | E22: 195.22 | F22: =E22*(1+F37) -> 214.742 | G22: =F22*(1+G37) -> 236.2162 | H22: =G22*(1+H37) -> 259.83782 | I22: =H22*(1+I37) -> 285.8216 | K22: 筹资活动现金流出小计 | L22: =SUM(L20:L21) -> 72.88 | M22: =SUM(M20:M21) -> 100.6723 | N22: =SUM(N20:N21) -> 161.72 | O22: =SUM(O20:O21) -> 205.142 | P22: =SUM(P20:P21) -> 231.6562 | Q22: =SUM(Q20:Q21) -> 208.82182 | R22: =SUM(R19:R21) -> 86.704002 | S22: =SUM(L22:R22)-#REF! -> #REF!
B23: 公共费用 | C23: 47.59 | D23: =3.31+27.62 -> 30.93 | E23: 34.32 | F23: =E23*(1+F37) -> 37.752 | G23: =F23*(1+G37) -> 41.5272 | H23: =G23*(1+H37) -> 45.67992 | I23: =H23*(1+I37) -> 50.247912 | K23: 筹资活动产生的现金流量净额 | L23: =L18-L22 -> 947.12 | M23: =M18-M22 -> 979.3277 | N23: =N18-N22 -> -161.72 | O23: =O18-O22 -> -205.142 | P23: =P18-P22 -> -231.6562 | Q23: =Q18-Q22 -> -208.82182 | R23: =R18-R22 -> -86.704002 | S23: =SUM(L23:R23)-#REF! -> #REF!
B24: 折旧摊销 | C24: 88.51 | D24: 95.74 | E24: 78.05 | F24: =E24*(1+F37) -> 85.855 | G24: =F24*(1+G37) -> 94.4405 | H24: =G24*(1+H37) -> 103.88455 | I24: =H24*(1+I37) -> 114.27301 | K24: 现金及现金等价物净增加额 | L24: =L12+L15+L23 -> 16.18 | M24: =M12+M15+M23 -> -231.05809 | N24: =N12+N15+N23 -> -1408.6749 | O24: =O12+O15+O23 -> -1072.4234 | P24: =P12+P15+P23 -> 528.0071 | Q24: =Q12+Q15+Q23 -> 4156.1197 | R24: =R12+R15+R23 -> 9876.114 | S24: =SUM(L24:R24)-#REF! -> #REF! | T24: =S23+S15+S12-S24 -> #REF!
B25: 其他费用 | C25: =C21-C22-C23-C24 -> 47.89 | D25: =547.61-500.43 -> 47.18 | E25: =356.71-307.59 -> 49.12 | F25: =E25*(1+F37) -> 54.032 | G25: =F25*(1+G37) -> 59.4352 | H25: =G25*(1+H37) -> 65.37872 | I25: =H25*(1+I37) -> 71.916592 | K25: 加：期初现金及现金等价物余额 | L25: 273.76 | M25: =L26 -> 289.94 | N25: =M26 -> 58.881911
B26: 财务费用 | C26: 18.23 | D26: 63.97 | E26: 104.59 | F26: =O20 -> 140 | G26: =P20 -> 160 | H26: =Q20 -> 130 | K26: 期末现金及现金等价物余额 | L26: =L24+L25 -> 289.94 | M26: =M24+M25 -> 58.881911 | N26: =N24+N25 -> -1349.793 | O26: =O24+O25 -> -1072.4234 | P26: =P24+P25 -> 528.0071 | Q26: =Q24+Q25 -> 4156.1197 | R26: =R24+R25 -> 9876.114
B27: 加 : 其他收益 | C27: 25.82 | D27: 6.78 | F27: =O5 -> 10 | G27: =P5 -> 10 | H27: =Q5 -> 10 | I27: =R5 -> 10 | K27: 借款额度 | O27: =SUM(M26:O26) -> -2363.3345
B28: 信用减值损失 | C28: -2.8176 | D28: -4.24 | E28: -6 | F28: =-10 -> -10 | G28: -15 | H28: -20 | I28: -25 | L28: =L3+L4+L5-L7-L8-L9-L10-L13+L17-L20-L21-L24 -> 2.2737368e-13 | M28: =M3+M4+M5-M7-M8-M9-M10-M13+M17-M20-M21-M24 -> 0 | N28: =N3+N4+N5-N7-N8-N9-N10-N13+N17-N20-N21-N24 -> 0 | O28: =O3+O4+O5-O7-O8-O9-O10-O13+O17-O20-O21-O24 -> 0 | P28: =P3+P4+P5-P7-P8-P9-P10-P13+P17-P20-P21-P24 -> 0 | Q28: =Q3+Q4+Q5-Q7-Q8-Q9-Q10-Q13+Q17-Q20-Q21-Q24 -> 0 | R28: =R3+R4+R5-R7-R8-R9-R10-R13+R17-R20-R21-R24 -> 0
B29: 资产减值损失 | C29: -0.025147 | E29: -0.4 | J29: =J28+J21+J16+J11+J5 -> 0
B30: 资产处置收益 | C30: -9.217147
B31: 营业利润 | C31: =C3-C4-C10-C11-C16-C21-C26+C27+C28+C29+C30 -> -1039.0699 | D31: =D3-D4-D10-D11-D16-D21-D26+D27+D28+D29+D30 -> -1541.67 | E31: =E3-E4-E10-E11-E16-E21-E26+E27+E28+E29+E30 -> -1052.8231 | F31: =F3-F4-F10-F11-F16-F21-F26+F27+F28+F29+F30 -> -1012.5927 | G31: =G3-G4-G10-G11-G16-G21-G26+G27+G28+G29+G30 -> 577.52487 | H31: =H3-H4-H10-H11-H16-H21-H26+H27+H28+H29+H30 -> 3335.5083 | I31: =I3-I4-I10-I11-I16-I21-I26+I27+I28+I29+I30 -> 7936.8996
C32: =C9-C10-C11-C16-C21-C26+C27+C28+C29+C30-C31 -> 0 | D32: =D9-D10-D11-D16-D21-D26+D27+D28+D29+D30-D31 -> 0 | E32: =E9-E10-E11-E16-E21-E26+E27+E28+E29+E30-E31 -> 0 | F32: =F9-F10-F11-F16-F21-F26+F27+F28+F29+F30-F31 -> 0 | G32: =G9-G10-G11-G16-G21-G26+G27+G28+G29+G30-G31 -> 0 | H32: =H9-H10-H11-H16-H21-H26+H27+H28+H29+H30-H31 -> 0 | I32: =I9-I10-I11-I16-I21-I26+I27+I28+I29+I30-I31 -> 0
B33: 毛利率 | C33: =C9/C3 -> 0.48949144 | D33: =D9/D3 -> 0.58675601 | E33: =E9/E3 -> 0.55090975 | F33: =收入预测!M16 -> 0.52777778 | G33: =收入预测!M24 -> 0.63406114 | H33: =收入预测!Y8 -> 0.68487143 | I33: =收入预测!Y16 -> 0.6359615
B34: 营业收入增长率 | F34: =F3/E3-1 -> 0.8375 | G34: =G3/F3-1 -> 1.5963719 | H34: =H3/G3-1 -> 0.98358079 | I34: =I3/H3-1 -> 0.99471645
B35: 销售费用增长率 | E35: =E11/D11-1 -> 0.11110703 | F35: 0.2 | G35: 0.2 | H35: 0.3 | I35: 0.3
B36: 管理费用增长率 | E36: =E16/D16-1 -> -0.0017145975 | F36: 0.05 | G36: 0.05 | H36: 0.05 | I36: 0.05
B37: 研发费用增长率 | E37: =E21/D21-1 -> -0.34860576 | F37: 0.1 | G37: 0.1 | H37: 0.1 | I37: 0.1
K40: 目标是 2027 现金流转正，2028 开始盈利

Sheet 收入预测
B2: 2026年 | C2: 产品名称 | D2: 产品类型 | E2: 销售数量 | F2: 销售单价（含税） | G2: 含税销售 | H2: 销售收入（不含税） | I2: 单位BOM材料费 | J2: BOM材料成本 | K2: 毛利率 | M2: 平均毛利率 | N2: 2029年 | O2: 产品名称 | P2: 产品类型 | Q2: 销售数量 | R2: 销售单价（含税） | S2: 含税销售 | T2: 销售收入（不含税） | U2: 单位BOM材料费 | V2: BOM材料成本 | W2: 毛利率 | Y2: 平均毛利率
C3: 高视高清 | D3: RGP | E3: 1000 | F3: =500/10000 -> 0.05 | G3: =E3*F3 -> 50 | H3: =+E3*F3/1.13 -> 44.247788 | I3: =0.0065 -> 0.0065 | J3: =I3*E3 -> 6.5 | K3: 0.01 | L3: =H3*(1-K3) -> 43.80531 | O3: 高视高清 | P3: RGP | Q3: 3000 | R3: =500/10000 -> 0.05 | S3: =Q3*R3 -> 150 | T3: =+Q3*R3/1.13 -> 132.74336 | U3: =0.0065 -> 0.0065 | V3: =U3*Q3 -> 19.5 | W3: 0.65 | X3: =T3*(1-W3) -> 46.460177
C4: 高视高清 | D4: 离焦镜片（副） | E4: 25000 | F4: =350/10000 -> 0.035 | G4: =E4*F4 -> 875 | H4: =+E4*F4/1.13 -> 774.33628 | I4: =0.0175/1.13 -> 0.015486726 | J4: =I4*E4 -> 387.16814 | K4: 0.75 | L4: =H4*(1-K4) -> 193.58407 | O4: 高视高清 | P4: 离焦镜片（副） | Q4: 100000 | R4: =350/10000 -> 0.035 | S4: =Q4*R4 -> 3500 | T4: =+Q4*R4/1.13 -> 3097.3451 | U4: =0.0175/1.13 -> 0.015486726 | V4: =U4*Q4 -> 1548.6726 | W4: 0.8 | X4: =T4*(1-W4) -> 619.46903
C5: 高视高清 | D5: OK镜（国内） | E5: 5000 | F5: =550/10000 -> 0.055 | G5: =E5*F5 -> 275 | H5: =+E5*F5/1.13 -> 243.36283 | I5: =0.01 -> 0.01 | J5: =I5*E5 -> 50 | K5: 0.01 | L5: =H5*(1-K5) -> 240.9292 | O5: 高视高清 | P5: OK镜（国内） | Q5: 90000 | R5: =550/10000 -> 0.055 | S5: =Q5*R5 -> 4950 | T5: =+Q5*R5/1.13 -> 4380.531 | U5: =0.01 -> 0.01 | V5: =U5*Q5 -> 900 | W5: 0.65 | X5: =T5*(1-W5) -> 1533.1858
C6: 高视高清 | D6: OK镜（国际） | F6: =700/10000 -> 0.07 | G6: =E6*F6 -> 0 | H6: =+E6*F6/1.13 -> 0 | I6: 0.01 | J6: =I6*E6 -> 0 | L6: =H6*(1-K6) -> 0 | O6: 高视高清 | P6: OK镜（国际） | Q6: 20000 | R6: =700/10000 -> 0.07 | S6: =Q6*R6 -> 1400 | T6: =+Q6*R6/1.13 -> 1238.9381 | U6: =0.01 -> 0.01 | V6: =U6*Q6 -> 200 | W6: 0.8 | X6: =T6*(1-W6) -> 247.78761
L7: =H7*(1-K7) -> 0 | O7: 高视高清 | P7: 隐形眼镜 | S7: =T7*1.13 -> 1356 | T7: 1200 | W7: 0.4 | X7: =T7*(1-W7) -> 720
C8: 总计 | G8: =SUM(G3:G7) -> 1200 | H8: =SUM(H3:H7) -> 1061.9469 | J8: =SUM(J3:J7) -> 443.66814 | K8: =J8/1.13 -> 392.62667 | L8: =SUM(L3:L7) -> 478.31858 | M8: =1-L8/H8 -> 0.54958333 | O8: 总计 | S8: =SUM(S3:S7) -> 11356 | T8: =SUM(T3:T7) -> 10049.558 | V8: =SUM(V3:V7) -> 2668.1726 | W8: =V8/1.13 -> 2361.2147 | X8: =SUM(X3:X7) -> 3166.9027 | Y8: =1-X8/T8 -> 0.68487143
B10: 2027年 | C10: 产品名称 | D10: 产品类型 | E10: 销售数量 | F10: 销售单价（含税） | G10: 含税销售 | H10: 销售收入（不含税） | I10: 单位BOM材料费 | J10: BOM材料成本 | K10: 毛利率 | M10: 平均毛利率 | N10: 2030年 | O10: 产品名称 | P10: 产品类型 | Q10: 销售数量 | R10: 销售单价（含税） | S10: 含税销售 | T10: 销售收入（不含税） | U10: 单位BOM材料费 | V10: BOM材料成本 | W10: 毛利率 | Y10: 平均毛利率
C11: 高视高清 | D11: RGP | E11: 1500 | F11: =500/10000 -> 0.05 | G11: =E11*F11 -> 75 | H11: =+E11*F11/1.13 -> 66.371681 | I11: =0.0065 -> 0.0065 | J11: =I11*E11 -> 9.75 | K11: 0.25 | L11: =H11*(1-K11) -> 49.778761 | O11: 高视高清 | P11: RGP | Q11: 5000 | R11: =500/10000 -> 0.05 | S11: =Q11*R11 -> 250 | T11: =+Q11*R11/1.13 -> 221.23894 | U11: =0.0065 -> 0.0065 | V11: =U11*Q11 -> 32.5 | W11: 0.65 | X11: =T11*(1-W11) -> 77.433628
C12: 高视高清 | D12: 离焦镜片（副） | E12: 32000 | F12: =350/10000 -> 0.035 | G12: =E12*F12 -> 1120 | H12: =+E12*F12/1.13 -> 991.15044 | I12: =0.0175/1.13 -> 0.015486726 | J12: =I12*E12 -> 495.57522 | K12: 0.75 | L12: =H12*(1-K12) -> 247.78761 | O12: 高视高清 | P12: 离焦镜片（副） | Q12: 150000 | R12: =350/10000 -> 0.035 | S12: =Q12*R12 -> 5250 | T12: =+Q12*R12/1.13 -> 4646.0177 | U12: =0.0175/1.13 -> 0.015486726 | V12: =U12*Q12 -> 2323.0088 | W12: 0.8 | X12: =T12*(1-W12) -> 929.20354
C13: 高视高清 | D13: OK镜（国内） | E13: 12000 | F13: =550/10000 -> 0.055 | G13: =E13*F13 -> 660 | H13: =+E13*F13/1.13 -> 584.0708 | I13: =0.01 -> 0.01 | J13: =I13*E13 -> 120 | K13: 0.25 | L13: =H13*(1-K13) -> 438.0531 | O13: 高视高清 | P13: OK镜（国内） | Q13: 150000 | R13: =550/10000 -> 0.055 | S13: =Q13*R13 -> 8250 | T13: =+Q13*R13/1.13 -> 7300.885 | U13: =0.01 -> 0.01 | V13: =U13*Q13 -> 1500 | W13: 0.65 | X13: =T13*(1-W13) -> 2555.3097
C14: 高视高清 | D14: OK镜（国际） | E14: 5000 | F14: =700/10000 -> 0.07 | G14: =E14*F14 -> 350 | H14: =+E14*F14/1.13 -> 309.73451 | I14: =0.01 -> 0.01 | J14: =I14*E14 -> 50 | K14: 0.4 | L14: =H14*(1-K14) -> 185.84071 | O14: 高视高清 | P14: OK镜（国际） | Q14: =Q6*2 -> 40000 | R14: =700/10000 -> 0.07 | S14: =Q14*R14 -> 2800 | T14: =+Q14*R14/1.13 -> 2477.8761 | U14: =0.01 -> 0.01 | V14: =U14*Q14 -> 400 | W14: 0.8 | X14: =T14*(1-W14) -> 495.57522
L15: =H15*(1-K15) -> 0 | O15: 高视高清 | P15: 隐形眼镜 | S15: =T15*1.13 -> 6102 | T15: 5400 | W15: 0.4 | X15: =T15*(1-W15) -> 3240
C16: 总计 | G16: =SUM(G11:G15) -> 2205 | H16: =SUM(H11:H15) -> 1951.3274 | J16: =SUM(J11:J15) -> 675.32522 | K16: =J16/1.13 -> 597.63294 | L16: =SUM(L11:L15) -> 921.46018 | M16: =1-L16/H16 -> 0.52777778 | O16: 总计 | S16: =SUM(S11:S15) -> 22652 | T16: =SUM(T11:T15) -> 20046.018 | V16: =SUM(V11:V15) -> 4255.5088 | W16: =V16/1.13 -> 3765.937 | X16: =SUM(X11:X15) -> 7297.5221 | Y16: =1-X16/T16 -> 0.6359615
B18: 2028年 | C18: 产品名称 | D18: 产品类型 | E18: 销售数量 | F18: 销售单价（含税） | G18: 含税销售 | H18: 销售收入（不含税） | I18: 单位BOM材料费 | J18: BOM材料成本 | K18: 毛利率 | M18: 平均毛利率
C19: 高视高清 | D19: RGP | E19: 2000 | F19: =500/10000 -> 0.05 | G19: =E19*F19 -> 100 | H19: =+E19*F19/1.13 -> 88.495575 | I19: =0.0065 -> 0.0065 | J19: =I19*E19 -> 13 | K19: 0.65 | L19: =H19*(1-K19) -> 30.973451
C20: 高视高清 | D20: 离焦镜片（副） | E20: 70000 | F20: =350/10000 -> 0.035 | G20: =E20*F20 -> 2450 | H20: =+E20*F20/1.13 -> 2168.1416 | I20: =0.0175/1.13 -> 0.015486726 | J20: =I20*E20 -> 1084.0708 | K20: 0.75 | L20: =H20*(1-K20) -> 542.0354
C21: 高视高清 | D21: OK镜（国内） | E21: 45000 | F21: =550/10000 -> 0.055 | G21: =E21*F21 -> 2475 | H21: =+E21*F21/1.13 -> 2190.2655 | I21: =0.01 -> 0.01 | J21: =I21*E21 -> 450 | K21: 0.5 | L21: =H21*(1-K21) -> 1095.1327
C22: 高视高清 | D22: OK镜（国际） | E22: 10000 | F22: =700/10000 -> 0.07 | G22: =E22*F22 -> 700 | H22: =+E22*F22/1.13 -> 619.46903 | I22: =0.01 -> 0.01 | J22: =I22*E22 -> 100 | K22: 0.7 | L22: =H22*(1-K22) -> 185.84071
L23: =H23*(1-K23) -> 0
C24: 总计 | G24: =SUM(G19:G23) -> 5725 | H24: =SUM(H19:H23) -> 5066.3717 | J24: =SUM(J19:J23) -> 1647.0708 | K24: =J24/1.13 -> 1457.5848 | L24: =SUM(L19:L23) -> 1853.9823 | M24: =1-L24/H24 -> 0.63406114
D27: 总金额 | E27: 年摊销金额 | F27: 一台机床24小时3班倒年可生产OK镜5W
C28: 无形资产摊销 | D28: 13000000 | E28: =D28/10 -> 1300000 | F28: 一台机床工作8小时可生产OK镜2W
C29: 工时 | D29: 6分钟
A31: 硬性接触镜（欧普） | E31: 角膜塑形镜（爱博） | I31: 人工晶状体（爱博） | K31: 单位成本
A32: 年销量 | B32: =B40 -> 666247 | E32: 年销量 | F32: 402854 | I32: 年生产量 | J32: 2196900
A33: 直接材料 | B33: =51924350.83+8623021.41 -> 60547372 | C33: =B33/B32 -> 90.878266 | E33: 直接材料 | F33: 8232991.1 | G33: =F33/F32 -> 20.436662 | I33: 年销量 | J33: 1738454
A34: 直接人工 | B34: 17715830 | C34: =B34/B32 -> 26.590484 | E34: 直接人工 | F34: 10687786 | G34: =F34/F32 -> 26.530172 | I34: 直接材料 | J34: 12649664 | K34: =J34/J33 -> 7.2763872
A35: 制造费用 | B35: 9687902.6 | C35: =B35/B32 -> 14.541007 | E35: 制造费用 | F35: 14925787 | G35: =F35/F32 -> 37.050116 | I35: 直接人工 | J35: 18227674 | K35: =J35/J33 -> 10.48499
A36: 运费 | B36: 1156975.8 | C36: =B36/B32 -> 1.7365568 | E36: 成本合计 | F36: =SUM(F33:F35) -> 33846564 | G36: =SUM(G33:G35) -> 84.016949 | I36: 制造费用 | J36: 32832420 | K36: =J36/J33 -> 18.885987
A37: 成本合计 | B37: =SUM(B33:B36) -> 89108081 | C37: =SUM(C33:C36) -> 133.74631 | I37: 成本合计 | J37: =SUM(J34:J36) -> 63709758 | K37: =SUM(K34:K36) -> 36.647365
A39: 营业成本 | B39: 89108081 | E39: 营业成本 | F39: 33846564
A40: 销售量 | B40: 666247 | E40: 销售量 | F40: 402854 | I40: 营业成本 | J40: 63709758 | K40: =J40/(1-J43) -> 5.877284e+08
A41: 单位成本 | B41: =B39/B40 -> 133.74631 | E41: 单位成本 | F41: =F39/F40 -> 84.016949 | I41: 销售量 | J41: 1738454
A42: 毛利率 | B42: 0.8831 | E42: 毛利率 | F42: 0.8568 | I42: 单位成本 | J42: =J40/J41 -> 36.647365
A43: 收入金额 | B43: =B41/(1-B42) -> 1144.1088 | E43: 收入金额 | F43: =F41/(1-F42) -> 586.71054 | I43: 毛利率 | J43: 0.8916
I44: 收入单价 | J44: =J42/(1-J43) -> 338.07532
E46: 隐形眼镜
E47: 年销量 | F47: 214121431 | I47: 其他手术产品
E48: 直接材料 | F48: 1.7496986e+08 | G48: =F48/F47 -> 0.8171525 | I48: 年销量
...
